Workbook

Sheet Instructions
A1: SUPERVISOR LOG — Instructions
A3: Owner: Production Supervisors / Shift Leaders
A5: Sheets: JobChange + DailyProduction
A7: Rules:
A8: 1. One row = one event
A9: 2. Use dropdowns (yellow cells) — do not free-type coded fields
A10: 3. Dates must be real Excel dates
A11: 4. Save as 02_Supervisor_Log_YYYYMMDD.xlsx into the OneDrive Daily folder
A13: Dataset: one-week business-rule-consistent synthetic data (2025-10-20 to 2025-10-26) for DWH / Power BI testing.
A15: NEW DETAIL MODEL — IMPORTANT
A16: JobChange and DailyProduction keep their original grain and original source columns.
A17: ProductionConfiguration is Event × Section with three cavity flags; unpivot Cavity1Active:Cavity3Active in Power Query for cavity grain.
... A20: NoCavities > 3 conflicts with the assumed physical capability and is flagged; existing source values are not silently changed.

Sheet JobChange
A1: JOB CHANGE LOG
A2: Maps to STG_JOBCHANGE → FACT_JOBCHANGE
A3: Yellow=Dropdown | Green=Date | Blue=Hours. FromOrderNumber can be empty for first job of day.
A4: FactoryCode | B4: LineNumber | C4: EventDate | D4: ShiftCode | E4: CrewCode | F4: FromOrderNumber | G4: ToOrderNumber | H4: JobChangeTypeName | I4: MechanicalWorkT1_Hrs | J4: FormingTimeT2_Hrs | K4: TrialLosses_Hrs | L4: HE_Downtime_Hrs | M4: HE_DowntimeReason | N4: CE_Losses_Hrs | O4: CE_LossesReason | P4: PalletizerLosses_Hrs | Q4: PalletizerReason | R4: Notes | S4: JobChangeEventID | T4: TotalJobChangeHours | U4: ImpactDurationHrs | V4: ImpactReconciliationCheck | W4: ReasonConsistencyCheck | X4: TransitionCheck | Y4: EventIDUniquenessCheck | Z4: DataQualityCheck
A5: KG01 | B5: 21 | C5: 45951 | D5: AM | E5: A | F5: ORD-2025-00019 | G5: ORD-2025-00020 | H5: Medium | I5: 3.08 | J5: 1 | K5: 0.19 | L5: 0 | N5: 0 | P5: 0 | R5: Within target | S5: =IF(A5="","", "JC-"&A5&"-L"&TEXT(B5,"00")&"-"&TEXT(C5,"yyyymmdd")&"-"&D5&"-"&IF(F5="","START",F5)&"-"&G5) -> JC-KG01-L21-20251021-AM-ORD-2025-00019-ORD-2025-00020 | T5: =IF(A5="","",SUM(I5:L5)+N5+P5) -> 4.27 | U5: =IF(S5="","",SUMIF(JobChangeImpact!$B$5:$B$100,S5,JobChangeImpact!$Q$5:$Q$100)) -> 4.27 | V5: =IF(A5="","",IF(ABS(T5-U5)<=0.001,"OK","CHECK")) -> OK | W5: =IF(A5="","",IF(AND(IF(L5>0,M5<>"",M5=""),IF(N5>0,O5<>"",O5=""),IF(P5>0,Q5<>"",Q5="")),"OK","CHECK")) -> OK | X5: =IF(A5="","",IF(OR(G5="",AND(F5<>"",F5=G5)),"CHECK","OK")) -> OK | Y5: =IF(S5="","",IF(COUNTIF($S$5:$S$100,S5)=1,"OK","CHECK")) -> OK | Z5: =IF(A5="","",IF(AND(V5="OK",W5="OK",X5="OK",Y5="OK",T5>0),"OK","CHECK")) -> OK
A6: KG01 | B6: 21 | C6: 45955 | D6: AM | E6: B | F6: ORD-2025-00020 | G6: ORD-2025-00021 | H6: Medium | I6: 3.15 | J6: 1.2 | K6: 0.1 | L6: 0.51 | M6: Gob Weight Adjustment | N6: 0 | P6: 0 | R6: Extended setup | S6: =IF(A6="","", "JC-"&A6&"-L"&TEXT(B6,"00")&"-"&TEXT(C6,"yyyymmdd")&"-"&D6&"-"&IF(F6="","START",F6)&"-"&G6) -> JC-KG01-L21-20251025-AM-ORD-2025-00020-ORD-2025-00021 | T6: =IF(A6="","",SUM(I6:L6)+N6+P6) -> 4.96 | U6: =IF(S6="","",SUMIF(JobChangeImpact!$B$5:$B$100,S6,JobChangeImpact!$Q$5:$Q$100)) -> 4.96 | V6: =IF(A6="","",IF(ABS(T6-U6)<=0.001,"OK","CHECK")) -> OK | W6: =IF(A6="","",IF(AND(IF(L6>0,M6<>"",M6=""),IF(N6>0,O6<>"",O6=""),IF(P6>0,Q6<>"",Q6="")),"OK","CHECK")) -> OK | X6: =IF(A6="","",IF(OR(G6="",AND(F6<>"",F6=G6)),"CHECK","OK")) -> OK | Y6: =IF(S6="","",IF(COUNTIF($S$5:$S$100,S6)=1,"OK","CHECK")) -> OK | Z6: =IF(A6="","",IF(AND(V6="OK",W6="OK",X6="OK",Y6="OK",T6>0),"OK","CHECK")) -> OK
A7: KG01 | B7: 22 | C7: 45950 | D7: AM | E7: C | F7: ORD-2025-00055 | G7: ORD-2025-00056 | H7: Big | I7: 6.84 | J7: 1.63 | K7: 0.78 | L7: 0 | N7: 0 | P7: 0.24 | Q7: Pallet Conveyor Jam | R7: Minor adjustment | S7: =IF(A7="","", "JC-"&A7&"-L"&TEXT(B7,"00")&"-"&TEXT(C7,"yyyymmdd")&"-"&D7&"-"&IF(F7="","START",F7)&"-"&G7) -> JC-KG01-L22-20251020-AM-ORD-2025-00055-ORD-2025-00056 | T7: =IF(A7="","",SUM(I7:L7)+N7+P7) -> 9.49 | U7: =IF(S7="","",SUMIF(JobChangeImpact!$B$5:$B$100,S7,JobChangeImpact!$Q$5:$Q$100)) -> 9.49 | V7: =IF(A7="","",IF(ABS(T7-U7)<=0.001,"OK","CHECK")) -> OK | W7: =IF(A7="","",IF(AND(IF(L7>0,M7<>"",M7=""),IF(N7>0,O7<>"",O7=""),IF(P7>0,Q7<>"",Q7="")),"OK","CHECK")) -> OK | X7: =IF(A7="","",IF(OR(G7="",AND(F7<>"",F7=G7)),"CHECK","OK")) -> OK | Y7: =IF(S7="","",IF(COUNTIF($S$5:$S$100,S7)=1,"OK","CHECK")) -> OK | Z7: =IF(A7="","",IF(AND(V7="OK",W7="OK",X7="OK",Y7="OK",T7>0),"OK","CHECK")) -> OK
A8: KG01 | B8: 22 | C8: 45956 | D8: AM | E8: C | F8: ORD-2025-00057 | G8: ORD-2025-00058 | H8: Big | I8: 5.65 | J8: 1.35 | K8: 0.78 | L8: 0.69 | M8: Neck Ring Issue | N8: 0 | P8: 0 | R8: Within target | S8: =IF(A8="","", "JC-"&A8&"-L"&TEXT(B8,"00")&"-"&TEXT(C8,"yyyymmdd")&"-"&D8&"-"&IF(F8="","START",F8)&"-"&G8) -> JC-KG01-L22-20251026-AM-ORD-2025-00057-ORD-2025-00058 | T8: =IF(A8="","",SUM(I8:L8)+N8+P8) -> 8.47 | U8: =IF(S8="","",SUMIF(JobChangeImpact!$B$5:$B$100,S8,JobChangeImpact!$Q$5:$Q$100)) -> 8.47 | V8: =IF(A8="","",IF(ABS(T8-U8)<=0.001,"OK","CHECK")) -> OK | W8: =IF(A8="","",IF(AND(IF(L8>0,M8<>"",M8=""),IF(N8>0,O8<>"",O8=""),IF(P8>0,Q8<>"",Q8="")),"OK","CHECK")) -> OK | X8: =IF(A8="","",IF(OR(G8="",AND(F8<>"",F8=G8)),"CHECK","OK")) -> OK | Y8: =IF(S8="","",IF(COUNTIF($S$5:$S$100,S8)=1,"OK","CHECK")) -> OK | Z8: =IF(A8="","",IF(AND(V8="OK",W8="OK",X8="OK",Y8="OK",T8>0),"OK","CHECK")) -> OK
A9: KG01 | B9: 23 | C9: 45952 | D9: AM | E9: B | F9: ORD-2025-00092 | G9: ORD-2025-00093 | H9: Medium | I9: 2.73 | J9: 1.06 | K9: 0.49 | L9: 0 | N9: 0 | P9: 0.4 | Q9: Palletizer Robot Fault | R9: Within target | S9: =IF(A9="","", "JC-"&A9&"-L"&TEXT(B9,"00")&"-"&TEXT(C9,"yyyymmdd")&"-"&D9&"-"&IF(F9="","START",F9)&"-"&G9) -> JC-KG01-L23-20251022-AM-ORD-2025-00092-ORD-2025-00093 | T9: =IF(A9="","",SUM(I9:L9)+N9+P9) -> 4.68 | U9: =IF(S9="","",SUMIF(JobChangeImpact!$B$5:$B$100,S9,JobChangeImpact!$Q$5:$Q$100)) -> 4.68 | V9: =IF(A9="","",IF(ABS(T9-U9)<=0.001,"OK","CHECK")) -> OK | W9: =IF(A9="","",IF(AND(IF(L9>0,M9<>"",M9=""),IF(N9>0,O9<>"",O9=""),IF(P9>0,Q9<>"",Q9="")),"OK","CHECK")) -> OK | X9: =IF(A9="","",IF(OR(G9="",AND(F9<>"",F9=G9)),"CHECK","OK")) -> OK | Y9: =IF(S9="","",IF(COUNTIF($S$5:$S$100,S9)=1,"OK","CHECK")) -> OK | Z9: =IF(A9="","",IF(AND(V9="OK",W9="OK",X9="OK",Y9="OK",T9>0),"OK","CHECK")) -> OK
A10: KG01 | B10: 23 | C10: 45956 | D10: AM | E10: C | F10: ORD-2025-00093 | G10: ORD-2025-00094 | H10: Process | I10: 6.68 | J10: 2.81 | K10: 0.35 | L10: 0.47 | M10: Gob Distributor Jam | N10: 0.39 | O10: Conveyor Speed Mismatch | P10: 0 | R10: Stable restart | S10: =IF(A10="","", "JC-"&A10&"-L"&TEXT(B10,"00")&"-"&TEXT(C10,"yyyymmdd")&"-"&D10&"-"&IF(F10="","START",F10)&"-"&G10) -> JC-KG01-L23-20251026-AM-ORD-2025-00093-ORD-2025-00094 | T10: =IF(A10="","",SUM(I10:L10)+N10+P10) -> 10.7 | U10: =IF(S10="","",SUMIF(JobChangeImpact!$B$5:$B$100,S10,JobChangeImpact!$Q$5:$Q$100)) -> 10.7 | V10: =IF(A10="","",IF(ABS(T10-U10)<=0.001,"OK","CHECK")) -> OK | W10: =IF(A10="","",IF(AND(IF(L10>0,M10<>"",M10=""),IF(N10>0,O10<>"",O10=""),IF(P10>0,Q10<>"",Q10="")),"OK","CHECK")) -> OK | X10: =IF(A10="","",IF(OR(G10="",AND(F10<>"",F10=G10)),"CHECK","OK")) -> OK | Y10: =IF(S10="","",IF(COUNTIF($S$5:$S$100,S10)=1,"OK","CHECK")) -> OK | Z10: =IF(A10="","",IF(AND(V10="OK",W10="OK",X10="OK",Y10="OK",T10>0),"OK","CHECK")) -> OK
A11: KG01 | B11: 24 | C11: 45951 | D11: AM | E11: A | F11: ORD-2025-00124 | G11: ORD-2025-00125 | H11: Medium | I11: 3.5 | J11: 0.76 | K11: 0.5 | L11: 0 | N11: 0 | P11: 0 | R11: Stable restart | S11: =IF(A11="","", "JC-"&A11&"-L"&TEXT(B11,"00")&"-"&TEXT(C11,"yyyymmdd")&"-"&D11&"-"&IF(F11="","START",F11)&"-"&G11) -> JC-KG01-L24-20251021-AM-ORD-2025-00124-ORD-2025-00125 | T11: =IF(A11="","",SUM(I11:L11)+N11+P11) -> 4.76 | U11: =IF(S11="","",SUMIF(JobChangeImpact!$B$5:$B$100,S11,JobChangeImpact!$Q$5:$Q$100)) -> 4.76 | V11: =IF(A11="","",IF(ABS(T11-U11)<=0.001,"OK","CHECK")) -> OK | W11: =IF(A11="","",IF(AND(IF(L11>0,M11<>"",M11=""),IF(N11>0,O11<>"",O11=""),IF(P11>0,Q11<>"",Q11="")),"OK","CHECK")) -> OK | X11: =IF(A11="","",IF(OR(G11="",AND(F11<>"",F11=G11)),"CHECK","OK")) -> OK | Y11: =IF(S11="","",IF(COUNTIF($S$5:$S$100,S11)=1,"OK","CHECK")) -> OK | Z11: =IF(A11="","",IF(AND(V11="OK",W11="OK",X11="OK",Y11="OK",T11>0),"OK","CHECK")) -> OK
A12: KG01 | B12: 24 | C12: 45955 | D12: AM | E12: B | F12: ORD-2025-00125 | G12: ORD-2025-00126 | H12: Small | I12: 1.35 | J12: 0.42 | K12: 0.42 | L12: 0 | N12: 0 | P12: 0 | R12: Within target | S12: =IF(A12="","", "JC-"&A12&"-L"&TEXT(B12,"00")&"-"&TEXT(C12,"yyyymmdd")&"-"&D12&"-"&IF(F12="","START",F12)&"-"&G12) -> JC-KG01-L24-20251025-AM-ORD-2025-00125-ORD-2025-00126 | T12: =IF(A12="","",SUM(I12:L12)+N12+P12) -> 2.19 | U12: =IF(S12="","",SUMIF(JobChangeImpact!$B$5:$B$100,S12,JobChangeImpact!$Q$5:$Q$100)) -> 2.19 | V12: =IF(A12="","",IF(ABS(T12-U12)<=0.001,"OK","CHECK")) -> OK | W12: =IF(A12="","",IF(AND(IF(L12>0,M12<>"",M12=""),IF(N12>0,O12<>"",O12=""),IF(P12>0,Q12<>"",Q12="")),"OK","CHECK")) -> OK | X12: =IF(A12="","",IF(OR(G12="",AND(F12<>"",F12=G12)),"CHECK","OK")) -> OK | Y12: =IF(S12="","",IF(COUNTIF($S$5:$S$100,S12)=1,"OK","CHECK")) -> OK | Z12: =IF(A12="","",IF(AND(V12="OK",W12="OK",X12="OK",Y12="OK",T12>0),"OK","CHECK")) -> OK
A13: KG01 | B13: 25 | C13: 45953 | D13: AM | E13: C | F13: ORD-2025-00161 | G13: ORD-2025-00162 | H13: Medium | I13: 2.75 | J13: 0.89 | K13: 0.49 | L13: 0 | N13: 0 | P13: 0 | R13: Stable restart | S13: =IF(A13="","", "JC-"&A13&"-L"&TEXT(B13,"00")&"-"&TEXT(C13,"yyyymmdd")&"-"&D13&"-"&IF(F13="","START",F13)&"-"&G13) -> JC-KG01-L25-20251023-AM-ORD-2025-00161-ORD-2025-00162 | T13: =IF(A13="","",SUM(I13:L13)+N13+P13) -> 4.13 | U13: =IF(S13="","",SUMIF(JobChangeImpact!$B$5:$B$100,S13,JobChangeImpact!$Q$5:$Q$100)) -> 4.13 | V13: =IF(A13="","",IF(ABS(T13-U13)<=0.001,"OK","CHECK")) -> OK | W13: =IF(A13="","",IF(AND(IF(L13>0,M13<>"",M13=""),IF(N13>0,O13<>"",O13=""),IF(P13>0,Q13<>"",Q13="")),"OK","CHECK")) -> OK | X13: =IF(A13="","",IF(OR(G13="",AND(F13<>"",F13=G13)),"CHECK","OK")) -> OK | Y13: =IF(S13="","",IF(COUNTIF($S$5:$S$100,S13)=1,"OK","CHECK")) -> OK | Z13: =IF(A13="","",IF(AND(V13="OK",W13="OK",X13="OK",Y13="OK",T13>0),"OK","CHECK")) -> OK
S14: =IF(A14="","", "JC-"&A14&"-L"&TEXT(B14,"00")&"-"&TEXT(C14,"yyyymmdd")&"-"&D14&"-"&IF(F14="","START",F14)&"-"&G14) | T14: =IF(A14="","",SUM(I14:L14)+N14+P14) | U14: =IF(S14="","",SUMIF(JobChangeImpact!$B$5:$B$100,S14,JobChangeImpact!$Q$5:$Q$100)) | V14: =IF(A14="","",IF(ABS(T14-U14)<=0.001,"OK","CHECK")) | W14: =IF(A14="","",IF(AND(IF(L14>0,M14<>"",M14=""),IF(N14>0,O14<>"",O14=""),IF(P14>0,Q14<>"",Q14="")),"OK","CHECK")) | X14: =IF(A14="","",IF(OR(G14="",AND(F14<>"",F14=G14)),"CHECK","OK")) | Y14: =IF(S14="","",IF(COUNTIF($S$5:$S$100,S14)=1,"OK","CHECK")) | Z14: =IF(A14="","",IF(AND(V14="OK",W14="OK",X14="OK",Y14="OK",T14>0),"OK","CHECK"))
S15: =IF(A15="","", "JC-"&A15&"-L"&TEXT(B15,"00")&"-"&TEXT(C15,"yyyymmdd")&"-"&D15&"-"&IF(F15="","START",F15)&"-"&G15) | T15: =IF(A15="","",SUM(I15:L15)+N15+P15) | U15: =IF(S15="","",SUMIF(JobChangeImpact!$B$5:$B$100,S15,JobChangeImpact!$Q$5:$Q$100)) | V15: =IF(A15="","",IF(ABS(T15-U15)<=0.001,"OK","CHECK")) | W15: =IF(A15="","",IF(AND(IF(L15>0,M15<>"",M15=""),IF(N15>0,O15<>"",O15=""),IF(P15>0,Q15<>"",Q15="")),"OK","CHECK")) | X15: =IF(A15="","",IF(OR(G15="",AND(F15<>"",F15=G15)),"CHECK","OK")) | Y15: =IF(S15="","",IF(COUNTIF($S$5:$S$100,S15)=1,"OK","CHECK")) | Z15: =IF(A15="","",IF(AND(V15="OK",W15="OK",X15="OK",Y15="OK",T15>0),"OK","CHECK"))
S16: =IF(A16="","", "JC-"&A16&"-L"&TEXT(B16,"00")&"-"&TEXT(C16,"yyyymmdd")&"-"&D16&"-"&IF(F16="","START",F16)&"-"&G16) | T16: =IF(A16="","",SUM(I16:L16)+N16+P16) | U16: =IF(S16="","",SUMIF(JobChangeImpact!$B$5:$B$100,S16,JobChangeImpact!$Q$5:$Q$100)) | V16: =IF(A16="","",IF(ABS(T16-U16)<=0.001,"OK","CHECK")) | W16: =IF(A16="","",IF(AND(IF(L16>0,M16<>"",M16=""),IF(N16>0,O16<>"",O16=""),IF(P16>0,Q16<>"",Q16="")),"OK","CHECK")) | X16: =IF(A16="","",IF(OR(G16="",AND(F16<>"",F16=G16)),"CHECK","OK")) | Y16: =IF(S16="","",IF(COUNTIF($S$5:$S$100,S16)=1,"OK","CHECK")) | Z16: =IF(A16="","",IF(AND(V16="OK",W16="OK",X16="OK",Y16="OK",T16>0),"OK","CHECK"))
S17: =IF(A17="","", "JC-"&A17&"-L"&TEXT(B17,"00")&"-"&TEXT(C17,"yyyymmdd")&"-"&D17&"-"&IF(F17="","START",F17)&"-"&G17) | T17: =IF(A17="","",SUM(I17:L17)+N17+P17) | U17: =IF(S17="","",SUMIF(JobChangeImpact!$B$5:$B$100,S17,JobChangeImpact!$Q$5:$Q$100)) | V17: =IF(A17="","",IF(ABS(T17-U17)<=0.001,"OK","CHECK")) | W17: =IF(A17="","",IF(AND(IF(L17>0,M17<>"",M17=""),IF(N17>0,O17<>"",O17=""),IF(P17>0,Q17<>"",Q17="")),"OK","CHECK")) | X17: =IF(A17="","",IF(OR(G17="",AND(F17<>"",F17=G17)),"CHECK","OK")) | Y17: =IF(S17="","",IF(COUNTIF($S$5:$S$100,S17)=1,"OK","CHECK")) | Z17: =IF(A17="","",IF(AND(V17="OK",W17="OK",X17="OK",Y17="OK",T17>0),"OK","CHECK"))
S18: =IF(A18="","", "JC-"&A18&"-L"&TEXT(B18,"00")&"-"&TEXT(C18,"yyyymmdd")&"-"&D18&"-"&IF(F18="","START",F18)&"-"&G18) | T18: =IF(A18="","",SUM(I18:L18)+N18+P18) | U18: =IF(S18="","",SUMIF(JobChangeImpact!$B$5:$B$100,S18,JobChangeImpact!$Q$5:$Q$100)) | V18: =IF(A18="","",IF(ABS(T18-U18)<=0.001,"OK","CHECK")) | W18: =IF(A18="","",IF(AND(IF(L18>0,M18<>"",M18=""),IF(N18>0,O18<>"",O18=""),IF(P18>0,Q18<>"",Q18="")),"OK","CHECK")) | X18: =IF(A18="","",IF(OR(G18="",AND(F18<>"",F18=G18)),"CHECK","OK")) | Y18: =IF(S18="","",IF(COUNTIF($S$5:$S$100,S18)=1,"OK","CHECK")) | Z18: =IF(A18="","",IF(AND(V18="OK",W18="OK",X18="OK",Y18="OK",T18>0),"OK","CHECK"))
S19: =IF(A19="","", "JC-"&A19&"-L"&TEXT(B19,"00")&"-"&TEXT(C19,"yyyymmdd")&"-"&D19&"-"&IF(F19="","START",F19)&"-"&G19) | T19: =IF(A19="","",SUM(I19:L19)+N19+P19) | U19: =IF(S19="","",SUMIF(JobChangeImpact!$B$5:$B$100,S19,JobChangeImpact!$Q$5:$Q$100)) | V19: =IF(A19="","",IF(ABS(T19-U19)<=0.001,"OK","CHECK")) | W19: =IF(A19="","",IF(AND(IF(L19>0,M19<>"",M19=""),IF(N19>0,O19<>"",O19=""),IF(P19>0,Q19<>"",Q19="")),"OK","CHECK")) | X19: =IF(A19="","",IF(OR(G19="",AND(F19<>"",F19=G19)),"CHECK","OK")) | Y19: =IF(S19="","",IF(COUNTIF($S$5:$S$100,S19)=1,"OK","CHECK")) | Z19: =IF(A19="","",IF(AND(V19="OK",W19="OK",X19="OK",Y19="OK",T19>0),"OK","CHECK"))
S20: =IF(A20="","", "JC-"&A20&"-L"&TEXT(B20,"00")&"-"&TEXT(C20,"yyyymmdd")&"-"&D20&"-"&IF(F20="","START",F20)&"-"&G20) | T20: =IF(A20="","",SUM(I20:L20)+N20+P20) | U20: =IF(S20="","",SUMIF(JobChangeImpact!$B$5:$B$100,S20,JobChangeImpact!$Q$5:$Q$100)) | V20: =IF(A20="","",IF(ABS(T20-U20)<=0.001,"OK","CHECK")) | W20: =IF(A20="","",IF(AND(IF(L20>0,M20<>"",M20=""),IF(N20>0,O20<>"",O20=""),IF(P20>0,Q20<>"",Q20="")),"OK","CHECK")) | X20: =IF(A20="","",IF(OR(G20="",AND(F20<>"",F20=G20)),"CHECK","OK")) | Y20: =IF(S20="","",IF(COUNTIF($S$5:$S$100,S20)=1,"OK","CHECK")) | Z20: =IF(A20="","",IF(AND(V20="OK",W20="OK",X20="OK",Y20="OK",T20>0),"OK","CHECK"))
S21: =IF(A21="","", "JC-"&A21&"-L"&TEXT(B21,"00")&"-"&TEXT(C21,"yyyymmdd")&"-"&D21&"-"&IF(F21="","START",F21)&"-"&G21) | T21: =IF(A21="","",SUM(I21:L21)+N21+P21) | U21: =IF(S21="","",SUMIF(JobChangeImpact!$B$5:$B$100,S21,JobChangeImpact!$Q$5:$Q$100)) | V21: =IF(A21="","",IF(ABS(T21-U21)<=0.001,"OK","CHECK")) | W21: =IF(A21="","",IF(AND(IF(L21>0,M21<>"",M21=""),IF(N21>0,O21<>"",O21=""),IF(P21>0,Q21<>"",Q21="")),"OK","CHECK")) | X21: =IF(A21="","",IF(OR(G21="",AND(F21<>"",F21=G21)),"CHECK","OK")) | Y21: =IF(S21="","",IF(COUNTIF($S$5:$S$100,S21)=1,"OK","CHECK")) | Z21: =IF(A21="","",IF(AND(V21="OK",W21="OK",X21="OK",Y21="OK",T21>0),"OK","CHECK"))
S22: =IF(A22="","", "JC-"&A22&"-L"&TEXT(B22,"00")&"-"&TEXT(C22,"yyyymmdd")&"-"&D22&"-"&IF(F22="","START",F22)&"-"&G22) | T22: =IF(A22="","",SUM(I22:L22)+N22+P22) | U22: =IF(S22="","",SUMIF(JobChangeImpact!$B$5:$B$100,S22,JobChangeImpact!$Q$5:$Q$100)) | V22: =IF(A22="","",IF(ABS(T22-U22)<=0.001,"OK","CHECK")) | W22: =IF(A22="","",IF(AND(IF(L22>0,M22<>"",M22=""),IF(N22>0,O22<>"",O22=""),IF(P22>0,Q22<>"",Q22="")),"OK","CHECK")) | X22: =IF(A22="","",IF(OR(G22="",AND(F22<>"",F22=G22)),"CHECK","OK")) | Y22: =IF(S22="","",IF(COUNTIF($S$5:$S$100,S22)=1,"OK","CHECK")) | Z22: =IF(A22="","",IF(AND(V22="OK",W22="OK",X22="OK",Y22="OK",T22>0),"OK","CHECK"))
S23: =IF(A23="","", "JC-"&A23&"-L"&TEXT(B23,"00")&"-"&TEXT(C23,"yyyymmdd")&"-"&D23&"-"&IF(F23="","START",F23)&"-"&G23) | T23: =IF(A23="","",SUM(I23:L23)+N23+P23) | U23: =IF(S23="","",SUMIF(JobChangeImpact!$B$5:$B$100,S23,JobChangeImpact!$Q$5:$Q$100)) | V23: =IF(A23="","",IF(ABS(T23-U23)<=0.001,"OK","CHECK")) | W23: =IF(A23="","",IF(AND(IF(L23>0,M23<>"",M23=""),IF(N23>0,O23<>"",O23=""),IF(P23>0,Q23<>"",Q23="")),"OK","CHECK")) | X23: =IF(A23="","",IF(OR(G23="",AND(F23<>"",F23=G23)),"CHECK","OK")) | Y23: =IF(S23="","",IF(COUNTIF($S$5:$S$100,S23)=1,"OK","CHECK")) | Z23: =IF(A23="","",IF(AND(V23="OK",W23="OK",X23="OK",Y23="OK",T23>0),"OK","CHECK"))
S24: =IF(A24="","", "JC-"&A24&"-L"&TEXT(B24,"00")&"-"&TEXT(C24,"yyyymmdd")&"-"&D24&"-"&IF(F24="","START",F24)&"-"&G24) | T24: =IF(A24="","",SUM(I24:L24)+N24+P24) | U24: =IF(S24="","",SUMIF(JobChangeImpact!$B$5:$B$100,S24,JobChangeImpact!$Q$5:$Q$100)) | V24: =IF(A24="","",IF(ABS(T24-U24)<=0.001,"OK","CHECK")) | W24: =IF(A24="","",IF(AND(IF(L24>0,M24<>"",M24=""),IF(N24>0,O24<>"",O24=""),IF(P24>0,Q24<>"",Q24="")),"OK","CHECK")) | X24: =IF(A24="","",IF(OR(G24="",AND(F24<>"",F24=G24)),"CHECK","OK")) | Y24: =IF(S24="","",IF(COUNTIF($S$5:$S$100,S24)=1,"OK","CHECK")) | Z24: =IF(A24="","",IF(AND(V24="OK",W24="OK",X24="OK",Y24="OK",T24>0),"OK","CHECK"))
S25: =IF(A25="","", "JC-"&A25&"-L"&TEXT(B25,"00")&"-"&TEXT(C25,"yyyymmdd")&"-"&D25&"-"&IF(F25="","START",F25)&"-"&G25) | T25: =IF(A25="","",SUM(I25:L25)+N25+P25) | U25: =IF(S25="","",SUMIF(JobChangeImpact!$B$5:$B$100,S25,JobChangeImpact!$Q$5:$Q$100)) | V25: =IF(A25="","",IF(ABS(T25-U25)<=0.001,"OK","CHECK")) | W25: =IF(A25="","",IF(AND(IF(L25>0,M25<>"",M25=""),IF(N25>0,O25<>"",O25=""),IF(P25>0,Q25<>"",Q25="")),"OK","CHECK")) | X25: =IF(A25="","",IF(OR(G25="",AND(F25<>"",F25=G25)),"CHECK","OK")) | Y25: =IF(S25="","",IF(COUNTIF($S$5:$S$100,S25)=1,"OK","CHECK")) | Z25: =IF(A25="","",IF(AND(V25="OK",W25="OK",X25="OK",Y25="OK",T25>0),"OK","CHECK"))
... S100: =IF(A100="","", "JC-"&A100&"-L"&TEXT(B100,"00")&"-"&TEXT(C100,"yyyymmdd")&"-"&D100&"-"&IF(F100="","START",F100)&"-"&G100) | T100: =IF(A100="","",SUM(I100:L100)+N100+P100) | U100: =IF(S100="","",SUMIF(JobChangeImpact!$B$5:$B$100,S100,JobChangeImpact!$Q$5:$Q$100)) | V100: =IF(A100="","",IF(ABS(T100-U100)<=0.001,"OK","CHECK")) | W100: =IF(A100="","",IF(AND(IF(L100>0,M100<>"",M100=""),IF(N100>0,O100<>"",O100=""),IF(P100>0,Q100<>"",Q100="")),"OK","CHECK")) | X100: =IF(A100="","",IF(OR(G100="",AND(F100<>"",F100=G100)),"CHECK","OK")) | Y100: =IF(S100="","",IF(COUNTIF($S$5:$S$100,S100)=1,"OK","CHECK")) | Z100: =IF(A100="","",IF(AND(V100="OK",W100="OK",X100="OK",Y100="OK",T100>0),"OK","CHECK"))

Sheet JobChangeImpact
A1: JOB CHANGE IMPACT — DETAILED ASSET LOSS
A2: Historical summary components are seeded at Line scope; enter new detail at Line, Section, or Cavity scope.
A4: JobChangeImpactID | B4: JobChangeEventID | C4: ProductionEventID | D4: FactoryCode | E4: LineNumber | F4: EventDate | G4: ShiftCode | H4: ToOrderNumber | I4: LossArea | J4: AssetScopeKey | K4: AssetLevel | L4: SectionNumber | M4: CavityNumber | N4: Reason | O4: StartDateTime | P4: EndDateTime | Q4: DurationHrs | R4: TotalActiveCavities | S4: AffectedActiveCavities | T4: CapacityImpactPct | U4: LineEquivalentLossHrs | V4: DesignedCyclesPerMin | W4: EstimatedLostUnits | X4: ImpactSource | Y4: ParentEventCheck | Z4: ScopeCheck | AA4: DurationCheck | AB4: DataQualityCheck
A5: JCI-000001 | B5: JC-KG01-L21-20251021-AM-ORD-2025-00019-ORD-2025-00020 | C5: PE-KG01-L21-20251021-AM-ORD-2025-00020 | D5: KG01 | E5: 21 | F5: 45951 | G5: AM | H5: ORD-2025-00020 | I5: T1 | J5: L21-S01-C1 | K5: Cavity | L5: 1 | M5: 1 | N5: Historical summary | Q5: 3.08 | R5: =IF(B5="","",SUMIF(ProductionConfiguration!$B$5:$B$914,C5,ProductionConfiguration!$S$5:$S$914)) -> 20 | S5: =IF(B5="","",IF(K5="Line",R5,IF(K5="Section",SUMIFS(ProductionConfiguration!$S$5:$S$914,ProductionConfiguration!$B$5:$B$914,C5,ProductionConfiguration!$I$5:$I$914,L5),IF(K5="Cavity",IF(M5=1,SUMIFS(ProductionConfiguration!$P$5:$P$914,ProductionConfiguration!$B$5:$B$914,C5,ProductionConfiguration!$I$5:$I$914,L5),IF(M5=2,SUMIFS(ProductionConfiguration!$Q$5:$Q$914,ProductionConfiguration!$B$5:$B$914,C5,ProductionConfiguration!$I$5:$I$914,L5),SUMIFS(ProductionConfiguration!$R$5:$R$914,ProductionConfiguration!$B$5:$B$914,C5,ProductionConfiguration!$I$5:$I$914,L5))),0)))) -> 1 | T5: =IF(B5="","",IFERROR(S5/R5,0)) -> 0.05 | U5: =IF(B5="","",Q5*T5) -> 0.154 | V5: =IF(C5="","",SUMIF(DailyProduction!$Q$5:$Q$100,C5,DailyProduction!$J$5:$J$100)) -> 10 | W5: =IF(B5="","",Q5*60*V5*S5) -> 1848 | X5: HistoricalSummary | Y5: =IF(B5="","",IF(COUNTIF(JobChange!$S$5:$S$100,B5)=1,"OK","CHECK")) -> OK | Z5: =IF(B5="","",IF(OR(AND(K5="Line",J5="L"&E5),AND(K5="Section",J5="L"&E5&"-S"&TEXT(L5,"00")),AND(K5="Cavity",J5="L"&E5&"-S"&TEXT(L5,"00")&"-C"&M5)),"OK","CHECK")) -> OK | AA5: =IF(B5="","",IF(AND(Q5>0,OR(AND(O5="",P5=""),AND(O5<>"",P5<>"",P5>=O5,ABS(Q5-((P5-O5)*24))<=0.01))),"OK","CHECK")) -> OK | AB5: =IF(B5="","",IF(AND(Y5="OK",Z5="OK",AA5="OK",R5>0,S5>0),"OK","CHECK")) -> OK
A6: JCI-000002 | B6: JC-KG01-L21-20251021-AM-ORD-2025-00019-ORD-2025-00020 | C6: PE-KG01-L21-20251021-AM-ORD-2025-00020 | D6: KG01 | E6: 21 | F6: 45951 | G6: AM | H6: ORD-2025-00020 | I6: T2 | J6: L21-S02 | K6: Section | L6: 2 | N6: Historical summary | Q6: 1 | R6: =IF(B6="","",SUMIF(ProductionConfiguration!$B$5:$B$914,C6,ProductionConfiguration!$S$5:$S$914)) -> 20 | S6: =IF(B6="","",IF(K6="Line",R6,IF(K6="Section",SUMIFS(ProductionConfiguration!$S$5:$S$914,ProductionConfiguration!$B$5:$B$914,C6,ProductionConfiguration!$I$5:$I$914,L6),IF(K6="Cavity",IF(M6=1,SUMIFS(ProductionConfiguration!$P$5:$P$914,ProductionConfiguration!$B$5:$B$914,C6,ProductionConfiguration!$I$5:$I$914,L6),IF(M6=2,SUMIFS(ProductionConfiguration!$Q$5:$Q$914,ProductionConfiguration!$B$5:$B$914,C6,ProductionConfiguration!$I$5:$I$914,L6),SUMIFS(ProductionConfiguration!$R$5:$R$914,ProductionConfiguration!$B$5:$B$914,C6,ProductionConfiguration!$I$5:$I$914,L6))),0)))) -> 2 | T6: =IF(B6="","",IFERROR(S6/R6,0)) -> 0.1 | U6: =IF(B6="","",Q6*T6) -> 0.1 | V6: =IF(C6="","",SUMIF(DailyProduction!$Q$5:$Q$100,C6,DailyProduction!$J$5:$J$100)) -> 10 | W6: =IF(B6="","",Q6*60*V6*S6) -> 1200 | X6: HistoricalSummary | Y6: =IF(B6="","",IF(COUNTIF(JobChange!$S$5:$S$100,B6)=1,"OK","CHECK")) -> OK | Z6: =IF(B6="","",IF(OR(AND(K6="Line",J6="L"&E6),AND(K6="Section",J6="L"&E6&"-S"&TEXT(L6,"00")),AND(K6="Cavity",J6="L"&E6&"-S"&TEXT(L6,"00")&"-C"&M6)),"OK","CHECK")) -> OK | AA6: =IF(B6="","",IF(AND(Q6>0,OR(AND(O6="",P6=""),AND(O6<>"",P6<>"",P6>=O6,ABS(Q6-((P6-O6)*24))<=0.01))),"OK","CHECK")) -> OK | AB6: =IF(B6="","",IF(AND(Y6="OK",Z6="OK",AA6="OK",R6>0,S6>0),"OK","CHECK")) -> OK
A7: JCI-000003 | B7: JC-KG01-L21-20251021-AM-ORD-2025-00019-ORD-2025-00020 | C7: PE-KG01-L21-20251021-AM-ORD-2025-00020 | D7: KG01 | E7: 21 | F7: 45951 | G7: AM | H7: ORD-2025-00020 | I7: Trial | J7: L21-S03 | K7: Section | L7: 3 | N7: Historical summary | Q7: 0.19 | R7: =IF(B7="","",SUMIF(ProductionConfiguration!$B$5:$B$914,C7,ProductionConfiguration!$S$5:$S$914)) -> 20 | S7: =IF(B7="","",IF(K7="Line",R7,IF(K7="Section",SUMIFS(ProductionConfiguration!$S$5:$S$914,ProductionConfiguration!$B$5:$B$914,C7,ProductionConfiguration!$I$5:$I$914,L7),IF(K7="Cavity",IF(M7=1,SUMIFS(ProductionConfiguration!$P$5:$P$914,ProductionConfiguration!$B$5:$B$914,C7,ProductionConfiguration!$I$5:$I$914,L7),IF(M7=2,SUMIFS(ProductionConfiguration!$Q$5:$Q$914,ProductionConfiguration!$B$5:$B$914,C7,ProductionConfiguration!$I$5:$I$914,L7),SUMIFS(ProductionConfiguration!$R$5:$R$914,ProductionConfiguration!$B$5:$B$914,C7,ProductionConfiguration!$I$5:$I$914,L7))),0)))) -> 2 | T7: =IF(B7="","",IFERROR(S7/R7,0)) -> 0.1 | U7: =IF(B7="","",Q7*T7) -> 0.019 | V7: =IF(C7="","",SUMIF(DailyProduction!$Q$5:$Q$100,C7,DailyProduction!$J$5:$J$100)) -> 10 | W7: =IF(B7="","",Q7*60*V7*S7) -> 228 | X7: HistoricalSummary | Y7: =IF(B7="","",IF(COUNTIF(JobChange!$S$5:$S$100,B7)=1,"OK","CHECK")) -> OK | Z7: =IF(B7="","",IF(OR(AND(K7="Line",J7="L"&E7),AND(K7="Section",J7="L"&E7&"-S"&TEXT(L7,"00")),AND(K7="Cavity",J7="L"&E7&"-S"&TEXT(L7,"00")&"-C"&M7)),"OK","CHECK")) -> OK | AA7: =IF(B7="","",IF(AND(Q7>0,OR(AND(O7="",P7=""),AND(O7<>"",P7<>"",P7>=O7,ABS(Q7-((P7-O7)*24))<=0.01))),"OK","CHECK")) -> OK | AB7: =IF(B7="","",IF(AND(Y7="OK",Z7="OK",AA7="OK",R7>0,S7>0),"OK","CHECK")) -> OK
A8: JCI-000004 | B8: JC-KG01-L21-20251025-AM-ORD-2025-00020-ORD-2025-00021 | C8: PE-KG01-L21-20251025-AM-ORD-2025-00021 | D8: KG01 | E8: 21 | F8: 45955 | G8: AM | H8: ORD-2025-00021 | I8: T1 | J8: L21-S04 | K8: Section | L8: 4 | N8: Historical summary | Q8: 3.15 | R8: =IF(B8="","",SUMIF(ProductionConfiguration!$B$5:$B$914,C8,ProductionConfiguration!$S$5:$S$914)) -> 30 | S8: =IF(B8="","",IF(K8="Line",R8,IF(K8="Section",SUMIFS(ProductionConfiguration!$S$5:$S$914,ProductionConfiguration!$B$5:$B$914,C8,ProductionConfiguration!$I$5:$I$914,L8),IF(K8="Cavity",IF(M8=1,SUMIFS(ProductionConfiguration!$P$5:$P$914,ProductionConfiguration!$B$5:$B$914,C8,ProductionConfiguration!$I$5:$I$914,L8),IF(M8=2,SUMIFS(ProductionConfiguration!$Q$5:$Q$914,ProductionConfiguration!$B$5:$B$914,C8,ProductionConfiguration!$I$5:$I$914,L8),SUMIFS(ProductionConfiguration!$R$5:$R$914,ProductionConfiguration!$B$5:$B$914,C8,ProductionConfiguration!$I$5:$I$914,L8))),0)))) -> 3 | T8: =IF(B8="","",IFERROR(S8/R8,0)) -> 0.1 | U8: =IF(B8="","",Q8*T8) -> 0.315 | V8: =IF(C8="","",SUMIF(DailyProduction!$Q$5:$Q$100,C8,DailyProduction!$J$5:$J$100)) -> 11 | W8: =IF(B8="","",Q8*60*V8*S8) -> 6237 | X8: HistoricalSummary | Y8: =IF(B8="","",IF(COUNTIF(JobChange!$S$5:$S$100,B8)=1,"OK","CHECK")) -> OK | Z8: =IF(B8="","",IF(OR(AND(K8="Line",J8="L"&E8),AND(K8="Section",J8="L"&E8&"-S"&TEXT(L8,"00")),AND(K8="Cavity",J8="L"&E8&"-S"&TEXT(L8,"00")&"-C"&M8)),"OK","CHECK")) -> OK | AA8: =IF(B8="","",IF(AND(Q8>0,OR(AND(O8="",P8=""),AND(O8<>"",P8<>"",P8>=O8,ABS(Q8-((P8-O8)*24))<=0.01))),"OK","CHECK")) -> OK | AB8: =IF(B8="","",IF(AND(Y8="OK",Z8="OK",AA8="OK",R8>0,S8>0),"OK","CHECK")) -> OK
A9: JCI-000005 | B9: JC-KG01-L21-20251025-AM-ORD-2025-00020-ORD-2025-00021 | C9: PE-KG01-L21-20251025-AM-ORD-2025-00021 | D9: KG01 | E9: 21 | F9: 45955 | G9: AM | H9: ORD-2025-00021 | I9: T2 | J9: L21-S05 | K9: Section | L9: 5 | N9: Historical summary | Q9: 1.2 | R9: =IF(B9="","",SUMIF(ProductionConfiguration!$B$5:$B$914,C9,ProductionConfiguration!$S$5:$S$914)) -> 30 | S9: =IF(B9="","",IF(K9="Line",R9,IF(K9="Section",SUMIFS(ProductionConfiguration!$S$5:$S$914,ProductionConfiguration!$B$5:$B$914,C9,ProductionConfiguration!$I$5:$I$914,L9),IF(K9="Cavity",IF(M9=1,SUMIFS(ProductionConfiguration!$P$5:$P$914,ProductionConfiguration!$B$5:$B$914,C9,ProductionConfiguration!$I$5:$I$914,L9),IF(M9=2,SUMIFS(ProductionConfiguration!$Q$5:$Q$914,ProductionConfiguration!$B$5:$B$914,C9,ProductionConfiguration!$I$5:$I$914,L9),SUMIFS(ProductionConfiguration!$R$5:$R$914,ProductionConfiguration!$B$5:$B$914,C9,ProductionConfiguration!$I$5:$I$914,L9))),0)))) -> 3 | T9: =IF(B9="","",IFERROR(S9/R9,0)) -> 0.1 | U9: =IF(B9="","",Q9*T9) -> 0.12 | V9: =IF(C9="","",SUMIF(DailyProduction!$Q$5:$Q$100,C9,DailyProduction!$J$5:$J$100)) -> 11 | W9: =IF(B9="","",Q9*60*V9*S9) -> 2376 | X9: HistoricalSummary | Y9: =IF(B9="","",IF(COUNTIF(JobChange!$S$5:$S$100,B9)=1,"OK","CHECK")) -> OK | Z9: =IF(B9="","",IF(OR(AND(K9="Line",J9="L"&E9),AND(K9="Section",J9="L"&E9&"-S"&TEXT(L9,"00")),AND(K9="Cavity",J9="L"&E9&"-S"&TEXT(L9,"00")&"-C"&M9)),"OK","CHECK")) -> OK | AA9: =IF(B9="","",IF(AND(Q9>0,OR(AND(O9="",P9=""),AND(O9<>"",P9<>"",P9>=O9,ABS(Q9-((P9-O9)*24))<=0.01))),"OK","CHECK")) -> OK | AB9: =IF(B9="","",IF(AND(Y9="OK",Z9="OK",AA9="OK",R9>0,S9>0),"OK","CHECK")) -> OK
A10: JCI-000006 | B10: JC-KG01-L21-20251025-AM-ORD-2025-00020-ORD-2025-00021 | C10: PE-KG01-L21-20251025-AM-ORD-2025-00021 | D10: KG01 | E10: 21 | F10: 45955 | G10: AM | H10: ORD-2025-00021 | I10: Trial | J10: L21-S01-C2 | K10: Cavity | L10: 1 | M10: 2 | N10: Historical summary | Q10: 0.1 | R10: =IF(B10="","",SUMIF(ProductionConfiguration!$B$5:$B$914,C10,ProductionConfiguration!$S$5:$S$914)) -> 30 | S10: =IF(B10="","",IF(K10="Line",R10,IF(K10="Section",SUMIFS(ProductionConfiguration!$S$5:$S$914,ProductionConfiguration!$B$5:$B$914,C10,ProductionConfiguration!$I$5:$I$914,L10),IF(K10="Cavity",IF(M10=1,SUMIFS(ProductionConfiguration!$P$5:$P$914,ProductionConfiguration!$B$5:$B$914,C10,ProductionConfiguration!$I$5:$I$914,L10),IF(M10=2,SUMIFS(ProductionConfiguration!$Q$5:$Q$914,ProductionConfiguration!$B$5:$B$914,C10,ProductionConfiguration!$I$5:$I$914,L10),SUMIFS(ProductionConfiguration!$R$5:$R$914,ProductionConfiguration!$B$5:$B$914,C10,ProductionConfiguration!$I$5:$I$914,L10))),0)))) -> 1 | T10: =IF(B10="","",IFERROR(S10/R10,0)) -> 0.033333333 | U10: =IF(B10="","",Q10*T10) -> 0.0033333333 | V10: =IF(C10="","",SUMIF(DailyProduction!$Q$5:$Q$100,C10,DailyProduction!$J$5:$J$100)) -> 11 | W10: =IF(B10="","",Q10*60*V10*S10) -> 66 | X10: HistoricalSummary | Y10: =IF(B10="","",IF(COUNTIF(JobChange!$S$5:$S$100,B10)=1,"OK","CHECK")) -> OK | Z10: =IF(B10="","",IF(OR(AND(K10="Line",J10="L"&E10),AND(K10="Section",J10="L"&E10&"-S"&TEXT(L10,"00")),AND(K10="Cavity",J10="L"&E10&"-S"&TEXT(L10,"00")&"-C"&M10)),"OK","CHECK")) -> OK | AA10: =IF(B10="","",IF(AND(Q10>0,OR(AND(O10="",P10=""),AND(O10<>"",P10<>"",P10>=O10,ABS(Q10-((P10-O10)*24))<=0.01))),"OK","CHECK")) -> OK | AB10: =IF(B10="","",IF(AND(Y10="OK",Z10="OK",AA10="OK",R10>0,S10>0),"OK","CHECK")) -> OK
A11: JCI-000007 | B11: JC-KG01-L21-20251025-AM-ORD-2025-00020-ORD-2025-00021 | C11: PE-KG01-L21-20251025-AM-ORD-2025-00021 | D11: KG01 | E11: 21 | F11: 45955 | G11: AM | H11: ORD-2025-00021 | I11: HE | J11: L21-S01-C1 | K11: Cavity | L11: 1 | M11: 1 | N11: Gob Weight Adjustment | Q11: 0.51 | R11: =IF(B11="","",SUMIF(ProductionConfiguration!$B$5:$B$914,C11,ProductionConfiguration!$S$5:$S$914)) -> 30 | S11: =IF(B11="","",IF(K11="Line",R11,IF(K11="Section",SUMIFS(ProductionConfiguration!$S$5:$S$914,ProductionConfiguration!$B$5:$B$914,C11,ProductionConfiguration!$I$5:$I$914,L11),IF(K11="Cavity",IF(M11=1,SUMIFS(ProductionConfiguration!$P$5:$P$914,ProductionConfiguration!$B$5:$B$914,C11,ProductionConfiguration!$I$5:$I$914,L11),IF(M11=2,SUMIFS(ProductionConfiguration!$Q$5:$Q$914,ProductionConfiguration!$B$5:$B$914,C11,ProductionConfiguration!$I$5:$I$914,L11),SUMIFS(ProductionConfiguration!$R$5:$R$914,ProductionConfiguration!$B$5:$B$914,C11,ProductionConfiguration!$I$5:$I$914,L11))),0)))) -> 1 | T11: =IF(B11="","",IFERROR(S11/R11,0)) -> 0.033333333 | U11: =IF(B11="","",Q11*T11) -> 0.017 | V11: =IF(C11="","",SUMIF(DailyProduction!$Q$5:$Q$100,C11,DailyProduction!$J$5:$J$100)) -> 11 | W11: =IF(B11="","",Q11*60*V11*S11) -> 336.6 | X11: HistoricalSummary | Y11: =IF(B11="","",IF(COUNTIF(JobChange!$S$5:$S$100,B11)=1,"OK","CHECK")) -> OK | Z11: =IF(B11="","",IF(OR(AND(K11="Line",J11="L"&E11),AND(K11="Section",J11="L"&E11&"-S"&TEXT(L11,"00")),AND(K11="Cavity",J11="L"&E11&"-S"&TEXT(L11,"00")&"-C"&M11)),"OK","CHECK")) -> OK | AA11: =IF(B11="","",IF(AND(Q11>0,OR(AND(O11="",P11=""),AND(O11<>"",P11<>"",P11>=O11,ABS(Q11-((P11-O11)*24))<=0.01))),"OK","CHECK")) -> OK | AB11: =IF(B11="","",IF(AND(Y11="OK",Z11="OK",AA11="OK",R11>0,S11>0),"OK","CHECK")) -> OK
A12: JCI-000008 | B12: JC-KG01-L22-20251020-AM-ORD-2025-00055-ORD-2025-00056 | C12: PE-KG01-L22-20251020-AM-ORD-2025-00056 | D12: KG01 | E12: 22 | F12: 45950 | G12: AM | H12: ORD-2025-00056 | I12: T1 | J12: L22-S02 | K12: Section | L12: 2 | N12: Historical summary | Q12: 6.84 | R12: =IF(B12="","",SUMIF(ProductionConfiguration!$B$5:$B$914,C12,ProductionConfiguration!$S$5:$S$914)) -> 20 | S12: =IF(B12="","",IF(K12="Line",R12,IF(K12="Section",SUMIFS(ProductionConfiguration!$S$5:$S$914,ProductionConfiguration!$B$5:$B$914,C12,ProductionConfiguration!$I$5:$I$914,L12),IF(K12="Cavity",IF(M12=1,SUMIFS(ProductionConfiguration!$P$5:$P$914,ProductionConfiguration!$B$5:$B$914,C12,ProductionConfiguration!$I$5:$I$914,L12),IF(M12=2,SUMIFS(ProductionConfiguration!$Q$5:$Q$914,ProductionConfiguration!$B$5:$B$914,C12,ProductionConfiguration!$I$5:$I$914,L12),SUMIFS(ProductionConfiguration!$R$5:$R$914,ProductionConfiguration!$B$5:$B$914,C12,ProductionConfiguration!$I$5:$I$914,L12))),0)))) -> 2 | T12: =IF(B12="","",IFERROR(S12/R12,0)) -> 0.1 | U12: =IF(B12="","",Q12*T12) -> 0.684 | V12: =IF(C12="","",SUMIF(DailyProduction!$Q$5:$Q$100,C12,DailyProduction!$J$5:$J$100)) -> 10 | W12: =IF(B12="","",Q12*60*V12*S12) -> 8208 | X12: HistoricalSummary | Y12: =IF(B12="","",IF(COUNTIF(JobChange!$S$5:$S$100,B12)=1,"OK","CHECK")) -> OK | Z12: =IF(B12="","",IF(OR(AND(K12="Line",J12="L"&E12),AND(K12="Section",J12="L"&E12&"-S"&TEXT(L12,"00")),AND(K12="Cavity",J12="L"&E12&"-S"&TEXT(L12,"00")&"-C"&M12)),"OK","CHECK")) -> OK | AA12: =IF(B12="","",IF(AND(Q12>0,OR(AND(O12="",P12=""),AND(O12<>"",P12<>"",P12>=O12,ABS(Q12-((P12-O12)*24))<=0.01))),"OK","CHECK")) -> OK | AB12: =IF(B12="","",IF(AND(Y12="OK",Z12="OK",AA12="OK",R12>0,S12>0),"OK","CHECK")) -> OK
A13: JCI-000009 | B13: JC-KG01-L22-20251020-AM-ORD-2025-00055-ORD-2025-00056 | C13: PE-KG01-L22-20251020-AM-ORD-2025-00056 | D13: KG01 | E13: 22 | F13: 45950 | G13: AM | H13: ORD-2025-00056 | I13: T2 | J13: L22-S03 | K13: Section | L13: 3 | N13: Historical summary | Q13: 1.63 | R13: =IF(B13="","",SUMIF(ProductionConfiguration!$B$5:$B$914,C13,ProductionConfiguration!$S$5:$S$914)) -> 20 | S13: =IF(B13="","",IF(K13="Line",R13,IF(K13="Section",SUMIFS(ProductionConfiguration!$S$5:$S$914,ProductionConfiguration!$B$5:$B$914,C13,ProductionConfiguration!$I$5:$I$914,L13),IF(K13="Cavity",IF(M13=1,SUMIFS(ProductionConfiguration!$P$5:$P$914,ProductionConfiguration!$B$5:$B$914,C13,ProductionConfiguration!$I$5:$I$914,L13),IF(M13=2,SUMIFS(ProductionConfiguration!$Q$5:$Q$914,ProductionConfiguration!$B$5:$B$914,C13,ProductionConfiguration!$I$5:$I$914,L13),SUMIFS(ProductionConfiguration!$R$5:$R$914,ProductionConfiguration!$B$5:$B$914,C13,ProductionConfiguration!$I$5:$I$914,L13))),0)))) -> 2 | T13: =IF(B13="","",IFERROR(S13/R13,0)) -> 0.1 | U13: =IF(B13="","",Q13*T13) -> 0.163 | V13: =IF(C13="","",SUMIF(DailyProduction!$Q$5:$Q$100,C13,DailyProduction!$J$5:$J$100)) -> 10 | W13: =IF(B13="","",Q13*60*V13*S13) -> 1956 | X13: HistoricalSummary | Y13: =IF(B13="","",IF(COUNTIF(JobChange!$S$5:$S$100,B13)=1,"OK","CHECK")) -> OK | Z13: =IF(B13="","",IF(OR(AND(K13="Line",J13="L"&E13),AND(K13="Section",J13="L"&E13&"-S"&TEXT(L13,"00")),AND(K13="Cavity",J13="L"&E13&"-S"&TEXT(L13,"00")&"-C"&M13)),"OK","CHECK")) -> OK | AA13: =IF(B13="","",IF(AND(Q13>0,OR(AND(O13="",P13=""),AND(O13<>"",P13<>"",P13>=O13,ABS(Q13-((P13-O13)*24))<=0.01))),"OK","CHECK")) -> OK | AB13: =IF(B13="","",IF(AND(Y13="OK",Z13="OK",AA13="OK",R13>0,S13>0),"OK","CHECK")) -> OK
A14: JCI-000010 | B14: JC-KG01-L22-20251020-AM-ORD-2025-00055-ORD-2025-00056 | C14: PE-KG01-L22-20251020-AM-ORD-2025-00056 | D14: KG01 | E14: 22 | F14: 45950 | G14: AM | H14: ORD-2025-00056 | I14: Trial | J14: L22-S03-C1 | K14: Cavity | L14: 3 | M14: 1 | N14: Historical summary | Q14: 0.78 | R14: =IF(B14="","",SUMIF(ProductionConfiguration!$B$5:$B$914,C14,ProductionConfiguration!$S$5:$S$914)) -> 20 | S14: =IF(B14="","",IF(K14="Line",R14,IF(K14="Section",SUMIFS(ProductionConfiguration!$S$5:$S$914,ProductionConfiguration!$B$5:$B$914,C14,ProductionConfiguration!$I$5:$I$914,L14),IF(K14="Cavity",IF(M14=1,SUMIFS(ProductionConfiguration!$P$5:$P$914,ProductionConfiguration!$B$5:$B$914,C14,ProductionConfiguration!$I$5:$I$914,L14),IF(M14=2,SUMIFS(ProductionConfiguration!$Q$5:$Q$914,ProductionConfiguration!$B$5:$B$914,C14,ProductionConfiguration!$I$5:$I$914,L14),SUMIFS(ProductionConfiguration!$R$5:$R$914,ProductionConfiguration!$B$5:$B$914,C14,ProductionConfiguration!$I$5:$I$914,L14))),0)))) -> 1 | T14: =IF(B14="","",IFERROR(S14/R14,0)) -> 0.05 | U14: =IF(B14="","",Q14*T14) -> 0.039 | V14: =IF(C14="","",SUMIF(DailyProduction!$Q$5:$Q$100,C14,DailyProduction!$J$5:$J$100)) -> 10 | W14: =IF(B14="","",Q14*60*V14*S14) -> 468 | X14: HistoricalSummary | Y14: =IF(B14="","",IF(COUNTIF(JobChange!$S$5:$S$100,B14)=1,"OK","CHECK")) -> OK | Z14: =IF(B14="","",IF(OR(AND(K14="Line",J14="L"&E14),AND(K14="Section",J14="L"&E14&"-S"&TEXT(L14,"00")),AND(K14="Cavity",J14="L"&E14&"-S"&TEXT(L14,"00")&"-C"&M14)),"OK","CHECK")) -> OK | AA14: =IF(B14="","",IF(AND(Q14>0,OR(AND(O14="",P14=""),AND(O14<>"",P14<>"",P14>=O14,ABS(Q14-((P14-O14)*24))<=0.01))),"OK","CHECK")) -> OK | AB14: =IF(B14="","",IF(AND(Y14="OK",Z14="OK",AA14="OK",R14>0,S14>0),"OK","CHECK")) -> OK
A15: JCI-000011 | B15: JC-KG01-L22-20251020-AM-ORD-2025-00055-ORD-2025-00056 | C15: PE-KG01-L22-20251020-AM-ORD-2025-00056 | D15: KG01 | E15: 22 | F15: 45950 | G15: AM | H15: ORD-2025-00056 | I15: Palletizer | J15: L22-S04 | K15: Section | L15: 4 | N15: Pallet Conveyor Jam | Q15: 0.24 | R15: =IF(B15="","",SUMIF(ProductionConfiguration!$B$5:$B$914,C15,ProductionConfiguration!$S$5:$S$914)) -> 20 | S15: =IF(B15="","",IF(K15="Line",R15,IF(K15="Section",SUMIFS(ProductionConfiguration!$S$5:$S$914,ProductionConfiguration!$B$5:$B$914,C15,ProductionConfiguration!$I$5:$I$914,L15),IF(K15="Cavity",IF(M15=1,SUMIFS(ProductionConfiguration!$P$5:$P$914,ProductionConfiguration!$B$5:$B$914,C15,ProductionConfiguration!$I$5:$I$914,L15),IF(M15=2,SUMIFS(ProductionConfiguration!$Q$5:$Q$914,ProductionConfiguration!$B$5:$B$914,C15,ProductionConfiguration!$I$5:$I$914,L15),SUMIFS(ProductionConfiguration!$R$5:$R$914,ProductionConfiguration!$B$5:$B$914,C15,ProductionConfiguration!$I$5:$I$914,L15))),0)))) -> 2 | T15: =IF(B15="","",IFERROR(S15/R15,0)) -> 0.1 | U15: =IF(B15="","",Q15*T15) -> 0.024 | V15: =IF(C15="","",SUMIF(DailyProduction!$Q$5:$Q$100,C15,DailyProduction!$J$5:$J$100)) -> 10 | W15: =IF(B15="","",Q15*60*V15*S15) -> 288 | X15: HistoricalSummary | Y15: =IF(B15="","",IF(COUNTIF(JobChange!$S$5:$S$100,B15)=1,"OK","CHECK")) -> OK | Z15: =IF(B15="","",IF(OR(AND(K15="Line",J15="L"&E15),AND(K15="Section",J15="L"&E15&"-S"&TEXT(L15,"00")),AND(K15="Cavity",J15="L"&E15&"-S"&TEXT(L15,"00")&"-C"&M15)),"OK","CHECK")) -> OK | AA15: =IF(B15="","",IF(AND(Q15>0,OR(AND(O15="",P15=""),AND(O15<>"",P15<>"",P15>=O15,ABS(Q15-((P15-O15)*24))<=0.01))),"OK","CHECK")) -> OK | AB15: =IF(B15="","",IF(AND(Y15="OK",Z15="OK",AA15="OK",R15>0,S15>0),"OK","CHECK")) -> OK
A16: JCI-000012 | B16: JC-KG01-L22-20251026-AM-ORD-2025-00057-ORD-2025-00058 | C16: PE-KG01-L22-20251026-AM-ORD-2025-00058 | D16: KG01 | E16: 22 | F16: 45956 | G16: AM | H16: ORD-2025-00058 | I16: T1 | J16: L22-S05 | K16: Section | L16: 5 | N16: Historical summary | Q16: 5.65 | R16: =IF(B16="","",SUMIF(ProductionConfiguration!$B$5:$B$914,C16,ProductionConfiguration!$S$5:$S$914)) -> 30 | S16: =IF(B16="","",IF(K16="Line",R16,IF(K16="Section",SUMIFS(ProductionConfiguration!$S$5:$S$914,ProductionConfiguration!$B$5:$B$914,C16,ProductionConfiguration!$I$5:$I$914,L16),IF(K16="Cavity",IF(M16=1,SUMIFS(ProductionConfiguration!$P$5:$P$914,ProductionConfiguration!$B$5:$B$914,C16,ProductionConfiguration!$I$5:$I$914,L16),IF(M16=2,SUMIFS(ProductionConfiguration!$Q$5:$Q$914,ProductionConfiguration!$B$5:$B$914,C16,ProductionConfiguration!$I$5:$I$914,L16),SUMIFS(ProductionConfiguration!$R$5:$R$914,ProductionConfiguration!$B$5:$B$914,C16,ProductionConfiguration!$I$5:$I$914,L16))),0)))) -> 3 | T16: =IF(B16="","",IFERROR(S16/R16,0)) -> 0.1 | U16: =IF(B16="","",Q16*T16) -> 0.565 | V16: =IF(C16="","",SUMIF(DailyProduction!$Q$5:$Q$100,C16,DailyProduction!$J$5:$J$100)) -> 14 | W16: =IF(B16="","",Q16*60*V16*S16) -> 14238 | X16: HistoricalSummary | Y16: =IF(B16="","",IF(COUNTIF(JobChange!$S$5:$S$100,B16)=1,"OK","CHECK")) -> OK | Z16: =IF(B16="","",IF(OR(AND(K16="Line",J16="L"&E16),AND(K16="Section",J16="L"&E16&"-S"&TEXT(L16,"00")),AND(K16="Cavity",J16="L"&E16&"-S"&TEXT(L16,"00")&"-C"&M16)),"OK","CHECK")) -> OK | AA16: =IF(B16="","",IF(AND(Q16>0,OR(AND(O16="",P16=""),AND(O16<>"",P16<>"",P16>=O16,ABS(Q16-((P16-O16)*24))<=0.01))),"OK","CHECK")) -> OK | AB16: =IF(B16="","",IF(AND(Y16="OK",Z16="OK",AA16="OK",R16>0,S16>0),"OK","CHECK")) -> OK
A17: JCI-000013 | B17: JC-KG01-L22-20251026-AM-ORD-2025-00057-ORD-2025-00058 | C17: PE-KG01-L22-20251026-AM-ORD-2025-00058 | D17: KG01 | E17: 22 | F17: 45956 | G17: AM | H17: ORD-2025-00058 | I17: T2 | J17: L22-S02-C2 | K17: Cavity | L17: 2 | M17: 2 | N17: Historical summary | Q17: 1.35 | R17: =IF(B17="","",SUMIF(ProductionConfiguration!$B$5:$B$914,C17,ProductionConfiguration!$S$5:$S$914)) -> 30 | S17: =IF(B17="","",IF(K17="Line",R17,IF(K17="Section",SUMIFS(ProductionConfiguration!$S$5:$S$914,ProductionConfiguration!$B$5:$B$914,C17,ProductionConfiguration!$I$5:$I$914,L17),IF(K17="Cavity",IF(M17=1,SUMIFS(ProductionConfiguration!$P$5:$P$914,ProductionConfiguration!$B$5:$B$914,C17,ProductionConfiguration!$I$5:$I$914,L17),IF(M17=2,SUMIFS(ProductionConfiguration!$Q$5:$Q$914,ProductionConfiguration!$B$5:$B$914,C17,ProductionConfiguration!$I$5:$I$914,L17),SUMIFS(ProductionConfiguration!$R$5:$R$914,ProductionConfiguration!$B$5:$B$914,C17,ProductionConfiguration!$I$5:$I$914,L17))),0)))) -> 1 | T17: =IF(B17="","",IFERROR(S17/R17,0)) -> 0.033333333 | U17: =IF(B17="","",Q17*T17) -> 0.045 | V17: =IF(C17="","",SUMIF(DailyProduction!$Q$5:$Q$100,C17,DailyProduction!$J$5:$J$100)) -> 14 | W17: =IF(B17="","",Q17*60*V17*S17) -> 1134 | X17: HistoricalSummary | Y17: =IF(B17="","",IF(COUNTIF(JobChange!$S$5:$S$100,B17)=1,"OK","CHECK")) -> OK | Z17: =IF(B17="","",IF(OR(AND(K17="Line",J17="L"&E17),AND(K17="Section",J17="L"&E17&"-S"&TEXT(L17,"00")),AND(K17="Cavity",J17="L"&E17&"-S"&TEXT(L17,"00")&"-C"&M17)),"OK","CHECK")) -> OK | AA17: =IF(B17="","",IF(AND(Q17>0,OR(AND(O17="",P17=""),AND(O17<>"",P17<>"",P17>=O17,ABS(Q17-((P17-O17)*24))<=0.01))),"OK","CHECK")) -> OK | AB17: =IF(B17="","",IF(AND(Y17="OK",Z17="OK",AA17="OK",R17>0,S17>0),"OK","CHECK")) -> OK
A18: JCI-000014 | B18: JC-KG01-L22-20251026-AM-ORD-2025-00057-ORD-2025-00058 | C18: PE-KG01-L22-20251026-AM-ORD-2025-00058 | D18: KG01 | E18: 22 | F18: 45956 | G18: AM | H18: ORD-2025-00058 | I18: Trial | J18: L22-S02 | K18: Section | L18: 2 | N18: Historical summary | Q18: 0.78 | R18: =IF(B18="","",SUMIF(ProductionConfiguration!$B$5:$B$914,C18,ProductionConfiguration!$S$5:$S$914)) -> 30 | S18: =IF(B18="","",IF(K18="Line",R18,IF(K18="Section",SUMIFS(ProductionConfiguration!$S$5:$S$914,ProductionConfiguration!$B$5:$B$914,C18,ProductionConfiguration!$I$5:$I$914,L18),IF(K18="Cavity",IF(M18=1,SUMIFS(ProductionConfiguration!$P$5:$P$914,ProductionConfiguration!$B$5:$B$914,C18,ProductionConfiguration!$I$5:$I$914,L18),IF(M18=2,SUMIFS(ProductionConfiguration!$Q$5:$Q$914,ProductionConfiguration!$B$5:$B$914,C18,ProductionConfiguration!$I$5:$I$914,L18),SUMIFS(ProductionConfiguration!$R$5:$R$914,ProductionConfiguration!$B$5:$B$914,C18,ProductionConfiguration!$I$5:$I$914,L18))),0)))) -> 3 | T18: =IF(B18="","",IFERROR(S18/R18,0)) -> 0.1 | U18: =IF(B18="","",Q18*T18) -> 0.078 | V18: =IF(C18="","",SUMIF(DailyProduction!$Q$5:$Q$100,C18,DailyProduction!$J$5:$J$100)) -> 14 | W18: =IF(B18="","",Q18*60*V18*S18) -> 1965.6 | X18: HistoricalSummary | Y18: =IF(B18="","",IF(COUNTIF(JobChange!$S$5:$S$100,B18)=1,"OK","CHECK")) -> OK | Z18: =IF(B18="","",IF(OR(AND(K18="Line",J18="L"&E18),AND(K18="Section",J18="L"&E18&"-S"&TEXT(L18,"00")),AND(K18="Cavity",J18="L"&E18&"-S"&TEXT(L18,"00")&"-C"&M18)),"OK","CHECK")) -> OK | AA18: =IF(B18="","",IF(AND(Q18>0,OR(AND(O18="",P18=""),AND(O18<>"",P18<>"",P18>=O18,ABS(Q18-((P18-O18)*24))<=0.01))),"OK","CHECK")) -> OK | AB18: =IF(B18="","",IF(AND(Y18="OK",Z18="OK",AA18="OK",R18>0,S18>0),"OK","CHECK")) -> OK
A19: JCI-000015 | B19: JC-KG01-L22-20251026-AM-ORD-2025-00057-ORD-2025-00058 | C19: PE-KG01-L22-20251026-AM-ORD-2025-00058 | D19: KG01 | E19: 22 | F19: 45956 | G19: AM | H19: ORD-2025-00058 | I19: HE | J19: L22-S03 | K19: Section | L19: 3 | N19: Neck Ring Issue | Q19: 0.69 | R19: =IF(B19="","",SUMIF(ProductionConfiguration!$B$5:$B$914,C19,ProductionConfiguration!$S$5:$S$914)) -> 30 | S19: =IF(B19="","",IF(K19="Line",R19,IF(K19="Section",SUMIFS(ProductionConfiguration!$S$5:$S$914,ProductionConfiguration!$B$5:$B$914,C19,ProductionConfiguration!$I$5:$I$914,L19),IF(K19="Cavity",IF(M19=1,SUMIFS(ProductionConfiguration!$P$5:$P$914,ProductionConfiguration!$B$5:$B$914,C19,ProductionConfiguration!$I$5:$I$914,L19),IF(M19=2,SUMIFS(ProductionConfiguration!$Q$5:$Q$914,ProductionConfiguration!$B$5:$B$914,C19,ProductionConfiguration!$I$5:$I$914,L19),SUMIFS(ProductionConfiguration!$R$5:$R$914,ProductionConfiguration!$B$5:$B$914,C19,ProductionConfiguration!$I$5:$I$914,L19))),0)))) -> 3 | T19: =IF(B19="","",IFERROR(S19/R19,0)) -> 0.1 | U19: =IF(B19="","",Q19*T19) -> 0.069 | V19: =IF(C19="","",SUMIF(DailyProduction!$Q$5:$Q$100,C19,DailyProduction!$J$5:$J$100)) -> 14 | W19: =IF(B19="","",Q19*60*V19*S19) -> 1738.8 | X19: HistoricalSummary | Y19: =IF(B19="","",IF(COUNTIF(JobChange!$S$5:$S$100,B19)=1,"OK","CHECK")) -> OK | Z19: =IF(B19="","",IF(OR(AND(K19="Line",J19="L"&E19),AND(K19="Section",J19="L"&E19&"-S"&TEXT(L19,"00")),AND(K19="Cavity",J19="L"&E19&"-S"&TEXT(L19,"00")&"-C"&M19)),"OK","CHECK")) -> OK | AA19: =IF(B19="","",IF(AND(Q19>0,OR(AND(O19="",P19=""),AND(O19<>"",P19<>"",P19>=O19,ABS(Q19-((P19-O19)*24))<=0.01))),"OK","CHECK")) -> OK | AB19: =IF(B19="","",IF(AND(Y19="OK",Z19="OK",AA19="OK",R19>0,S19>0),"OK","CHECK")) -> OK
A20: JCI-000016 | B20: JC-KG01-L23-20251022-AM-ORD-2025-00092-ORD-2025-00093 | C20: PE-KG01-L23-20251022-AM-ORD-2025-00093 | D20: KG01 | E20: 23 | F20: 45952 | G20: AM | H20: ORD-2025-00093 | I20: T1 | J20: L23 | K20: Line | N20: Historical summary | Q20: 2.73 | R20: =IF(B20="","",SUMIF(ProductionConfiguration!$B$5:$B$914,C20,ProductionConfiguration!$S$5:$S$914)) -> 24 | S20: =IF(B20="","",IF(K20="Line",R20,IF(K20="Section",SUMIFS(ProductionConfiguration!$S$5:$S$914,ProductionConfiguration!$B$5:$B$914,C20,ProductionConfiguration!$I$5:$I$914,L20),IF(K20="Cavity",IF(M20=1,SUMIFS(ProductionConfiguration!$P$5:$P$914,ProductionConfiguration!$B$5:$B$914,C20,ProductionConfiguration!$I$5:$I$914,L20),IF(M20=2,SUMIFS(ProductionConfiguration!$Q$5:$Q$914,ProductionConfiguration!$B$5:$B$914,C20,ProductionConfiguration!$I$5:$I$914,L20),SUMIFS(ProductionConfiguration!$R$5:$R$914,ProductionConfiguration!$B$5:$B$914,C20,ProductionConfiguration!$I$5:$I$914,L20))),0)))) -> 24 | T20: =IF(B20="","",IFERROR(S20/R20,0)) -> 1 | U20: =IF(B20="","",Q20*T20) -> 2.73 | V20: =IF(C20="","",SUMIF(DailyProduction!$Q$5:$Q$100,C20,DailyProduction!$J$5:$J$100)) -> 9 | W20: =IF(B20="","",Q20*60*V20*S20) -> 35380.8 | X20: HistoricalSummary | Y20: =IF(B20="","",IF(COUNTIF(JobChange!$S$5:$S$100,B20)=1,"OK","CHECK")) -> OK | Z20: =IF(B20="","",IF(OR(AND(K20="Line",J20="L"&E20),AND(K20="Section",J20="L"&E20&"-S"&TEXT(L20,"00")),AND(K20="Cavity",J20="L"&E20&"-S"&TEXT(L20,"00")&"-C"&M20)),"OK","CHECK")) -> OK | AA20: =IF(B20="","",IF(AND(Q20>0,OR(AND(O20="",P20=""),AND(O20<>"",P20<>"",P20>=O20,ABS(Q20-((P20-O20)*24))<=0.01))),"OK","CHECK")) -> OK | AB20: =IF(B20="","",IF(AND(Y20="OK",Z20="OK",AA20="OK",R20>0,S20>0),"OK","CHECK")) -> OK
A21: JCI-000017 | B21: JC-KG01-L23-20251022-AM-ORD-2025-00092-ORD-2025-00093 | C21: PE-KG01-L23-20251022-AM-ORD-2025-00093 | D21: KG01 | E21: 23 | F21: 45952 | G21: AM | H21: ORD-2025-00093 | I21: T2 | J21: L23-S02-C1 | K21: Cavity | L21: 2 | M21: 1 | N21: Historical summary | Q21: 1.06 | R21: =IF(B21="","",SUMIF(ProductionConfiguration!$B$5:$B$914,C21,ProductionConfiguration!$S$5:$S$914)) -> 24 | S21: =IF(B21="","",IF(K21="Line",R21,IF(K21="Section",SUMIFS(ProductionConfiguration!$S$5:$S$914,ProductionConfiguration!$B$5:$B$914,C21,ProductionConfiguration!$I$5:$I$914,L21),IF(K21="Cavity",IF(M21=1,SUMIFS(ProductionConfiguration!$P$5:$P$914,ProductionConfiguration!$B$5:$B$914,C21,ProductionConfiguration!$I$5:$I$914,L21),IF(M21=2,SUMIFS(ProductionConfiguration!$Q$5:$Q$914,ProductionConfiguration!$B$5:$B$914,C21,ProductionConfiguration!$I$5:$I$914,L21),SUMIFS(ProductionConfiguration!$R$5:$R$914,ProductionConfiguration!$B$5:$B$914,C21,ProductionConfiguration!$I$5:$I$914,L21))),0)))) -> 1 | T21: =IF(B21="","",IFERROR(S21/R21,0)) -> 0.041666667 | U21: =IF(B21="","",Q21*T21) -> 0.044166667 | V21: =IF(C21="","",SUMIF(DailyProduction!$Q$5:$Q$100,C21,DailyProduction!$J$5:$J$100)) -> 9 | W21: =IF(B21="","",Q21*60*V21*S21) -> 572.4 | X21: HistoricalSummary | Y21: =IF(B21="","",IF(COUNTIF(JobChange!$S$5:$S$100,B21)=1,"OK","CHECK")) -> OK | Z21: =IF(B21="","",IF(OR(AND(K21="Line",J21="L"&E21),AND(K21="Section",J21="L"&E21&"-S"&TEXT(L21,"00")),AND(K21="Cavity",J21="L"&E21&"-S"&TEXT(L21,"00")&"-C"&M21)),"OK","CHECK")) -> OK | AA21: =IF(B21="","",IF(AND(Q21>0,OR(AND(O21="",P21=""),AND(O21<>"",P21<>"",P21>=O21,ABS(Q21-((P21-O21)*24))<=0.01))),"OK","CHECK")) -> OK | AB21: =IF(B21="","",IF(AND(Y21="OK",Z21="OK",AA21="OK",R21>0,S21>0),"OK","CHECK")) -> OK
A22: JCI-000018 | B22: JC-KG01-L23-20251022-AM-ORD-2025-00092-ORD-2025-00093 | C22: PE-KG01-L23-20251022-AM-ORD-2025-00093 | D22: KG01 | E22: 23 | F22: 45952 | G22: AM | H22: ORD-2025-00093 | I22: Trial | J22: L23-S01-C1 | K22: Cavity | L22: 1 | M22: 1 | N22: Historical summary | Q22: 0.49 | R22: =IF(B22="","",SUMIF(ProductionConfiguration!$B$5:$B$914,C22,ProductionConfiguration!$S$5:$S$914)) -> 24 | S22: =IF(B22="","",IF(K22="Line",R22,IF(K22="Section",SUMIFS(ProductionConfiguration!$S$5:$S$914,ProductionConfiguration!$B$5:$B$914,C22,ProductionConfiguration!$I$5:$I$914,L22),IF(K22="Cavity",IF(M22=1,SUMIFS(ProductionConfiguration!$P$5:$P$914,ProductionConfiguration!$B$5:$B$914,C22,ProductionConfiguration!$I$5:$I$914,L22),IF(M22=2,SUMIFS(ProductionConfiguration!$Q$5:$Q$914,ProductionConfiguration!$B$5:$B$914,C22,ProductionConfiguration!$I$5:$I$914,L22),SUMIFS(ProductionConfiguration!$R$5:$R$914,ProductionConfiguration!$B$5:$B$914,C22,ProductionConfiguration!$I$5:$I$914,L22))),0)))) -> 1 | T22: =IF(B22="","",IFERROR(S22/R22,0)) -> 0.041666667 | U22: =IF(B22="","",Q22*T22) -> 0.020416667 | V22: =IF(C22="","",SUMIF(DailyProduction!$Q$5:$Q$100,C22,DailyProduction!$J$5:$J$100)) -> 9 | W22: =IF(B22="","",Q22*60*V22*S22) -> 264.6 | X22: HistoricalSummary | Y22: =IF(B22="","",IF(COUNTIF(JobChange!$S$5:$S$100,B22)=1,"OK","CHECK")) -> OK | Z22: =IF(B22="","",IF(OR(AND(K22="Line",J22="L"&E22),AND(K22="Section",J22="L"&E22&"-S"&TEXT(L22,"00")),AND(K22="Cavity",J22="L"&E22&"-S"&TEXT(L22,"00")&"-C"&M22)),"OK","CHECK")) -> OK | AA22: =IF(B22="","",IF(AND(Q22>0,OR(AND(O22="",P22=""),AND(O22<>"",P22<>"",P22>=O22,ABS(Q22-((P22-O22)*24))<=0.01))),"OK","CHECK")) -> OK | AB22: =IF(B22="","",IF(AND(Y22="OK",Z22="OK",AA22="OK",R22>0,S22>0),"OK","CHECK")) -> OK
A23: JCI-000019 | B23: JC-KG01-L23-20251022-AM-ORD-2025-00092-ORD-2025-00093 | C23: PE-KG01-L23-20251022-AM-ORD-2025-00093 | D23: KG01 | E23: 23 | F23: 45952 | G23: AM | H23: ORD-2025-00093 | I23: Palletizer | J23: L23-S03-C1 | K23: Cavity | L23: 3 | M23: 1 | N23: Palletizer Robot Fault | Q23: 0.4 | R23: =IF(B23="","",SUMIF(ProductionConfiguration!$B$5:$B$914,C23,ProductionConfiguration!$S$5:$S$914)) -> 24 | S23: =IF(B23="","",IF(K23="Line",R23,IF(K23="Section",SUMIFS(ProductionConfiguration!$S$5:$S$914,ProductionConfiguration!$B$5:$B$914,C23,ProductionConfiguration!$I$5:$I$914,L23),IF(K23="Cavity",IF(M23=1,SUMIFS(ProductionConfiguration!$P$5:$P$914,ProductionConfiguration!$B$5:$B$914,C23,ProductionConfiguration!$I$5:$I$914,L23),IF(M23=2,SUMIFS(ProductionConfiguration!$Q$5:$Q$914,ProductionConfiguration!$B$5:$B$914,C23,ProductionConfiguration!$I$5:$I$914,L23),SUMIFS(ProductionConfiguration!$R$5:$R$914,ProductionConfiguration!$B$5:$B$914,C23,ProductionConfiguration!$I$5:$I$914,L23))),0)))) -> 1 | T23: =IF(B23="","",IFERROR(S23/R23,0)) -> 0.041666667 | U23: =IF(B23="","",Q23*T23) -> 0.016666667 | V23: =IF(C23="","",SUMIF(DailyProduction!$Q$5:$Q$100,C23,DailyProduction!$J$5:$J$100)) -> 9 | W23: =IF(B23="","",Q23*60*V23*S23) -> 216 | X23: HistoricalSummary | Y23: =IF(B23="","",IF(COUNTIF(JobChange!$S$5:$S$100,B23)=1,"OK","CHECK")) -> OK | Z23: =IF(B23="","",IF(OR(AND(K23="Line",J23="L"&E23),AND(K23="Section",J23="L"&E23&"-S"&TEXT(L23,"00")),AND(K23="Cavity",J23="L"&E23&"-S"&TEXT(L23,"00")&"-C"&M23)),"OK","CHECK")) -> OK | AA23: =IF(B23="","",IF(AND(Q23>0,OR(AND(O23="",P23=""),AND(O23<>"",P23<>"",P23>=O23,ABS(Q23-((P23-O23)*24))<=0.01))),"OK","CHECK")) -> OK | AB23: =IF(B23="","",IF(AND(Y23="OK",Z23="OK",AA23="OK",R23>0,S23>0),"OK","CHECK")) -> OK
A24: JCI-000020 | B24: JC-KG01-L23-20251026-AM-ORD-2025-00093-ORD-2025-00094 | C24: PE-KG01-L23-20251026-AM-ORD-2025-00094 | D24: KG01 | E24: 23 | F24: 45956 | G24: AM | H24: ORD-2025-00094 | I24: T1 | J24: L23 | K24: Line | N24: Historical summary | Q24: 6.68 | R24: =IF(B24="","",SUMIF(ProductionConfiguration!$B$5:$B$914,C24,ProductionConfiguration!$S$5:$S$914)) -> 24 | S24: =IF(B24="","",IF(K24="Line",R24,IF(K24="Section",SUMIFS(ProductionConfiguration!$S$5:$S$914,ProductionConfiguration!$B$5:$B$914,C24,ProductionConfiguration!$I$5:$I$914,L24),IF(K24="Cavity",IF(M24=1,SUMIFS(ProductionConfiguration!$P$5:$P$914,ProductionConfiguration!$B$5:$B$914,C24,ProductionConfiguration!$I$5:$I$914,L24),IF(M24=2,SUMIFS(ProductionConfiguration!$Q$5:$Q$914,ProductionConfiguration!$B$5:$B$914,C24,ProductionConfiguration!$I$5:$I$914,L24),SUMIFS(ProductionConfiguration!$R$5:$R$914,ProductionConfiguration!$B$5:$B$914,C24,ProductionConfiguration!$I$5:$I$914,L24))),0)))) -> 24 | T24: =IF(B24="","",IFERROR(S24/R24,0)) -> 1 | U24: =IF(B24="","",Q24*T24) -> 6.68 | V24: =IF(C24="","",SUMIF(DailyProduction!$Q$5:$Q$100,C24,DailyProduction!$J$5:$J$100)) -> 10 | W24: =IF(B24="","",Q24*60*V24*S24) -> 96192 | X24: HistoricalSummary | Y24: =IF(B24="","",IF(COUNTIF(JobChange!$S$5:$S$100,B24)=1,"OK","CHECK")) -> OK | Z24: =IF(B24="","",IF(OR(AND(K24="Line",J24="L"&E24),AND(K24="Section",J24="L"&E24&"-S"&TEXT(L24,"00")),AND(K24="Cavity",J24="L"&E24&"-S"&TEXT(L24,"00")&"-C"&M24)),"OK","CHECK")) -> OK | AA24: =IF(B24="","",IF(AND(Q24>0,OR(AND(O24="",P24=""),AND(O24<>"",P24<>"",P24>=O24,ABS(Q24-((P24-O24)*24))<=0.01))),"OK","CHECK")) -> OK | AB24: =IF(B24="","",IF(AND(Y24="OK",Z24="OK",AA24="OK",R24>0,S24>0),"OK","CHECK")) -> OK
A25: JCI-000021 | B25: JC-KG01-L23-20251026-AM-ORD-2025-00093-ORD-2025-00094 | C25: PE-KG01-L23-20251026-AM-ORD-2025-00094 | D25: KG01 | E25: 23 | F25: 45956 | G25: AM | H25: ORD-2025-00094 | I25: T2 | J25: L23-S01 | K25: Section | L25: 1 | N25: Historical summary | Q25: 2.81 | R25: =IF(B25="","",SUMIF(ProductionConfiguration!$B$5:$B$914,C25,ProductionConfiguration!$S$5:$S$914)) -> 24 | S25: =IF(B25="","",IF(K25="Line",R25,IF(K25="Section",SUMIFS(ProductionConfiguration!$S$5:$S$914,ProductionConfiguration!$B$5:$B$914,C25,ProductionConfiguration!$I$5:$I$914,L25),IF(K25="Cavity",IF(M25=1,SUMIFS(ProductionConfiguration!$P$5:$P$914,ProductionConfiguration!$B$5:$B$914,C25,ProductionConfiguration!$I$5:$I$914,L25),IF(M25=2,SUMIFS(ProductionConfiguration!$Q$5:$Q$914,ProductionConfiguration!$B$5:$B$914,C25,ProductionConfiguration!$I$5:$I$914,L25),SUMIFS(ProductionConfiguration!$R$5:$R$914,ProductionConfiguration!$B$5:$B$914,C25,ProductionConfiguration!$I$5:$I$914,L25))),0)))) -> 2 | T25: =IF(B25="","",IFERROR(S25/R25,0)) -> 0.083333333 | U25: =IF(B25="","",Q25*T25) -> 0.23416667 | V25: =IF(C25="","",SUMIF(DailyProduction!$Q$5:$Q$100,C25,DailyProduction!$J$5:$J$100)) -> 10 | W25: =IF(B25="","",Q25*60*V25*S25) -> 3372 | X25: HistoricalSummary | Y25: =IF(B25="","",IF(COUNTIF(JobChange!$S$5:$S$100,B25)=1,"OK","CHECK")) -> OK | Z25: =IF(B25="","",IF(OR(AND(K25="Line",J25="L"&E25),AND(K25="Section",J25="L"&E25&"-S"&TEXT(L25,"00")),AND(K25="Cavity",J25="L"&E25&"-S"&TEXT(L25,"00")&"-C"&M25)),"OK","CHECK")) -> OK | AA25: =IF(B25="","",IF(AND(Q25>0,OR(AND(O25="",P25=""),AND(O25<>"",P25<>"",P25>=O25,ABS(Q25-((P25-O25)*24))<=0.01))),"OK","CHECK")) -> OK | AB25: =IF(B25="","",IF(AND(Y25="OK",Z25="OK",AA25="OK",R25>0,S25>0),"OK","CHECK")) -> OK
A26: JCI-000022 | B26: JC-KG01-L23-20251026-AM-ORD-2025-00093-ORD-2025-00094 | C26: PE-KG01-L23-20251026-AM-ORD-2025-00094 | D26: KG01 | E26: 23 | F26: 45956 | G26: AM | H26: ORD-2025-00094 | I26: Trial | J26: L23 | K26: Line | N26: Historical summary | Q26: 0.35 | R26: =IF(B26="","",SUMIF(ProductionConfiguration!$B$5:$B$914,C26,ProductionConfiguration!$S$5:$S$914)) -> 24 | S26: =IF(B26="","",IF(K26="Line",R26,IF(K26="Section",SUMIFS(ProductionConfiguration!$S$5:$S$914,ProductionConfiguration!$B$5:$B$914,C26,ProductionConfiguration!$I$5:$I$914,L26),IF(K26="Cavity",IF(M26=1,SUMIFS(ProductionConfiguration!$P$5:$P$914,ProductionConfiguration!$B$5:$B$914,C26,ProductionConfiguration!$I$5:$I$914,L26),IF(M26=2,SUMIFS(ProductionConfiguration!$Q$5:$Q$914,ProductionConfiguration!$B$5:$B$914,C26,ProductionConfiguration!$I$5:$I$914,L26),SUMIFS(ProductionConfiguration!$R$5:$R$914,ProductionConfiguration!$B$5:$B$914,C26,ProductionConfiguration!$I$5:$I$914,L26))),0)))) -> 24 | T26: =IF(B26="","",IFERROR(S26/R26,0)) -> 1 | U26: =IF(B26="","",Q26*T26) -> 0.35 | V26: =IF(C26="","",SUMIF(DailyProduction!$Q$5:$Q$100,C26,DailyProduction!$J$5:$J$100)) -> 10 | W26: =IF(B26="","",Q26*60*V26*S26) -> 5040 | X26: HistoricalSummary | Y26: =IF(B26="","",IF(COUNTIF(JobChange!$S$5:$S$100,B26)=1,"OK","CHECK")) -> OK | Z26: =IF(B26="","",IF(OR(AND(K26="Line",J26="L"&E26),AND(K26="Section",J26="L"&E26&"-S"&TEXT(L26,"00")),AND(K26="Cavity",J26="L"&E26&"-S"&TEXT(L26,"00")&"-C"&M26)),"OK","CHECK")) -> OK | AA26: =IF(B26="","",IF(AND(Q26>0,OR(AND(O26="",P26=""),AND(O26<>"",P26<>"",P26>=O26,ABS(Q26-((P26-O26)*24))<=0.01))),"OK","CHECK")) -> OK | AB26: =IF(B26="","",IF(AND(Y26="OK",Z26="OK",AA26="OK",R26>0,S26>0),"OK","CHECK")) -> OK
A27: JCI-000023 | B27: JC-KG01-L23-20251026-AM-ORD-2025-00093-ORD-2025-00094 | C27: PE-KG01-L23-20251026-AM-ORD-2025-00094 | D27: KG01 | E27: 23 | F27: 45956 | G27: AM | H27: ORD-2025-00094 | I27: HE | J27: L23-S06 | K27: Section | L27: 6 | N27: Gob Distributor Jam | Q27: 0.47 | R27: =IF(B27="","",SUMIF(ProductionConfiguration!$B$5:$B$914,C27,ProductionConfiguration!$S$5:$S$914)) -> 24 | S27: =IF(B27="","",IF(K27="Line",R27,IF(K27="Section",SUMIFS(ProductionConfiguration!$S$5:$S$914,ProductionConfiguration!$B$5:$B$914,C27,ProductionConfiguration!$I$5:$I$914,L27),IF(K27="Cavity",IF(M27=1,SUMIFS(ProductionConfiguration!$P$5:$P$914,ProductionConfiguration!$B$5:$B$914,C27,ProductionConfiguration!$I$5:$I$914,L27),IF(M27=2,SUMIFS(ProductionConfiguration!$Q$5:$Q$914,ProductionConfiguration!$B$5:$B$914,C27,ProductionConfiguration!$I$5:$I$914,L27),SUMIFS(ProductionConfiguration!$R$5:$R$914,ProductionConfiguration!$B$5:$B$914,C27,ProductionConfiguration!$I$5:$I$914,L27))),0)))) -> 2 | T27: =IF(B27="","",IFERROR(S27/R27,0)) -> 0.083333333 | U27: =IF(B27="","",Q27*T27) -> 0.039166667 | V27: =IF(C27="","",SUMIF(DailyProduction!$Q$5:$Q$100,C27,DailyProduction!$J$5:$J$100)) -> 10 | W27: =IF(B27="","",Q27*60*V27*S27) -> 564 | X27: HistoricalSummary | Y27: =IF(B27="","",IF(COUNTIF(JobChange!$S$5:$S$100,B27)=1,"OK","CHECK")) -> OK | Z27: =IF(B27="","",IF(OR(AND(K27="Line",J27="L"&E27),AND(K27="Section",J27="L"&E27&"-S"&TEXT(L27,"00")),AND(K27="Cavity",J27="L"&E27&"-S"&TEXT(L27,"00")&"-C"&M27)),"OK","CHECK")) -> OK | AA27: =IF(B27="","",IF(AND(Q27>0,OR(AND(O27="",P27=""),AND(O27<>"",P27<>"",P27>=O27,ABS(Q27-((P27-O27)*24))<=0.01))),"OK","CHECK")) -> OK | AB27: =IF(B27="","",IF(AND(Y27="OK",Z27="OK",AA27="OK",R27>0,S27>0),"OK","CHECK")) -> OK
