Workbook

Sheet Instructions
A1: KANDIL GLASS — MASTER DATA WORKBOOK
A3: Owner: Planning / Sales / IT
A5: Purpose: Maintain customers, products, orders, job-change types, lines and all dropdown lists.
A7: Rules:
A8: 1. Never change column header names.
A9: 2. Codes must be unique.
A10: 3. New codes are added HERE first, then appear in other workbooks' dropdowns.
A11: 4. Yellow cells = dropdown. Blue cells = input.
A12: 5. Load this file into Staging BEFORE any daily transactional files.
A14: JobChangeType official values: Small, Medium, Big, Process
A16: Dataset: one-week subset for DWH / Power BI testing (2025-10-20 to 2025-10-26); synthetic operational data.
A18: NEW SECTION/CAVITY MODEL
... A22: All additions are additive; do not delete/rename existing Power BI source columns.

Sheet Customers
A1: Master Data — Customers
A2: Maps to STG_CUSTOMER → DIM_CUSTOMER
A3: One row per customer. CustomerCode must be unique.
A4: CustomerCode | B4: CustomerName | C4: CountryType
A5: CUST001 | B5: Coca-Cola Egypt | C5: Local
A6: CUST002 | B6: PepsiCo Egypt | C6: Local
A7: CUST003 | B7: Nestle Waters | C7: Export

Sheet Products
A1: Master Data — Products
A2: Maps to STG_PRODUCT → DIM_PRODUCT
A3: ProductCode unique. Category = Jar or Bottle. CustomerCode must exist in Customers.
A4: ProductCode | B4: ProductName | C4: Category | D4: CustomerCode
A5: PRD-JAR-330 | B5: Jar 330ml Twist-off | C5: Jar | D5: CUST001
A6: PRD-BOT-500 | B6: Bottle 500ml Crown | C6: Bottle | D6: CUST002
A7: PRD-JAR-720 | B7: Jar 720ml Lug Cap | C7: Jar | D7: CUST001
A8: PRD-BOT-750 | B8: Bottle 750ml Export Cap | C8: Bottle | D8: CUST003

Sheet Orders
A1: Master Data — Orders
A2: Maps to STG_ORDER → DIM_ORDER
A3: OrderNumber unique. TotalMoltenUnits = Packed + Rejected + Hold.
A4: OrderNumber | B4: ProductCode | C4: CustomerCode | D4: TotalMoltenUnits | E4: ProductCustomerCheck
A5: ORD-2025-00019 | B5: PRD-JAR-330 | C5: CUST001 | D5: 1548306 | E5: =IF(A5="","",IF(COUNTIFS(Products!$A$5:$A$100,B5,Products!$D$5:$D$100,C5)=1,"OK","CHECK")) -> OK
A6: ORD-2025-00020 | B6: PRD-JAR-720 | C6: CUST001 | D6: 1050408 | E6: =IF(A6="","",IF(COUNTIFS(Products!$A$5:$A$100,B6,Products!$D$5:$D$100,C6)=1,"OK","CHECK")) -> OK
A7: ORD-2025-00021 | B7: PRD-JAR-330 | C7: CUST001 | D7: 2448972 | E7: =IF(A7="","",IF(COUNTIFS(Products!$A$5:$A$100,B7,Products!$D$5:$D$100,C7)=1,"OK","CHECK")) -> OK
A8: ORD-2025-00055 | B8: PRD-BOT-500 | C8: CUST002 | D8: 2732760 | E8: =IF(A8="","",IF(COUNTIFS(Products!$A$5:$A$100,B8,Products!$D$5:$D$100,C8)=1,"OK","CHECK")) -> OK
A9: ORD-2025-00056 | B9: PRD-JAR-720 | C9: CUST001 | D9: 462168 | E9: =IF(A9="","",IF(COUNTIFS(Products!$A$5:$A$100,B9,Products!$D$5:$D$100,C9)=1,"OK","CHECK")) -> OK
A10: ORD-2025-00057 | B10: PRD-JAR-720 | C10: CUST001 | D10: 1111476 | E10: =IF(A10="","",IF(COUNTIFS(Products!$A$5:$A$100,B10,Products!$D$5:$D$100,C10)=1,"OK","CHECK")) -> OK
A11: ORD-2025-00058 | B11: PRD-BOT-500 | C11: CUST002 | D11: 2712264 | E11: =IF(A11="","",IF(COUNTIFS(Products!$A$5:$A$100,B11,Products!$D$5:$D$100,C11)=1,"OK","CHECK")) -> OK
A12: ORD-2025-00092 | B12: PRD-JAR-330 | C12: CUST001 | D12: 3348843 | E12: =IF(A12="","",IF(COUNTIFS(Products!$A$5:$A$100,B12,Products!$D$5:$D$100,C12)=1,"OK","CHECK")) -> OK
A13: ORD-2025-00093 | B13: PRD-JAR-720 | C13: CUST001 | D13: 1243871 | E13: =IF(A13="","",IF(COUNTIFS(Products!$A$5:$A$100,B13,Products!$D$5:$D$100,C13)=1,"OK","CHECK")) -> OK
A14: ORD-2025-00094 | B14: PRD-JAR-720 | C14: CUST001 | D14: 1907410 | E14: =IF(A14="","",IF(COUNTIFS(Products!$A$5:$A$100,B14,Products!$D$5:$D$100,C14)=1,"OK","CHECK")) -> OK
A15: ORD-2025-00124 | B15: PRD-BOT-500 | C15: CUST002 | D15: 4150713 | E15: =IF(A15="","",IF(COUNTIFS(Products!$A$5:$A$100,B15,Products!$D$5:$D$100,C15)=1,"OK","CHECK")) -> OK
A16: ORD-2025-00125 | B16: PRD-JAR-330 | C16: CUST001 | D16: 2296749 | E16: =IF(A16="","",IF(COUNTIFS(Products!$A$5:$A$100,B16,Products!$D$5:$D$100,C16)=1,"OK","CHECK")) -> OK
... A160: ORD-2025-00303 | B160: PRD-JAR-330 | C160: CUST001 | D160: 1013598 | E160: =IF(A160="","",IF(COUNTIFS(Products!$A$5:$A$100,B160,Products!$D$5:$D$100,C160)=1,"OK","CHECK")) -> OK
E161: =IF(A161="","",IF(COUNTIFS(Products!$A$5:$A$100,B161,Products!$D$5:$D$100,C161)=1,"OK","CHECK"))
E162: =IF(A162="","",IF(COUNTIFS(Products!$A$5:$A$100,B162,Products!$D$5:$D$100,C162)=1,"OK","CHECK"))
E163: =IF(A163="","",IF(COUNTIFS(Products!$A$5:$A$100,B163,Products!$D$5:$D$100,C163)=1,"OK","CHECK"))
E164: =IF(A164="","",IF(COUNTIFS(Products!$A$5:$A$100,B164,Products!$D$5:$D$100,C164)=1,"OK","CHECK"))
E165: =IF(A165="","",IF(COUNTIFS(Products!$A$5:$A$100,B165,Products!$D$5:$D$100,C165)=1,"OK","CHECK"))
E166: =IF(A166="","",IF(COUNTIFS(Products!$A$5:$A$100,B166,Products!$D$5:$D$100,C166)=1,"OK","CHECK"))
E167: =IF(A167="","",IF(COUNTIFS(Products!$A$5:$A$100,B167,Products!$D$5:$D$100,C167)=1,"OK","CHECK"))
E168: =IF(A168="","",IF(COUNTIFS(Products!$A$5:$A$100,B168,Products!$D$5:$D$100,C168)=1,"OK","CHECK"))
E169: =IF(A169="","",IF(COUNTIFS(Products!$A$5:$A$100,B169,Products!$D$5:$D$100,C169)=1,"OK","CHECK"))
E170: =IF(A170="","",IF(COUNTIFS(Products!$A$5:$A$100,B170,Products!$D$5:$D$100,C170)=1,"OK","CHECK"))

Sheet DefectName
A1: Master Data — Defects
A2: Maps to STG_DEFECT → DIM_DEFECT
A3: Maintain only approved values.
A4: DefectName
A5: Crack
A6: Chip
A7: Blister
A8: Distortion
A9: Stone
A10: Bird Swing
A11: Overpress
A12: Thin Wall
A13: Choke Neck

Sheet HE_DowntimeReason
A1: Master Data — HE Downtime Reasons
A2: Reference list for JobChange HE_DowntimeReason
A3: Maintain only approved values.
A4: HE_DowntimeReason
A5: Feeder Temperature Instability
A6: Gob Weight Adjustment
A7: Shear Mechanism Fault
A8: Gob Distributor Jam
A9: Mould Cooling Issue
A10: Swabbing / Lubrication
A11: Blank Mould Change
A12: Neck Ring Issue
A13: Air Pressure Instability

Sheet CE_LossesReason
A1: Master Data — CE Loss Reasons
A2: Reference list for JobChange CE_LossesReason
A3: Maintain only approved values.
A4: CE_LossesReason
A5: Cross Conveyor Jam
A6: Ware Transfer Misalignment
A7: Dead Plate Congestion
A8: Lehr Loader Delay
A9: Conveyor Speed Mismatch
A10: Bottle Fall / Tip
A11: Sensor Fault
A12: Drive / Motor Fault
A13: Belt Tracking Issue

Sheet PalletizerReason
A1: Master Data — Palletizer Reasons
A2: Reference list for JobChange PalletizerReason
A3: Maintain only approved values.
A4: PalletizerReason
A5: Palletizer Robot Fault
A6: Layer Pattern Adjustment
A7: Pallet Shortage
A8: Separator Pad Shortage
A9: Pallet Conveyor Jam
A10: Film / Hood Fault
A11: Gripper / Vacuum Fault
A12: Sensor / Photoeye Fault
A13: Manual Intervention

Sheet ReworkStatus
A1: Master Data — Rework Status
A2: Maps to DIM_REWORKSTATUS
A3: Maintain only approved values.
A4: ReworkStatus
A5: Resorted
A6: Move to Cullet

Sheet CaseName
A1: Master Data — Case Name
A2: Reference list for production / losses case
A3: Maintain only approved values.
A4: CaseName
A5: Normal
A6: Trial
A7: Reworking

Sheet Crew
A1: Master Data — Crew
A2: Reference list for production crews
A3: Maintain only approved values.
A4: Crew
A5: A
A6: B
A7: C

Sheet Shifts
A1: Master Data — Shifts
A2: Reference list for shifts
A3: Maintain only approved values.
A4: Shift
A5: AM
A6: PM

Sheet Lines
A1: Master Data — Production Lines
A2: Maps to REF_LINE / DIM_LINE
A3: FactoryCode + LineNumber must be unique. | D3: Physical capability only; active setup is event-specific.
A4: FactoryCode | B4: LineNumber | C4: LineStatus | D4: PhysicalSectionsCapability | E4: MaxCavityPositionsPerSection | F4: CapabilityCheck
A5: KG01 | B5: 21 | C5: Active | D5: 13 | E5: 3 | F5: =IF(AND(D5=13,E5=3),"OK","CHECK") -> OK
A6: KG01 | B6: 22 | C6: Active | D6: 13 | E6: 3 | F6: =IF(AND(D6=13,E6=3),"OK","CHECK") -> OK
A7: KG01 | B7: 23 | C7: Active | D7: 13 | E7: 3 | F7: =IF(AND(D7=13,E7=3),"OK","CHECK") -> OK
A8: KG01 | B8: 24 | C8: Active | D8: 13 | E8: 3 | F8: =IF(AND(D8=13,E8=3),"OK","CHECK") -> OK
A9: KG01 | B9: 25 | C9: Active | D9: 13 | E9: 3 | F9: =IF(AND(D9=13,E9=3),"OK","CHECK") -> OK

Sheet JobChangeTypes
A1: Master Data — Job Change Types
A2: Maps to STG_JOBCHANGETYPE → DIM_JOBCHANGETYPE
A3: Official values: Small, Medium, Big, Process
A4: JobChangeTypeName | B4: TargetT1_Hrs | C4: TargetT2_Hrs
A5: Small | B5: 1.5 | C5: 0.5
A6: Medium | B6: 3 | C6: 1
A7: Big | B7: 6 | C7: 2
A8: Process | B8: 8 | C8: 3

Sheet Lookups
A1: Lookup Lists (power dropdowns in other workbooks)
A2: Do not delete rows that are in use
A4: Shift | B4: Crew | C4: CaseName | D4: ReworkStatus | E4: DefectName | F4: HE_DowntimeReason | G4: CE_LossesReason | H4: PalletizerReason | I4: AssetLevel | J4: LossArea | K4: ActiveFlag | L4: ImpactSource
A5: AM | B5: A | C5: Normal | D5: Resorted | E5: Crack | F5: Feeder Temperature Instability | G5: Cross Conveyor Jam | H5: Palletizer Robot Fault | I5: Line | J5: T1 | K5: 0 | L5: HistoricalSummary
A6: PM | B6: B | C6: Trial | D6: Move to Cullet | E6: Chip | F6: Gob Weight Adjustment | G6: Ware Transfer Misalignment | H6: Layer Pattern Adjustment | I6: Section | J6: T2 | K6: 1 | L6: ManualDetail
B7: C | C7: Reworking | E7: Blister | F7: Shear Mechanism Fault | G7: Dead Plate Congestion | H7: Pallet Shortage | I7: Cavity | J7: Trial
E8: Distortion | F8: Gob Distributor Jam | G8: Lehr Loader Delay | H8: Separator Pad Shortage | J8: HE
E9: Stone | F9: Mould Cooling Issue | G9: Conveyor Speed Mismatch | H9: Pallet Conveyor Jam | J9: CE
E10: Bird Swing | F10: Swabbing / Lubrication | G10: Bottle Fall / Tip | H10: Film / Hood Fault | J10: Palletizer
E11: Overpress | F11: Blank Mould Change | G11: Sensor Fault | H11: Gripper / Vacuum Fault
E12: Thin Wall | F12: Neck Ring Issue | G12: Drive / Motor Fault | H12: Sensor / Photoeye Fault
E13: Choke Neck | F13: Air Pressure Instability | G13: Belt Tracking Issue | H13: Manual Intervention

Sheet AssetScope
A1: PHYSICAL ASSET SCOPE — LINE / SECTION / CAVITY
A2: Lines 21–25 capability: 13 sections × max 3 cavity positions. Physical capability ≠ active production setup.
A4: AssetScopeKey | B4: FactoryCode | C4: LineNumber | D4: SectionNumber | E4: CavityNumber | F4: AssetLevel | G4: AssetLabel | H4: ParentAssetScopeKey | I4: PhysicalSectionsCapability | J4: MaxCavityPositionsPerSection | K4: IsPhysicalSlot | L4: IntegrityCheck
A5: L21 | B5: KG01 | C5: 21 | F5: Line | G5: Line 21 | I5: 13 | J5: 3 | K5: 1 | L5: =IF(OR(F5="Line",AND(F5="Section",D5>=1,D5<=I5,E5=""),AND(F5="Cavity",D5>=1,D5<=I5,E5>=1,E5<=J5)),"OK","CHECK") -> OK
A6: L21-S01 | B6: KG01 | C6: 21 | D6: 1 | F6: Section | G6: Line 21 / Section 01 | H6: L21 | I6: 13 | J6: 3 | K6: 1 | L6: =IF(OR(F6="Line",AND(F6="Section",D6>=1,D6<=I6,E6=""),AND(F6="Cavity",D6>=1,D6<=I6,E6>=1,E6<=J6)),"OK","CHECK") -> OK
A7: L21-S01-C1 | B7: KG01 | C7: 21 | D7: 1 | E7: 1 | F7: Cavity | G7: Line 21 / Section 01 / Cavity 1 | H7: L21-S01 | I7: 13 | J7: 3 | K7: 1 | L7: =IF(OR(F7="Line",AND(F7="Section",D7>=1,D7<=I7,E7=""),AND(F7="Cavity",D7>=1,D7<=I7,E7>=1,E7<=J7)),"OK","CHECK") -> OK
A8: L21-S01-C2 | B8: KG01 | C8: 21 | D8: 1 | E8: 2 | F8: Cavity | G8: Line 21 / Section 01 / Cavity 2 | H8: L21-S01 | I8: 13 | J8: 3 | K8: 1 | L8: =IF(OR(F8="Line",AND(F8="Section",D8>=1,D8<=I8,E8=""),AND(F8="Cavity",D8>=1,D8<=I8,E8>=1,E8<=J8)),"OK","CHECK") -> OK
A9: L21-S01-C3 | B9: KG01 | C9: 21 | D9: 1 | E9: 3 | F9: Cavity | G9: Line 21 / Section 01 / Cavity 3 | H9: L21-S01 | I9: 13 | J9: 3 | K9: 1 | L9: =IF(OR(F9="Line",AND(F9="Section",D9>=1,D9<=I9,E9=""),AND(F9="Cavity",D9>=1,D9<=I9,E9>=1,E9<=J9)),"OK","CHECK") -> OK
A10: L21-S02 | B10: KG01 | C10: 21 | D10: 2 | F10: Section | G10: Line 21 / Section 02 | H10: L21 | I10: 13 | J10: 3 | K10: 1 | L10: =IF(OR(F10="Line",AND(F10="Section",D10>=1,D10<=I10,E10=""),AND(F10="Cavity",D10>=1,D10<=I10,E10>=1,E10<=J10)),"OK","CHECK") -> OK
A11: L21-S02-C1 | B11: KG01 | C11: 21 | D11: 2 | E11: 1 | F11: Cavity | G11: Line 21 / Section 02 / Cavity 1 | H11: L21-S02 | I11: 13 | J11: 3 | K11: 1 | L11: =IF(OR(F11="Line",AND(F11="Section",D11>=1,D11<=I11,E11=""),AND(F11="Cavity",D11>=1,D11<=I11,E11>=1,E11<=J11)),"OK","CHECK") -> OK
A12: L21-S02-C2 | B12: KG01 | C12: 21 | D12: 2 | E12: 2 | F12: Cavity | G12: Line 21 / Section 02 / Cavity 2 | H12: L21-S02 | I12: 13 | J12: 3 | K12: 1 | L12: =IF(OR(F12="Line",AND(F12="Section",D12>=1,D12<=I12,E12=""),AND(F12="Cavity",D12>=1,D12<=I12,E12>=1,E12<=J12)),"OK","CHECK") -> OK
A13: L21-S02-C3 | B13: KG01 | C13: 21 | D13: 2 | E13: 3 | F13: Cavity | G13: Line 21 / Section 02 / Cavity 3 | H13: L21-S02 | I13: 13 | J13: 3 | K13: 1 | L13: =IF(OR(F13="Line",AND(F13="Section",D13>=1,D13<=I13,E13=""),AND(F13="Cavity",D13>=1,D13<=I13,E13>=1,E13<=J13)),"OK","CHECK") -> OK
A14: L21-S03 | B14: KG01 | C14: 21 | D14: 3 | F14: Section | G14: Line 21 / Section 03 | H14: L21 | I14: 13 | J14: 3 | K14: 1 | L14: =IF(OR(F14="Line",AND(F14="Section",D14>=1,D14<=I14,E14=""),AND(F14="Cavity",D14>=1,D14<=I14,E14>=1,E14<=J14)),"OK","CHECK") -> OK
A15: L21-S03-C1 | B15: KG01 | C15: 21 | D15: 3 | E15: 1 | F15: Cavity | G15: Line 21 / Section 03 / Cavity 1 | H15: L21-S03 | I15: 13 | J15: 3 | K15: 1 | L15: =IF(OR(F15="Line",AND(F15="Section",D15>=1,D15<=I15,E15=""),AND(F15="Cavity",D15>=1,D15<=I15,E15>=1,E15<=J15)),"OK","CHECK") -> OK
A16: L21-S03-C2 | B16: KG01 | C16: 21 | D16: 3 | E16: 2 | F16: Cavity | G16: Line 21 / Section 03 / Cavity 2 | H16: L21-S03 | I16: 13 | J16: 3 | K16: 1 | L16: =IF(OR(F16="Line",AND(F16="Section",D16>=1,D16<=I16,E16=""),AND(F16="Cavity",D16>=1,D16<=I16,E16>=1,E16<=J16)),"OK","CHECK") -> OK
A17: L21-S03-C3 | B17: KG01 | C17: 21 | D17: 3 | E17: 3 | F17: Cavity | G17: Line 21 / Section 03 / Cavity 3 | H17: L21-S03 | I17: 13 | J17: 3 | K17: 1 | L17: =IF(OR(F17="Line",AND(F17="Section",D17>=1,D17<=I17,E17=""),AND(F17="Cavity",D17>=1,D17<=I17,E17>=1,E17<=J17)),"OK","CHECK") -> OK
A18: L21-S04 | B18: KG01 | C18: 21 | D18: 4 | F18: Section | G18: Line 21 / Section 04 | H18: L21 | I18: 13 | J18: 3 | K18: 1 | L18: =IF(OR(F18="Line",AND(F18="Section",D18>=1,D18<=I18,E18=""),AND(F18="Cavity",D18>=1,D18<=I18,E18>=1,E18<=J18)),"OK","CHECK") -> OK
A19: L21-S04-C1 | B19: KG01 | C19: 21 | D19: 4 | E19: 1 | F19: Cavity | G19: Line 21 / Section 04 / Cavity 1 | H19: L21-S04 | I19: 13 | J19: 3 | K19: 1 | L19: =IF(OR(F19="Line",AND(F19="Section",D19>=1,D19<=I19,E19=""),AND(F19="Cavity",D19>=1,D19<=I19,E19>=1,E19<=J19)),"OK","CHECK") -> OK
A20: L21-S04-C2 | B20: KG01 | C20: 21 | D20: 4 | E20: 2 | F20: Cavity | G20: Line 21 / Section 04 / Cavity 2 | H20: L21-S04 | I20: 13 | J20: 3 | K20: 1 | L20: =IF(OR(F20="Line",AND(F20="Section",D20>=1,D20<=I20,E20=""),AND(F20="Cavity",D20>=1,D20<=I20,E20>=1,E20<=J20)),"OK","CHECK") -> OK
A21: L21-S04-C3 | B21: KG01 | C21: 21 | D21: 4 | E21: 3 | F21: Cavity | G21: Line 21 / Section 04 / Cavity 3 | H21: L21-S04 | I21: 13 | J21: 3 | K21: 1 | L21: =IF(OR(F21="Line",AND(F21="Section",D21>=1,D21<=I21,E21=""),AND(F21="Cavity",D21>=1,D21<=I21,E21>=1,E21<=J21)),"OK","CHECK") -> OK
A22: L21-S05 | B22: KG01 | C22: 21 | D22: 5 | F22: Section | G22: Line 21 / Section 05 | H22: L21 | I22: 13 | J22: 3 | K22: 1 | L22: =IF(OR(F22="Line",AND(F22="Section",D22>=1,D22<=I22,E22=""),AND(F22="Cavity",D22>=1,D22<=I22,E22>=1,E22<=J22)),"OK","CHECK") -> OK
A23: L21-S05-C1 | B23: KG01 | C23: 21 | D23: 5 | E23: 1 | F23: Cavity | G23: Line 21 / Section 05 / Cavity 1 | H23: L21-S05 | I23: 13 | J23: 3 | K23: 1 | L23: =IF(OR(F23="Line",AND(F23="Section",D23>=1,D23<=I23,E23=""),AND(F23="Cavity",D23>=1,D23<=I23,E23>=1,E23<=J23)),"OK","CHECK") -> OK
A24: L21-S05-C2 | B24: KG01 | C24: 21 | D24: 5 | E24: 2 | F24: Cavity | G24: Line 21 / Section 05 / Cavity 2 | H24: L21-S05 | I24: 13 | J24: 3 | K24: 1 | L24: =IF(OR(F24="Line",AND(F24="Section",D24>=1,D24<=I24,E24=""),AND(F24="Cavity",D24>=1,D24<=I24,E24>=1,E24<=J24)),"OK","CHECK") -> OK
A25: L21-S05-C3 | B25: KG01 | C25: 21 | D25: 5 | E25: 3 | F25: Cavity | G25: Line 21 / Section 05 / Cavity 3 | H25: L21-S05 | I25: 13 | J25: 3 | K25: 1 | L25: =IF(OR(F25="Line",AND(F25="Section",D25>=1,D25<=I25,E25=""),AND(F25="Cavity",D25>=1,D25<=I25,E25>=1,E25<=J25)),"OK","CHECK") -> OK
A26: L21-S06 | B26: KG01 | C26: 21 | D26: 6 | F26: Section | G26: Line 21 / Section 06 | H26: L21 | I26: 13 | J26: 3 | K26: 1 | L26: =IF(OR(F26="Line",AND(F26="Section",D26>=1,D26<=I26,E26=""),AND(F26="Cavity",D26>=1,D26<=I26,E26>=1,E26<=J26)),"OK","CHECK") -> OK
A27: L21-S06-C1 | B27: KG01 | C27: 21 | D27: 6 | E27: 1 | F27: Cavity | G27: Line 21 / Section 06 / Cavity 1 | H27: L21-S06 | I27: 13 | J27: 3 | K27: 1 | L27: =IF(OR(F27="Line",AND(F27="Section",D27>=1,D27<=I27,E27=""),AND(F27="Cavity",D27>=1,D27<=I27,E27>=1,E27<=J27)),"OK","CHECK") -> OK
A28: L21-S06-C2 | B28: KG01 | C28: 21 | D28: 6 | E28: 2 | F28: Cavity | G28: Line 21 / Section 06 / Cavity 2 | H28: L21-S06 | I28: 13 | J28: 3 | K28: 1 | L28: =IF(OR(F28="Line",AND(F28="Section",D28>=1,D28<=I28,E28=""),AND(F28="Cavity",D28>=1,D28<=I28,E28>=1,E28<=J28)),"OK","CHECK") -> OK
A29: L21-S06-C3 | B29: KG01 | C29: 21 | D29: 6 | E29: 3 | F29: Cavity | G29: Line 21 / Section 06 / Cavity 3 | H29: L21-S06 | I29: 13 | J29: 3 | K29: 1 | L29: =IF(OR(F29="Line",AND(F29="Section",D29>=1,D29<=I29,E29=""),AND(F29="Cavity",D29>=1,D29<=I29,E29>=1,E29<=J29)),"OK","CHECK") -> OK
A30: L21-S07 | B30: KG01 | C30: 21 | D30: 7 | F30: Section | G30: Line 21 / Section 07 | H30: L21 | I30: 13 | J30: 3 | K30: 1 | L30: =IF(OR(F30="Line",AND(F30="Section",D30>=1,D30<=I30,E30=""),AND(F30="Cavity",D30>=1,D30<=I30,E30>=1,E30<=J30)),"OK","CHECK") -> OK
A31: L21-S07-C1 | B31: KG01 | C31: 21 | D31: 7 | E31: 1 | F31: Cavity | G31: Line 21 / Section 07 / Cavity 1 | H31: L21-S07 | I31: 13 | J31: 3 | K31: 1 | L31: =IF(OR(F31="Line",AND(F31="Section",D31>=1,D31<=I31,E31=""),AND(F31="Cavity",D31>=1,D31<=I31,E31>=1,E31<=J31)),"OK","CHECK") -> OK
A32: L21-S07-C2 | B32: KG01 | C32: 21 | D32: 7 | E32: 2 | F32: Cavity | G32: Line 21 / Section 07 / Cavity 2 | H32: L21-S07 | I32: 13 | J32: 3 | K32: 1 | L32: =IF(OR(F32="Line",AND(F32="Section",D32>=1,D32<=I32,E32=""),AND(F32="Cavity",D32>=1,D32<=I32,E32>=1,E32<=J32)),"OK","CHECK") -> OK
A33: L21-S07-C3 | B33: KG01 | C33: 21 | D33: 7 | E33: 3 | F33: Cavity | G33: Line 21 / Section 07 / Cavity 3 | H33: L21-S07 | I33: 13 | J33: 3 | K33: 1 | L33: =IF(OR(F33="Line",AND(F33="Section",D33>=1,D33<=I33,E33=""),AND(F33="Cavity",D33>=1,D33<=I33,E33>=1,E33<=J33)),"OK","CHECK") -> OK
A34: L21-S08 | B34: KG01 | C34: 21 | D34: 8 | F34: Section | G34: Line 21 / Section 08 | H34: L21 | I34: 13 | J34: 3 | K34: 1 | L34: =IF(OR(F34="Line",AND(F34="Section",D34>=1,D34<=I34,E34=""),AND(F34="Cavity",D34>=1,D34<=I34,E34>=1,E34<=J34)),"OK","CHECK") -> OK
A35: L21-S08-C1 | B35: KG01 | C35: 21 | D35: 8 | E35: 1 | F35: Cavity | G35: Line 21 / Section 08 / Cavity 1 | H35: L21-S08 | I35: 13 | J35: 3 | K35: 1 | L35: =IF(OR(F35="Line",AND(F35="Section",D35>=1,D35<=I35,E35=""),AND(F35="Cavity",D35>=1,D35<=I35,E35>=1,E35<=J35)),"OK","CHECK") -> OK
A36: L21-S08-C2 | B36: KG01 | C36: 21 | D36: 8 | E36: 2 | F36: Cavity | G36: Line 21 / Section 08 / Cavity 2 | H36: L21-S08 | I36: 13 | J36: 3 | K36: 1 | L36: =IF(OR(F36="Line",AND(F36="Section",D36>=1,D36<=I36,E36=""),AND(F36="Cavity",D36>=1,D36<=I36,E36>=1,E36<=J36)),"OK","CHECK") -> OK
A37: L21-S08-C3 | B37: KG01 | C37: 21 | D37: 8 | E37: 3 | F37: Cavity | G37: Line 21 / Section 08 / Cavity 3 | H37: L21-S08 | I37: 13 | J37: 3 | K37: 1 | L37: =IF(OR(F37="Line",AND(F37="Section",D37>=1,D37<=I37,E37=""),AND(F37="Cavity",D37>=1,D37<=I37,E37>=1,E37<=J37)),"OK","CHECK") -> OK
A38: L21-S09 | B38: KG01 | C38: 21 | D38: 9 | F38: Section | G38: Line 21 / Section 09 | H38: L21 | I38: 13 | J38: 3 | K38: 1 | L38: =IF(OR(F38="Line",AND(F38="Section",D38>=1,D38<=I38,E38=""),AND(F38="Cavity",D38>=1,D38<=I38,E38>=1,E38<=J38)),"OK","CHECK") -> OK
A39: L21-S09-C1 | B39: KG01 | C39: 21 | D39: 9 | E39: 1 | F39: Cavity | G39: Line 21 / Section 09 / Cavity 1 | H39: L21-S09 | I39: 13 | J39: 3 | K39: 1 | L39: =IF(OR(F39="Line",AND(F39="Section",D39>=1,D39<=I39,E39=""),AND(F39="Cavity",D39>=1,D39<=I39,E39>=1,E39<=J39)),"OK","CHECK") -> OK
A40: L21-S09-C2 | B40: KG01 | C40: 21 | D40: 9 | E40: 2 | F40: Cavity | G40: Line 21 / Section 09 / Cavity 2 | H40: L21-S09 | I40: 13 | J40: 3 | K40: 1 | L40: =IF(OR(F40="Line",AND(F40="Section",D40>=1,D40<=I40,E40=""),AND(F40="Cavity",D40>=1,D40<=I40,E40>=1,E40<=J40)),"OK","CHECK") -> OK
A41: L21-S09-C3 | B41: KG01 | C41: 21 | D41: 9 | E41: 3 | F41: Cavity | G41: Line 21 / Section 09 / Cavity 3 | H41: L21-S09 | I41: 13 | J41: 3 | K41: 1 | L41: =IF(OR(F41="Line",AND(F41="Section",D41>=1,D41<=I41,E41=""),AND(F41="Cavity",D41>=1,D41<=I41,E41>=1,E41<=J41)),"OK","CHECK") -> OK
...

Sheet ModelChanges
A1: MODEL EXTENSION — SECTION/CAVITY JOB CHANGE ANALYSIS
A4: Component | B4: Workbook/Sheet | C4: Grain | D4: Purpose | E4: Power BI role | F4: Rule
A5: Physical capability | B5: 01_MasterData / Lines | C5: Line | D5: 13 sections / max 3 cavity positions | E5: DIM_LINE attributes | F5: Capability ≠ active setup
A6: Asset hierarchy | B6: 01_MasterData / AssetScope | C6: Physical asset | D6: Line→Section→Cavity hierarchy | E6: DIM_ASSET_SCOPE | F6: No false production precision
A7: Production event ID | B7: 02_Supervisor_Log / DailyProduction | C7: Production event | D7: Stable parent key | E7: Existing FACT_PRODUCTION + key | F7: Original grain unchanged
A8: Production configuration | B8: 02_Supervisor_Log / ProductionConfiguration | C8: Event × Section | D8: Exact active cavity flags | E8: New detail bridge/fact | F8: Unpivot cavity flags in Power Query
A9: Job change event ID | B9: 02_Supervisor_Log / JobChange | C9: Job change event | D9: Stable parent key | E9: Existing FACT_JOBCHANGE + key | F9: Existing measures remain
A10: Job change impact | B10: 02_Supervisor_Log / JobChangeImpact | C10: Impact record | D10: Where loss occurred | E10: New FACT_JOBCHANGE_IMPACT | F10: Use capacity-weighted loss
