Workbook

Sheet Dashboard_View
A1: Kandil Glass Company - Factory #3 Performance Dashboard
A2: Period: 2026-07-01 to 2026-07-02 | Source: Fact_Production_Hourly, Fact_Quality_Sampling
A3: KPI CARDS | B3: Value | C3: Status | F3: Hour | G3: TotalActualUnits | I3: Classification | J3: TotalCount | L3: Machine | M3: EfficiencyPct | O3: Shift | P3: AvgOEE
A4: OEE (Availability x Performance x Quality) | B4: =AVERAGE(Fact_Production_Hourly!$O$2:$O$337)*AVERAGE(Fact_Production_Hourly!$P$2:$P$337)*AVERAGE(Fact_Production_Hourly!$Q$2:$Q$337) -> 0.80742922 | C4: =IF(B4>=0.85,"GOOD",IF(B4>=0.7,"WARNING","BAD")) -> WARNING | F4: 0 | G4: =SUMIFS(Fact_Production_Hourly!$K$2:$K$337,Fact_Production_Hourly!$C$2:$C$337,F4) -> 326024 | I4: Critical | J4: =SUM(Fact_Quality_Sampling!$I$2:$I$337) -> 0 | L4: M1 | M4: =SUMIFS(Fact_Production_Hourly!$K$2:$K$337,Fact_Production_Hourly!$D$2:$D$337,L4)/SUMIFS(Fact_Production_Hourly!$J$2:$J$337,Fact_Production_Hourly!$D$2:$D$337,L4) -> 0.89125037 | O4: A-AM | P4: =AVERAGEIFS(Fact_Production_Hourly!$R$2:$R$337,Fact_Production_Hourly!$E$2:$E$337,O4) -> 0.80546518
A5: Efficiency % (Actual / Design Capacity) | B5: =SUM(Fact_Production_Hourly!$K$2:$K$337)/SUM(Fact_Production_Hourly!$J$2:$J$337) -> 0.88321676 | C5: =IF(B5>=0.9,"GOOD",IF(B5>=0.8,"WARNING","BAD")) -> WARNING | F5: 1 | G5: =SUMIFS(Fact_Production_Hourly!$K$2:$K$337,Fact_Production_Hourly!$C$2:$C$337,F5) -> 336188 | I5: Major | J5: =SUM(Fact_Quality_Sampling!$J$2:$J$337) -> 140 | L5: M2 | M5: =SUMIFS(Fact_Production_Hourly!$K$2:$K$337,Fact_Production_Hourly!$D$2:$D$337,L5)/SUMIFS(Fact_Production_Hourly!$J$2:$J$337,Fact_Production_Hourly!$D$2:$D$337,L5) -> 0.87869705 | O5: B-PM | P5: =AVERAGEIFS(Fact_Production_Hourly!$R$2:$R$337,Fact_Production_Hourly!$E$2:$E$337,O5) -> 0.80908319
A6: Pack-to-Melt % (Accepted Tons / Molten Tons) | B6: =SUM(Fact_Production_Hourly!$T$2:$T$337)/SUM(Fact_Production_Hourly!$S$2:$S$337) -> 0.87151259 | C6: =IF(B6>=0.85,"GOOD",IF(B6>=0.75,"WARNING","BAD")) -> GOOD | F6: 2 | G6: =SUMIFS(Fact_Production_Hourly!$K$2:$K$337,Fact_Production_Hourly!$C$2:$C$337,F6) -> 343981 | I6: Minor | J6: =SUM(Fact_Quality_Sampling!$K$2:$K$337) -> 355 | L6: M3 | M6: =SUMIFS(Fact_Production_Hourly!$K$2:$K$337,Fact_Production_Hourly!$D$2:$D$337,L6)/SUMIFS(Fact_Production_Hourly!$J$2:$J$337,Fact_Production_Hourly!$D$2:$D$337,L6) -> 0.8790067
A7: First Pass Yield (FPY) | B7: =1-SUM(Fact_Quality_Sampling!$H$2:$H$337)/SUM(Fact_Quality_Sampling!$G$2:$G$337) -> 0.9597168 | C7: =IF(B7>=0.95,"GOOD",IF(B7>=0.9,"WARNING","BAD")) -> GOOD | F7: 3 | G7: =SUMIFS(Fact_Production_Hourly!$K$2:$K$337,Fact_Production_Hourly!$C$2:$C$337,F7) -> 344793 | L7: M4 | M7: =SUMIFS(Fact_Production_Hourly!$K$2:$K$337,Fact_Production_Hourly!$D$2:$D$337,L7)/SUMIFS(Fact_Production_Hourly!$J$2:$J$337,Fact_Production_Hourly!$D$2:$D$337,L7) -> 0.88856616
A8: Defect Rate % | B8: =SUM(Fact_Quality_Sampling!$H$2:$H$337)/SUM(Fact_Quality_Sampling!$G$2:$G$337) -> 0.040283203 | C8: =IF(B8<=0.03,"GOOD",IF(B8<=0.06,"WARNING","BAD")) -> WARNING | F8: 4 | G8: =SUMIFS(Fact_Production_Hourly!$K$2:$K$337,Fact_Production_Hourly!$C$2:$C$337,F8) -> 340542 | L8: M5 | M8: =SUMIFS(Fact_Production_Hourly!$K$2:$K$337,Fact_Production_Hourly!$D$2:$D$337,L8)/SUMIFS(Fact_Production_Hourly!$J$2:$J$337,Fact_Production_Hourly!$D$2:$D$337,L8) -> 0.87020595
A9: - Critical Defect Share | B9: =SUM(Fact_Quality_Sampling!$I$2:$I$337)/SUM(Fact_Quality_Sampling!$H$2:$H$337) -> 0 | F9: 5 | G9: =SUMIFS(Fact_Production_Hourly!$K$2:$K$337,Fact_Production_Hourly!$C$2:$C$337,F9) -> 329757 | L9: M6 | M9: =SUMIFS(Fact_Production_Hourly!$K$2:$K$337,Fact_Production_Hourly!$D$2:$D$337,L9)/SUMIFS(Fact_Production_Hourly!$J$2:$J$337,Fact_Production_Hourly!$D$2:$D$337,L9) -> 0.88578062
A10: - Major Defect Share | B10: =SUM(Fact_Quality_Sampling!$J$2:$J$337)/SUM(Fact_Quality_Sampling!$H$2:$H$337) -> 0.28282828 | F10: 6 | G10: =SUMIFS(Fact_Production_Hourly!$K$2:$K$337,Fact_Production_Hourly!$C$2:$C$337,F10) -> 327997 | L10: M7 | M10: =SUMIFS(Fact_Production_Hourly!$K$2:$K$337,Fact_Production_Hourly!$D$2:$D$337,L10)/SUMIFS(Fact_Production_Hourly!$J$2:$J$337,Fact_Production_Hourly!$D$2:$D$337,L10) -> 0.88604283
A11: - Minor Defect Share | B11: =SUM(Fact_Quality_Sampling!$K$2:$K$337)/SUM(Fact_Quality_Sampling!$H$2:$H$337) -> 0.71717172 | F11: 7 | G11: =SUMIFS(Fact_Production_Hourly!$K$2:$K$337,Fact_Production_Hourly!$C$2:$C$337,F11) -> 342391
F12: 8 | G12: =SUMIFS(Fact_Production_Hourly!$K$2:$K$337,Fact_Production_Hourly!$C$2:$C$337,F12) -> 332231
F13: 9 | G13: =SUMIFS(Fact_Production_Hourly!$K$2:$K$337,Fact_Production_Hourly!$C$2:$C$337,F13) -> 344261
F14: 10 | G14: =SUMIFS(Fact_Production_Hourly!$K$2:$K$337,Fact_Production_Hourly!$C$2:$C$337,F14) -> 336146
F15: 11 | G15: =SUMIFS(Fact_Production_Hourly!$K$2:$K$337,Fact_Production_Hourly!$C$2:$C$337,F15) -> 339673
F16: 12 | G16: =SUMIFS(Fact_Production_Hourly!$K$2:$K$337,Fact_Production_Hourly!$C$2:$C$337,F16) -> 341599
F17: 13 | G17: =SUMIFS(Fact_Production_Hourly!$K$2:$K$337,Fact_Production_Hourly!$C$2:$C$337,F17) -> 345543
F18: 14 | G18: =SUMIFS(Fact_Production_Hourly!$K$2:$K$337,Fact_Production_Hourly!$C$2:$C$337,F18) -> 319429
F19: 15 | G19: =SUMIFS(Fact_Production_Hourly!$K$2:$K$337,Fact_Production_Hourly!$C$2:$C$337,F19) -> 339712
F20: 16 | G20: =SUMIFS(Fact_Production_Hourly!$K$2:$K$337,Fact_Production_Hourly!$C$2:$C$337,F20) -> 330608
F21: 17 | G21: =SUMIFS(Fact_Production_Hourly!$K$2:$K$337,Fact_Production_Hourly!$C$2:$C$337,F21) -> 328956
F22: 18 | G22: =SUMIFS(Fact_Production_Hourly!$K$2:$K$337,Fact_Production_Hourly!$C$2:$C$337,F22) -> 341672
F23: 19 | G23: =SUMIFS(Fact_Production_Hourly!$K$2:$K$337,Fact_Production_Hourly!$C$2:$C$337,F23) -> 338998
... F27: 23 | G27: =SUMIFS(Fact_Production_Hourly!$K$2:$K$337,Fact_Production_Hourly!$C$2:$C$337,F27) -> 346208

Sheet Decision_Layer
A1: Industrial Decision Layer - Thresholds & Required Actions
A3: KPI | B3: Good | C3: Warning | D3: Bad | E3: Action if Warning | F3: Action if Bad
A4: OEE | B4: >= 85% | C4: 70% - 84% | D4: < 70% | E4: Review the weakest of Availability/Performance/Quality for the shift; brief the shift lead. | F4: Stop and root-cause: check changeover/downtime logs, mold condition, and defect Pareto before resuming full-speed run.
A5: Efficiency % | B5: >= 90% | C5: 80% - 89% | D5: < 80% | E5: Check for minor speed loss or short stoppages; verify machine is running at rated speed. | F5: Investigate downtime causes (mechanical, material feed, operator) and speed loss; escalate to maintenance.
A6: Pack-to-Melt % | B6: >= 85% | C6: 75% - 84% | D6: < 75% | E6: Review scrap/rejects at the hot end and cooling; check for glass loss between melt and pack. | F6: Stop and inspect furnace-to-press glass flow and job-change losses; significant tonnage is being lost.
A7: First Pass Yield (FPY) | B7: >= 95% | C7: 90% - 94% | D7: < 90% | E7: Review recent mold/tooling wear and process drift on the affected machine/product. | F7: Halt the line for mold/tooling inspection; a systemic first-pass quality issue is likely.
A8: Defect Rate % | B8: <= 3% | C8: 3% - 6% | D8: > 6% | E8: Increase sampling frequency temporarily and monitor the trend for the next 2 hours. | F8: Stop the machine and investigate mold, glass temperature, or operator technique immediately.
A9: Critical Defects (trend) | B9: flat/zero | C9: isolated increase | D9: sustained increase | E9: Notify shift QC lead; re-inspect the last 2 hours of that machine's output. | F9: Stop machine immediately and investigate mold/tooling; quarantine the affected pallets.
A10: Scrap Rate | B10: <= 2% | C10: 2% - 5% | D10: > 5% | E10: Check press settings and glass temperature consistency. | F10: Stop and recalibrate machine settings; escalate to process engineer.

Sheet Data_Dictionary
A1: Data Dictionary & Modeling Notes - Kandil Glass Factory #3
A3: Sheet | B3: Grain Definition | C3: Keys / Star-Schema Relationship
A4: Fact_Production_Hourly | B4: 1 row per Machine per Hour per Product per Shift (7 machines x 24h x 2 days = 336 rows). | C4: PK: ProdKey (DateKey-HourKey-MachineKey). FKs: DateKey->Dim_Date, HourKey->Dim_Time, MachineKey->Dim_Machine, ShiftKey->Dim_Shift, ProductKey->Dim_Product.
A5: Fact_Quality_Sampling | B5: 1 row per Machine per Hour, aggregating that hour's sample (SampleSize = Forms x 2). Chosen over a literal per-sampled-unit grain (~250 units/hour x 336 hours = ~85,000 rows) to stay practical in Excel, while still carrying full Critical/Major/Minor breakdown and weight/diameter/height tolerance-check counts per hour. | C5: PK: SampleKey. Same FKs as Fact_Production_Hourly, joins 1:1 on DateKey+HourKey+MachineKey.
A6: Fact_Inspection | B6: 1 row per Order per Inspection event (6 sample orders). | C6: PK: InspectionKey. FKs: CustomerKey->Dim_Customer, InspectorKey->Dim_Inspector, ShiftKey->Dim_Shift, DateKey->Dim_Date, ProductKey->Dim_Product.
A7: Dim_Date | B7: 1 row per calendar day. | C7: PK: DateKey (YYYYMMDD integer).
A8: Dim_Time | B8: 1 row per hour-of-day (0-23). | C8: PK: HourKey. AM shift = hours 6-17, PM shift = hours 18-5 (720 min each).
A9: Dim_Shift | B9: 1 row per Group x AM/PM permutation across the 3-week rotation. | C9: PK: ShiftKey (e.g. A-AM).
A10: Dim_Machine | B10: 1 row per pressing machine (7 total). | C10: PK: MachineKey. Units/cycle = Forms.
A11: Dim_Product | B11: 1 row per product code (3 sample products). | C11: PK: ProductKey. Min/Max = Design +/- Tolerance.
A12: Dim_Defect | B12: 1 row per defect code (6 sample defects). | C12: PK: DefectCode. Classification: Critical/Major/Minor.
A13: Dim_Inspector | B13: 1 row per QC inspector. | C13: PK: InspectorKey.
A14: Dim_Customer | B14: 1 row per customer. | C14: PK: CustomerKey.
A16: DATA CLEANING RULES
A17: - Missing hourly data: flag the ProdKey as missing rather than deleting the hour; do not interpolate Actual Production (masks real downtime) - instead set ActualProductionUnits=0 and DowntimeMinutes=60, which correctly drags Availability to 0 for that hour.
A18: - Standardizing defect names: enforce defect entry via Dim_Defect's DefectCode only (dropdown/validation), never free-text defect names, so 'Bubble' / 'bubbles' / 'Air bubble' always resolve to one canonical D03 row.
A19: - No duplicate records: ProdKey (DateKey-HourKey-MachineKey) and SampleKey must be unique - enforce with a UNIQUE/COUNTIFS check column before load, or a Power Query dedupe step keyed on those columns.
A20: - Out-of-tolerance measurements: never discard - keep the raw measurement and let the OK/NOT OK formula classify it; out-of-tolerance rows are exactly the signal Quality/FPY KPIs need, not data errors to clean away.

Sheet Fact_Production_Hourly
A1: ProdKey (PK) | B1: DateKey (FK) | C1: HourKey (FK) | D1: MachineKey (FK) | E1: ShiftKey (FK) | F1: ProductKey (FK) | G1: PlannedMinutes | H1: DowntimeMinutes | I1: OperatingMinutes | J1: DesignCapacityUnits | K1: ActualProductionUnits | L1: ScrapUnits | M1: GoodUnits | N1: EfficiencyPct | O1: Availability | P1: Performance | Q1: QualityRate | R1: OEE | S1: MoltenGlassTons | T1: OutputTons | U1: PackToMeltPct
A2: 20260701-00-M1 | B2: 20260701 | C2: 0 | D2: M1 | E2: B-PM | F2: A | G2: 60 | H2: 5.6 | I2: =G2-H2 -> 54.4 | J2: =INDEX(Dim_Machine!$E$2:$E$8,MATCH(D2,Dim_Machine!$A$2:$A$8,0))*INDEX(Dim_Machine!$D$2:$D$8,MATCH(D2,Dim_Machine!$A$2:$A$8,0))*I2 -> 21760 | K2: =ROUND(J2*0.864,0) -> 18801 | L2: =ROUND(K2*0.0185,0) -> 348 | M2: =K2-L2 -> 18453 | N2: =IFERROR(K2/J2,0) -> 0.86401654 | O2: =IFERROR(I2/G2,0) -> 0.90666667 | P2: =IFERROR((K2/I2)/(INDEX(Dim_Machine!$E$2:$E$8,MATCH(D2,Dim_Machine!$A$2:$A$8,0))*INDEX(Dim_Machine!$D$2:$D$8,MATCH(D2,Dim_Machine!$A$2:$A$8,0))),0) -> 0.86401654 | Q2: =IFERROR(M2/K2,0) -> 0.98149035 | R2: =O2*P2*Q2 -> 0.768875 | S2: =T2/0.842 -> 5.4789192 | T2: =M2*INDEX(Dim_Product!$C$2:$C$4,MATCH(F2,Dim_Product!$A$2:$A$4,0))/1000000 -> 4.61325 | U2: =IFERROR(T2/S2,0) -> 0.842
A3: 20260701-00-M2 | B3: 20260701 | C3: 0 | D3: M2 | E3: B-PM | F3: C | G3: 60 | H3: 7 | I3: =G3-H3 -> 53 | J3: =INDEX(Dim_Machine!$E$2:$E$8,MATCH(D3,Dim_Machine!$A$2:$A$8,0))*INDEX(Dim_Machine!$D$2:$D$8,MATCH(D3,Dim_Machine!$A$2:$A$8,0))*I3 -> 35616 | K3: =ROUND(J3*0.932,0) -> 33194 | L3: =ROUND(K3*0.0098,0) -> 325 | M3: =K3-L3 -> 32869 | N3: =IFERROR(K3/J3,0) -> 0.93199686 | O3: =IFERROR(I3/G3,0) -> 0.88333333 | P3: =IFERROR((K3/I3)/(INDEX(Dim_Machine!$E$2:$E$8,MATCH(D3,Dim_Machine!$A$2:$A$8,0))*INDEX(Dim_Machine!$D$2:$D$8,MATCH(D3,Dim_Machine!$A$2:$A$8,0))),0) -> 0.93199686 | Q3: =IFERROR(M3/K3,0) -> 0.99020907 | R3: =O3*P3*Q3 -> 0.81520337 | S3: =T3/0.863 -> 7.6173812 | T3: =M3*INDEX(Dim_Product!$C$2:$C$4,MATCH(F3,Dim_Product!$A$2:$A$4,0))/1000000 -> 6.5738 | U3: =IFERROR(T3/S3,0) -> 0.863
A4: 20260701-00-M3 | B4: 20260701 | C4: 0 | D4: M3 | E4: B-PM | F4: A | G4: 60 | H4: 2.2 | I4: =G4-H4 -> 57.8 | J4: =INDEX(Dim_Machine!$E$2:$E$8,MATCH(D4,Dim_Machine!$A$2:$A$8,0))*INDEX(Dim_Machine!$D$2:$D$8,MATCH(D4,Dim_Machine!$A$2:$A$8,0))*I4 -> 15259.2 | K4: =ROUND(J4*0.823,0) -> 12558 | L4: =ROUND(K4*0.0279,0) -> 350 | M4: =K4-L4 -> 12208 | N4: =IFERROR(K4/J4,0) -> 0.82297892 | O4: =IFERROR(I4/G4,0) -> 0.96333333 | P4: =IFERROR((K4/I4)/(INDEX(Dim_Machine!$E$2:$E$8,MATCH(D4,Dim_Machine!$A$2:$A$8,0))*INDEX(Dim_Machine!$D$2:$D$8,MATCH(D4,Dim_Machine!$A$2:$A$8,0))),0) -> 0.82297892 | Q4: =IFERROR(M4/K4,0) -> 0.97212932 | R4: =O4*P4*Q4 -> 0.77070707 | S4: =T4/0.815 -> 3.7447853 | T4: =M4*INDEX(Dim_Product!$C$2:$C$4,MATCH(F4,Dim_Product!$A$2:$A$4,0))/1000000 -> 3.052 | U4: =IFERROR(T4/S4,0) -> 0.815
A5: 20260701-00-M4 | B5: 20260701 | C5: 0 | D5: M4 | E5: B-PM | F5: A | G5: 60 | H5: 3 | I5: =G5-H5 -> 57 | J5: =INDEX(Dim_Machine!$E$2:$E$8,MATCH(D5,Dim_Machine!$A$2:$A$8,0))*INDEX(Dim_Machine!$D$2:$D$8,MATCH(D5,Dim_Machine!$A$2:$A$8,0))*I5 -> 41040 | K5: =ROUND(J5*0.852,0) -> 34966 | L5: =ROUND(K5*0.0153,0) -> 535 | M5: =K5-L5 -> 34431 | N5: =IFERROR(K5/J5,0) -> 0.85199805 | O5: =IFERROR(I5/G5,0) -> 0.95 | P5: =IFERROR((K5/I5)/(INDEX(Dim_Machine!$E$2:$E$8,MATCH(D5,Dim_Machine!$A$2:$A$8,0))*INDEX(Dim_Machine!$D$2:$D$8,MATCH(D5,Dim_Machine!$A$2:$A$8,0))),0) -> 0.85199805 | Q5: =IFERROR(M5/K5,0) -> 0.98469942 | R5: =O5*P5*Q5 -> 0.79701389 | S5: =T5/0.84 -> 10.247321 | T5: =M5*INDEX(Dim_Product!$C$2:$C$4,MATCH(F5,Dim_Product!$A$2:$A$4,0))/1000000 -> 8.60775 | U5: =IFERROR(T5/S5,0) -> 0.84
A6: 20260701-00-M5 | B6: 20260701 | C6: 0 | D6: M5 | E6: B-PM | F6: A | G6: 60 | H6: 0.3 | I6: =G6-H6 -> 59.7 | J6: =INDEX(Dim_Machine!$E$2:$E$8,MATCH(D6,Dim_Machine!$A$2:$A$8,0))*INDEX(Dim_Machine!$D$2:$D$8,MATCH(D6,Dim_Machine!$A$2:$A$8,0))*I6 -> 24835.2 | K6: =ROUND(J6*0.872,0) -> 21656 | L6: =ROUND(K6*0.0087,0) -> 188 | M6: =K6-L6 -> 21468 | N6: =IFERROR(K6/J6,0) -> 0.87198815 | O6: =IFERROR(I6/G6,0) -> 0.995 | P6: =IFERROR((K6/I6)/(INDEX(Dim_Machine!$E$2:$E$8,MATCH(D6,Dim_Machine!$A$2:$A$8,0))*INDEX(Dim_Machine!$D$2:$D$8,MATCH(D6,Dim_Machine!$A$2:$A$8,0))),0) -> 0.87198815 | Q6: =IFERROR(M6/K6,0) -> 0.9913188 | R6: =O6*P6*Q6 -> 0.86009615 | S6: =T6/0.938 -> 5.7217484 | T6: =M6*INDEX(Dim_Product!$C$2:$C$4,MATCH(F6,Dim_Product!$A$2:$A$4,0))/1000000 -> 5.367 | U6: =IFERROR(T6/S6,0) -> 0.938
A7: 20260701-00-M6 | B7: 20260701 | C7: 0 | D7: M6 | E7: B-PM | F7: C | G7: 60 | H7: 0.6 | I7: =G7-H7 -> 59.4 | J7: =INDEX(Dim_Machine!$E$2:$E$8,MATCH(D7,Dim_Machine!$A$2:$A$8,0))*INDEX(Dim_Machine!$D$2:$D$8,MATCH(D7,Dim_Machine!$A$2:$A$8,0))*I7 -> 17107.2 | K7: =ROUND(J7*0.839,0) -> 14353 | L7: =ROUND(K7*0.0239,0) -> 343 | M7: =K7-L7 -> 14010 | N7: =IFERROR(K7/J7,0) -> 0.83900346 | O7: =IFERROR(I7/G7,0) -> 0.99 | P7: =IFERROR((K7/I7)/(INDEX(Dim_Machine!$E$2:$E$8,MATCH(D7,Dim_Machine!$A$2:$A$8,0))*INDEX(Dim_Machine!$D$2:$D$8,MATCH(D7,Dim_Machine!$A$2:$A$8,0))),0) -> 0.83900346 | Q7: =IFERROR(M7/K7,0) -> 0.97610256 | R7: =O7*P7*Q7 -> 0.81076389 | S7: =T7/0.933 -> 3.0032154 | T7: =M7*INDEX(Dim_Product!$C$2:$C$4,MATCH(F7,Dim_Product!$A$2:$A$4,0))/1000000 -> 2.802 | U7: =IFERROR(T7/S7,0) -> 0.933
A8: 20260701-00-M7 | B8: 20260701 | C8: 0 | D8: M7 | E8: B-PM | F8: A | G8: 60 | H8: 2.9 | I8: =G8-H8 -> 57.1 | J8: =INDEX(Dim_Machine!$E$2:$E$8,MATCH(D8,Dim_Machine!$A$2:$A$8,0))*INDEX(Dim_Machine!$D$2:$D$8,MATCH(D8,Dim_Machine!$A$2:$A$8,0))*I8 -> 37000.8 | K8: =ROUND(J8*0.818,0) -> 30267 | L8: =ROUND(K8*0.0071,0) -> 215 | M8: =K8-L8 -> 30052 | N8: =IFERROR(K8/J8,0) -> 0.81800934 | O8: =IFERROR(I8/G8,0) -> 0.95166667 | P8: =IFERROR((K8/I8)/(INDEX(Dim_Machine!$E$2:$E$8,MATCH(D8,Dim_Machine!$A$2:$A$8,0))*INDEX(Dim_Machine!$D$2:$D$8,MATCH(D8,Dim_Machine!$A$2:$A$8,0))),0) -> 0.81800934 | Q8: =IFERROR(M8/K8,0) -> 0.99289655 | R8: =O8*P8*Q8 -> 0.77294239 | S8: =T8/0.899 -> 8.3570634 | T8: =M8*INDEX(Dim_Product!$C$2:$C$4,MATCH(F8,Dim_Product!$A$2:$A$4,0))/1000000 -> 7.513 | U8: =IFERROR(T8/S8,0) -> 0.899
A9: 20260701-01-M1 | B9: 20260701 | C9: 1 | D9: M1 | E9: B-PM | F9: A | G9: 60 | H9: 6.2 | I9: =G9-H9 -> 53.8 | J9: =INDEX(Dim_Machine!$E$2:$E$8,MATCH(D9,Dim_Machine!$A$2:$A$8,0))*INDEX(Dim_Machine!$D$2:$D$8,MATCH(D9,Dim_Machine!$A$2:$A$8,0))*I9 -> 21520 | K9: =ROUND(J9*0.977,0) -> 21025 | L9: =ROUND(K9*0.0307,0) -> 645 | M9: =K9-L9 -> 20380 | N9: =IFERROR(K9/J9,0) -> 0.97699814 | O9: =IFERROR(I9/G9,0) -> 0.89666667 | P9: =IFERROR((K9/I9)/(INDEX(Dim_Machine!$E$2:$E$8,MATCH(D9,Dim_Machine!$A$2:$A$8,0))*INDEX(Dim_Machine!$D$2:$D$8,MATCH(D9,Dim_Machine!$A$2:$A$8,0))),0) -> 0.97699814 | Q9: =IFERROR(M9/K9,0) -> 0.96932224 | R9: =O9*P9*Q9 -> 0.84916667 | S9: =T9/0.93 -> 5.4784946 | T9: =M9*INDEX(Dim_Product!$C$2:$C$4,MATCH(F9,Dim_Product!$A$2:$A$4,0))/1000000 -> 5.095 | U9: =IFERROR(T9/S9,0) -> 0.93
A10: 20260701-01-M2 | B10: 20260701 | C10: 1 | D10: M2 | E10: B-PM | F10: C | G10: 60 | H10: 3 | I10: =G10-H10 -> 57 | J10: =INDEX(Dim_Machine!$E$2:$E$8,MATCH(D10,Dim_Machine!$A$2:$A$8,0))*INDEX(Dim_Machine!$D$2:$D$8,MATCH(D10,Dim_Machine!$A$2:$A$8,0))*I10 -> 38304 | K10: =ROUND(J10*0.871,0) -> 33363 | L10: =ROUND(K10*0.03,0) -> 1001 | M10: =K10-L10 -> 32362 | N10: =IFERROR(K10/J10,0) -> 0.87100564 | O10: =IFERROR(I10/G10,0) -> 0.95 | P10: =IFERROR((K10/I10)/(INDEX(Dim_Machine!$E$2:$E$8,MATCH(D10,Dim_Machine!$A$2:$A$8,0))*INDEX(Dim_Machine!$D$2:$D$8,MATCH(D10,Dim_Machine!$A$2:$A$8,0))),0) -> 0.87100564 | Q10: =IFERROR(M10/K10,0) -> 0.9699967 | R10: =O10*P10*Q10 -> 0.80262897 | S10: =T10/0.824 -> 7.8548544 | T10: =M10*INDEX(Dim_Product!$C$2:$C$4,MATCH(F10,Dim_Product!$A$2:$A$4,0))/1000000 -> 6.4724 | U10: =IFERROR(T10/S10,0) -> 0.824
A11: 20260701-01-M3 | B11: 20260701 | C11: 1 | D11: M3 | E11: B-PM | F11: A | G11: 60 | H11: 2.8 | I11: =G11-H11 -> 57.2 | J11: =INDEX(Dim_Machine!$E$2:$E$8,MATCH(D11,Dim_Machine!$A$2:$A$8,0))*INDEX(Dim_Machine!$D$2:$D$8,MATCH(D11,Dim_Machine!$A$2:$A$8,0))*I11 -> 15100.8 | K11: =ROUND(J11*0.914,0) -> 13802 | L11: =ROUND(K11*0.0261,0) -> 360 | M11: =K11-L11 -> 13442 | N11: =IFERROR(K11/J11,0) -> 0.91399131 | O11: =IFERROR(I11/G11,0) -> 0.95333333 | P11: =IFERROR((K11/I11)/(INDEX(Dim_Machine!$E$2:$E$8,MATCH(D11,Dim_Machine!$A$2:$A$8,0))*INDEX(Dim_Machine!$D$2:$D$8,MATCH(D11,Dim_Machine!$A$2:$A$8,0))),0) -> 0.91399131 | Q11: =IFERROR(M11/K11,0) -> 0.97391682 | R11: =O11*P11*Q11 -> 0.84861111 | S11: =T11/0.903 -> 3.7214839 | T11: =M11*INDEX(Dim_Product!$C$2:$C$4,MATCH(F11,Dim_Product!$A$2:$A$4,0))/1000000 -> 3.3605 | U11: =IFERROR(T11/S11,0) -> 0.903
A12: 20260701-01-M4 | B12: 20260701 | C12: 1 | D12: M4 | E12: B-PM | F12: A | G12: 60 | H12: 0.6 | I12: =G12-H12 -> 59.4 | J12: =INDEX(Dim_Machine!$E$2:$E$8,MATCH(D12,Dim_Machine!$A$2:$A$8,0))*INDEX(Dim_Machine!$D$2:$D$8,MATCH(D12,Dim_Machine!$A$2:$A$8,0))*I12 -> 42768 | K12: =ROUND(J12*0.907,0) -> 38791 | L12: =ROUND(K12*0.021,0) -> 815 | M12: =K12-L12 -> 37976 | N12: =IFERROR(K12/J12,0) -> 0.90700991 | O12: =IFERROR(I12/G12,0) -> 0.99 | P12: =IFERROR((K12/I12)/(INDEX(Dim_Machine!$E$2:$E$8,MATCH(D12,Dim_Machine!$A$2:$A$8,0))*INDEX(Dim_Machine!$D$2:$D$8,MATCH(D12,Dim_Machine!$A$2:$A$8,0))),0) -> 0.90700991 | Q12: =IFERROR(M12/K12,0) -> 0.97898997 | R12: =O12*P12*Q12 -> 0.87907407 | S12: =T12/0.837 -> 11.342891 | T12: =M12*INDEX(Dim_Product!$C$2:$C$4,MATCH(F12,Dim_Product!$A$2:$A$4,0))/1000000 -> 9.494 | U12: =IFERROR(T12/S12,0) -> 0.837
A13: 20260701-01-M5 | B13: 20260701 | C13: 1 | D13: M5 | E13: B-PM | F13: A | G13: 60 | H13: 3.7 | I13: =G13-H13 -> 56.3 | J13: =INDEX(Dim_Machine!$E$2:$E$8,MATCH(D13,Dim_Machine!$A$2:$A$8,0))*INDEX(Dim_Machine!$D$2:$D$8,MATCH(D13,Dim_Machine!$A$2:$A$8,0))*I13 -> 23420.8 | K13: =ROUND(J13*0.834,0) -> 19533 | L13: =ROUND(K13*0.0328,0) -> 641 | M13: =K13-L13 -> 18892 | N13: =IFERROR(K13/J13,0) -> 0.83400225 | O13: =IFERROR(I13/G13,0) -> 0.93833333 | P13: =IFERROR((K13/I13)/(INDEX(Dim_Machine!$E$2:$E$8,MATCH(D13,Dim_Machine!$A$2:$A$8,0))*INDEX(Dim_Machine!$D$2:$D$8,MATCH(D13,Dim_Machine!$A$2:$A$8,0))),0) -> 0.83400225 | Q13: =IFERROR(M13/K13,0) -> 0.96718374 | R13: =O13*P13*Q13 -> 0.75689103 | S13: =T13/0.903 -> 5.2303433 | T13: =M13*INDEX(Dim_Product!$C$2:$C$4,MATCH(F13,Dim_Product!$A$2:$A$4,0))/1000000 -> 4.723 | U13: =IFERROR(T13/S13,0) -> 0.903
A14: 20260701-01-M6 | B14: 20260701 | C14: 1 | D14: M6 | E14: B-PM | F14: C | G14: 60 | H14: 1.8 | I14: =G14-H14 -> 58.2 | J14: =INDEX(Dim_Machine!$E$2:$E$8,MATCH(D14,Dim_Machine!$A$2:$A$8,0))*INDEX(Dim_Machine!$D$2:$D$8,MATCH(D14,Dim_Machine!$A$2:$A$8,0))*I14 -> 16761.6 | K14: =ROUND(J14*0.845,0) -> 14164 | L14: =ROUND(K14*0.028,0) -> 397 | M14: =K14-L14 -> 13767 | N14: =IFERROR(K14/J14,0) -> 0.84502673 | O14: =IFERROR(I14/G14,0) -> 0.97 | P14: =IFERROR((K14/I14)/(INDEX(Dim_Machine!$E$2:$E$8,MATCH(D14,Dim_Machine!$A$2:$A$8,0))*INDEX(Dim_Machine!$D$2:$D$8,MATCH(D14,Dim_Machine!$A$2:$A$8,0))),0) -> 0.84502673 | Q14: =IFERROR(M14/K14,0) -> 0.97197119 | R14: =O14*P14*Q14 -> 0.79670139 | S14: =T14/0.808 -> 3.4076733 | T14: =M14*INDEX(Dim_Product!$C$2:$C$4,MATCH(F14,Dim_Product!$A$2:$A$4,0))/1000000 -> 2.7534 | U14: =IFERROR(T14/S14,0) -> 0.808
A15: 20260701-01-M7 | B15: 20260701 | C15: 1 | D15: M7 | E15: B-PM | F15: A | G15: 60 | H15: 6.6 | I15: =G15-H15 -> 53.4 | J15: =INDEX(Dim_Machine!$E$2:$E$8,MATCH(D15,Dim_Machine!$A$2:$A$8,0))*INDEX(Dim_Machine!$D$2:$D$8,MATCH(D15,Dim_Machine!$A$2:$A$8,0))*I15 -> 34603.2 | K15: =ROUND(J15*0.941,0) -> 32562 | L15: =ROUND(K15*0.017,0) -> 554 | M15: =K15-L15 -> 32008 | N15: =IFERROR(K15/J15,0) -> 0.94101124 | O15: =IFERROR(I15/G15,0) -> 0.89 | P15: =IFERROR((K15/I15)/(INDEX(Dim_Machine!$E$2:$E$8,MATCH(D15,Dim_Machine!$A$2:$A$8,0))*INDEX(Dim_Machine!$D$2:$D$8,MATCH(D15,Dim_Machine!$A$2:$A$8,0))),0) -> 0.94101124 | Q15: =IFERROR(M15/K15,0) -> 0.9829863 | R15: =O15*P15*Q15 -> 0.82325103 | S15: =T15/0.81 -> 9.8790123 | T15: =M15*INDEX(Dim_Product!$C$2:$C$4,MATCH(F15,Dim_Product!$A$2:$A$4,0))/1000000 -> 8.002 | U15: =IFERROR(T15/S15,0) -> 0.81
A16: 20260701-02-M1 | B16: 20260701 | C16: 2 | D16: M1 | E16: B-PM | F16: A | G16: 60 | H16: 7.3 | I16: =G16-H16 -> 52.7 | J16: =INDEX(Dim_Machine!$E$2:$E$8,MATCH(D16,Dim_Machine!$A$2:$A$8,0))*INDEX(Dim_Machine!$D$2:$D$8,MATCH(D16,Dim_Machine!$A$2:$A$8,0))*I16 -> 21080 | K16: =ROUND(J16*0.893,0) -> 18824 | L16: =ROUND(K16*0.0265,0) -> 499 | M16: =K16-L16 -> 18325 | N16: =IFERROR(K16/J16,0) -> 0.89297913 | O16: =IFERROR(I16/G16,0) -> 0.87833333 | P16: =IFERROR((K16/I16)/(INDEX(Dim_Machine!$E$2:$E$8,MATCH(D16,Dim_Machine!$A$2:$A$8,0))*INDEX(Dim_Machine!$D$2:$D$8,MATCH(D16,Dim_Machine!$A$2:$A$8,0))),0) -> 0.89297913 | Q16: =IFERROR(M16/K16,0) -> 0.97349129 | R16: =O16*P16*Q16 -> 0.76354167 | S16: =T16/0.832 -> 5.5063101 | T16: =M16*INDEX(Dim_Product!$C$2:$C$4,MATCH(F16,Dim_Product!$A$2:$A$4,0))/1000000 -> 4.58125 | U16: =IFERROR(T16/S16,0) -> 0.832
A17: 20260701-02-M2 | B17: 20260701 | C17: 2 | D17: M2 | E17: B-PM | F17: C | G17: 60 | H17: 4 | I17: =G17-H17 -> 56 | J17: =INDEX(Dim_Machine!$E$2:$E$8,MATCH(D17,Dim_Machine!$A$2:$A$8,0))*INDEX(Dim_Machine!$D$2:$D$8,MATCH(D17,Dim_Machine!$A$2:$A$8,0))*I17 -> 37632 | K17: =ROUND(J17*0.957,0) -> 36014 | L17: =ROUND(K17*0.0243,0) -> 875 | M17: =K17-L17 -> 35139 | N17: =IFERROR(K17/J17,0) -> 0.95700468 | O17: =IFERROR(I17/G17,0) -> 0.93333333 | P17: =IFERROR((K17/I17)/(INDEX(Dim_Machine!$E$2:$E$8,MATCH(D17,Dim_Machine!$A$2:$A$8,0))*INDEX(Dim_Machine!$D$2:$D$8,MATCH(D17,Dim_Machine!$A$2:$A$8,0))),0) -> 0.95700468 | Q17: =IFERROR(M17/K17,0) -> 0.97570389 | R17: =O17*P17*Q17 -> 0.87150298 | S17: =T17/0.821 -> 8.5600487 | T17: =M17*INDEX(Dim_Product!$C$2:$C$4,MATCH(F17,Dim_Product!$A$2:$A$4,0))/1000000 -> 7.0278 | U17: =IFERROR(T17/S17,0) -> 0.821 | W17: 85000
A18: 20260701-02-M3 | B18: 20260701 | C18: 2 | D18: M3 | E18: B-PM | F18: A | G18: 60 | H18: 1.1 | I18: =G18-H18 -> 58.9 | J18: =INDEX(Dim_Machine!$E$2:$E$8,MATCH(D18,Dim_Machine!$A$2:$A$8,0))*INDEX(Dim_Machine!$D$2:$D$8,MATCH(D18,Dim_Machine!$A$2:$A$8,0))*I18 -> 15549.6 | K18: =ROUND(J18*0.929,0) -> 14446 | L18: =ROUND(K18*0.0212,0) -> 306 | M18: =K18-L18 -> 14140 | N18: =IFERROR(K18/J18,0) -> 0.92902711 | O18: =IFERROR(I18/G18,0) -> 0.98166667 | P18: =IFERROR((K18/I18)/(INDEX(Dim_Machine!$E$2:$E$8,MATCH(D18,Dim_Machine!$A$2:$A$8,0))*INDEX(Dim_Machine!$D$2:$D$8,MATCH(D18,Dim_Machine!$A$2:$A$8,0))),0) -> 0.92902711 | Q18: =IFERROR(M18/K18,0) -> 0.97881767 | R18: =O18*P18*Q18 -> 0.89267677 | S18: =T18/0.912 -> 3.8760965 | T18: =M18*INDEX(Dim_Product!$C$2:$C$4,MATCH(F18,Dim_Product!$A$2:$A$4,0))/1000000 -> 3.535 | U18: =IFERROR(T18/S18,0) -> 0.912 | W18: 4047000 | X18: 4590000
A19: 20260701-02-M4 | B19: 20260701 | C19: 2 | D19: M4 | E19: B-PM | F19: A | G19: 60 | H19: 3.4 | I19: =G19-H19 -> 56.6 | J19: =INDEX(Dim_Machine!$E$2:$E$8,MATCH(D19,Dim_Machine!$A$2:$A$8,0))*INDEX(Dim_Machine!$D$2:$D$8,MATCH(D19,Dim_Machine!$A$2:$A$8,0))*I19 -> 40752 | K19: =ROUND(J19*0.897,0) -> 36555 | L19: =ROUND(K19*0.0159,0) -> 581 | M19: =K19-L19 -> 35974 | N19: =IFERROR(K19/J19,0) -> 0.89701119 | O19: =IFERROR(I19/G19,0) -> 0.94333333 | P19: =IFERROR((K19/I19)/(INDEX(Dim_Machine!$E$2:$E$8,MATCH(D19,Dim_Machine!$A$2:$A$8,0))*INDEX(Dim_Machine!$D$2:$D$8,MATCH(D19,Dim_Machine!$A$2:$A$8,0))),0) -> 0.89701119 | Q19: =IFERROR(M19/K19,0) -> 0.98410614 | R19: =O19*P19*Q19 -> 0.83273148 | S19: =T19/0.95 -> 9.4668421 | T19: =M19*INDEX(Dim_Product!$C$2:$C$4,MATCH(F19,Dim_Product!$A$2:$A$4,0))/1000000 -> 8.9935 | U19: =IFERROR(T19/S19,0) -> 0.95 | W19: =W17/W18 -> 0.021003212
A20: 20260701-02-M5 | B20: 20260701 | C20: 2 | D20: M5 | E20: B-PM | F20: A | G20: 60 | H20: 1.1 | I20: =G20-H20 -> 58.9 | J20: =INDEX(Dim_Machine!$E$2:$E$8,MATCH(D20,Dim_Machine!$A$2:$A$8,0))*INDEX(Dim_Machine!$D$2:$D$8,MATCH(D20,Dim_Machine!$A$2:$A$8,0))*I20 -> 24502.4 | K20: =ROUND(J20*0.879,0) -> 21538 | L20: =ROUND(K20*0.0277,0) -> 597 | M20: =K20-L20 -> 20941 | N20: =IFERROR(K20/J20,0) -> 0.87901593 | O20: =IFERROR(I20/G20,0) -> 0.98166667 | P20: =IFERROR((K20/I20)/(INDEX(Dim_Machine!$E$2:$E$8,MATCH(D20,Dim_Machine!$A$2:$A$8,0))*INDEX(Dim_Machine!$D$2:$D$8,MATCH(D20,Dim_Machine!$A$2:$A$8,0))),0) -> 0.87901593 | Q20: =IFERROR(M20/K20,0) -> 0.97228155 | R20: =O20*P20*Q20 -> 0.83898237 | S20: =T20/0.929 -> 5.6353606 | T20: =M20*INDEX(Dim_Product!$C$2:$C$4,MATCH(F20,Dim_Product!$A$2:$A$4,0))/1000000 -> 5.23525 | U20: =IFERROR(T20/S20,0) -> 0.929
A21: 20260701-02-M6 | B21: 20260701 | C21: 2 | D21: M6 | E21: B-PM | F21: C | G21: 60 | H21: 1.2 | I21: =G21-H21 -> 58.8 | J21: =INDEX(Dim_Machine!$E$2:$E$8,MATCH(D21,Dim_Machine!$A$2:$A$8,0))*INDEX(Dim_Machine!$D$2:$D$8,MATCH(D21,Dim_Machine!$A$2:$A$8,0))*I21 -> 16934.4 | K21: =ROUND(J21*0.812,0) -> 13751 | L21: =ROUND(K21*0.0254,0) -> 349 | M21: =K21-L21 -> 13402 | N21: =IFERROR(K21/J21,0) -> 0.81201578 | O21: =IFERROR(I21/G21,0) -> 0.98 | P21: =IFERROR((K21/I21)/(INDEX(Dim_Machine!$E$2:$E$8,MATCH(D21,Dim_Machine!$A$2:$A$8,0))*INDEX(Dim_Machine!$D$2:$D$8,MATCH(D21,Dim_Machine!$A$2:$A$8,0))),0) -> 0.81201578 | Q21: =IFERROR(M21/K21,0) -> 0.97462003 | R21: =O21*P21*Q21 -> 0.7755787 | S21: =T21/0.889 -> 3.0150731 | T21: =M21*INDEX(Dim_Product!$C$2:$C$4,MATCH(F21,Dim_Product!$A$2:$A$4,0))/1000000 -> 2.6804 | U21: =IFERROR(T21/S21,0) -> 0.889 | W21: 4123000
A22: 20260701-02-M7 | B22: 20260701 | C22: 2 | D22: M7 | E22: B-PM | F22: A | G22: 60 | H22: 3.1 | I22: =G22-H22 -> 56.9 | J22: =INDEX(Dim_Machine!$E$2:$E$8,MATCH(D22,Dim_Machine!$A$2:$A$8,0))*INDEX(Dim_Machine!$D$2:$D$8,MATCH(D22,Dim_Machine!$A$2:$A$8,0))*I22 -> 36871.2 | K22: =ROUND(J22*0.899,0) -> 33147 | L22: =ROUND(K22*0.019,0) -> 630 | M22: =K22-L22 -> 32517 | N22: =IFERROR(K22/J22,0) -> 0.89899434 | O22: =IFERROR(I22/G22,0) -> 0.94833333 | P22: =IFERROR((K22/I22)/(INDEX(Dim_Machine!$E$2:$E$8,MATCH(D22,Dim_Machine!$A$2:$A$8,0))*INDEX(Dim_Machine!$D$2:$D$8,MATCH(D22,Dim_Machine!$A$2:$A$8,0))),0) -> 0.89899434 | Q22: =IFERROR(M22/K22,0) -> 0.98099376 | R22: =O22*P22*Q22 -> 0.83634259 | S22: =T22/0.838 -> 9.7007757 | T22: =M22*INDEX(Dim_Product!$C$2:$C$4,MATCH(F22,Dim_Product!$A$2:$A$4,0))/1000000 -> 8.12925 | U22: =IFERROR(T22/S22,0) -> 0.838 | W22: =W21/X18 -> 0.89825708
A23: 20260701-03-M1 | B23: 20260701 | C23: 3 | D23: M1 | E23: B-PM | F23: A | G23: 60 | H23: 4.4 | I23: =G23-H23 -> 55.6 | J23: =INDEX(Dim_Machine!$E$2:$E$8,MATCH(D23,Dim_Machine!$A$2:$A$8,0))*INDEX(Dim_Machine!$D$2:$D$8,MATCH(D23,Dim_Machine!$A$2:$A$8,0))*I23 -> 22240 | K23: =ROUND(J23*0.968,0) -> 21528 | L23: =ROUND(K23*0.0254,0) -> 547 | M23: =K23-L23 -> 20981 | N23: =IFERROR(K23/J23,0) -> 0.96798561 | O23: =IFERROR(I23/G23,0) -> 0.92666667 | P23: =IFERROR((K23/I23)/(INDEX(Dim_Machine!$E$2:$E$8,MATCH(D23,Dim_Machine!$A$2:$A$8,0))*INDEX(Dim_Machine!$D$2:$D$8,MATCH(D23,Dim_Machine!$A$2:$A$8,0))),0) -> 0.96798561 | Q23: =IFERROR(M23/K23,0) -> 0.97459123 | R23: =O23*P23*Q23 -> 0.87420833 | S23: =T23/0.817 -> 6.4201346 | T23: =M23*INDEX(Dim_Product!$C$2:$C$4,MATCH(F23,Dim_Product!$A$2:$A$4,0))/1000000 -> 5.24525 | U23: =IFERROR(T23/S23,0) -> 0.817 | W23: =W22*100 -> 89.825708
A24: 20260701-03-M2 | B24: 20260701 | C24: 3 | D24: M2 | E24: B-PM | F24: C | G24: 60 | H24: 7.1 | I24: =G24-H24 -> 52.9 | J24: =INDEX(Dim_Machine!$E$2:$E$8,MATCH(D24,Dim_Machine!$A$2:$A$8,0))*INDEX(Dim_Machine!$D$2:$D$8,MATCH(D24,Dim_Machine!$A$2:$A$8,0))*I24 -> 35548.8 | K24: =ROUND(J24*0.93,0) -> 33060 | L24: =ROUND(K24*0.0281,0) -> 929 | M24: =K24-L24 -> 32131 | N24: =IFERROR(K24/J24,0) -> 0.9299892 | O24: =IFERROR(I24/G24,0) -> 0.88166667 | P24: =IFERROR((K24/I24)/(INDEX(Dim_Machine!$E$2:$E$8,MATCH(D24,Dim_Machine!$A$2:$A$8,0))*INDEX(Dim_Machine!$D$2:$D$8,MATCH(D24,Dim_Machine!$A$2:$A$8,0))),0) -> 0.9299892 | Q24: =IFERROR(M24/K24,0) -> 0.97189958 | R24: =O24*P24*Q24 -> 0.7968998 | S24: =T24/0.851 -> 7.5513514 | T24: =M24*INDEX(Dim_Product!$C$2:$C$4,MATCH(F24,Dim_Product!$A$2:$A$4,0))/1000000 -> 6.4262 | U24: =IFERROR(T24/S24,0) -> 0.851
A25: 20260701-03-M3 | B25: 20260701 | C25: 3 | D25: M3 | E25: B-PM | F25: A | G25: 60 | H25: 2.3 | I25: =G25-H25 -> 57.7 | J25: =INDEX(Dim_Machine!$E$2:$E$8,MATCH(D25,Dim_Machine!$A$2:$A$8,0))*INDEX(Dim_Machine!$D$2:$D$8,MATCH(D25,Dim_Machine!$A$2:$A$8,0))*I25 -> 15232.8 | K25: =ROUND(J25*0.812,0) -> 12369 | L25: =ROUND(K25*0.0051,0) -> 63 | M25: =K25-L25 -> 12306 | N25: =IFERROR(K25/J25,0) -> 0.81199779 | O25: =IFERROR(I25/G25,0) -> 0.96166667 | P25: =IFERROR((K25/I25)/(INDEX(Dim_Machine!$E$2:$E$8,MATCH(D25,Dim_Machine!$A$2:$A$8,0))*INDEX(Dim_Machine!$D$2:$D$8,MATCH(D25,Dim_Machine!$A$2:$A$8,0))),0) -> 0.81199779 | Q25: =IFERROR(M25/K25,0) -> 0.99490662 | R25: =O25*P25*Q25 -> 0.77689394 | S25: =T25/0.908 -> 3.3882159 | T25: =M25*INDEX(Dim_Product!$C$2:$C$4,MATCH(F25,Dim_Product!$A$2:$A$4,0))/1000000 -> 3.0765 | U25: =IFERROR(T25/S25,0) -> 0.908
A26: 20260701-03-M4 | B26: 20260701 | C26: 3 | D26: M4 | E26: B-PM | F26: A | G26: 60 | H26: 5.8 | I26: =G26-H26 -> 54.2 | J26: =INDEX(Dim_Machine!$E$2:$E$8,MATCH(D26,Dim_Machine!$A$2:$A$8,0))*INDEX(Dim_Machine!$D$2:$D$8,MATCH(D26,Dim_Machine!$A$2:$A$8,0))*I26 -> 39024 | K26: =ROUND(J26*0.974,0) -> 38009 | L26: =ROUND(K26*0.0279,0) -> 1060 | M26: =K26-L26 -> 36949 | N26: =IFERROR(K26/J26,0) -> 0.97399036 | O26: =IFERROR(I26/G26,0) -> 0.90333333 | P26: =IFERROR((K26/I26)/(INDEX(Dim_Machine!$E$2:$E$8,MATCH(D26,Dim_Machine!$A$2:$A$8,0))*INDEX(Dim_Machine!$D$2:$D$8,MATCH(D26,Dim_Machine!$A$2:$A$8,0))),0) -> 0.97399036 | Q26: =IFERROR(M26/K26,0) -> 0.97211187 | R26: =O26*P26*Q26 -> 0.85530093 | S26: =T26/0.876 -> 10.544806 | T26: =M26*INDEX(Dim_Product!$C$2:$C$4,MATCH(F26,Dim_Product!$A$2:$A$4,0))/1000000 -> 9.23725 | U26: =IFERROR(T26/S26,0) -> 0.876
A27: 20260701-03-M5 | B27: 20260701 | C27: 3 | D27: M5 | E27: B-PM | F27: A | G27: 60 | H27: 0.9 | I27: =G27-H27 -> 59.1 | J27: =INDEX(Dim_Machine!$E$2:$E$8,MATCH(D27,Dim_Machine!$A$2:$A$8,0))*INDEX(Dim_Machine!$D$2:$D$8,MATCH(D27,Dim_Machine!$A$2:$A$8,0))*I27 -> 24585.6 | K27: =ROUND(J27*0.905,0) -> 22250 | L27: =ROUND(K27*0.0303,0) -> 674 | M27: =K27-L27 -> 21576 | N27: =IFERROR(K27/J27,0) -> 0.9050013 | O27: =IFERROR(I27/G27,0) -> 0.985 | P27: =IFERROR((K27/I27)/(INDEX(Dim_Machine!$E$2:$E$8,MATCH(D27,Dim_Machine!$A$2:$A$8,0))*INDEX(Dim_Machine!$D$2:$D$8,MATCH(D27,Dim_Machine!$A$2:$A$8,0))),0) -> 0.9050013 | Q27: =IFERROR(M27/K27,0) -> 0.96970787 | R27: =O27*P27*Q27 -> 0.86442308 | S27: =T27/0.876 -> 6.1575342 | T27: =M27*INDEX(Dim_Product!$C$2:$C$4,MATCH(F27,Dim_Product!$A$2:$A$4,0))/1000000 -> 5.394 | U27: =IFERROR(T27/S27,0) -> 0.876
A28: 20260701-03-M6 | B28: 20260701 | C28: 3 | D28: M6 | E28: B-PM | F28: C | G28: 60 | H28: 1.6 | I28: =G28-H28 -> 58.4 | J28: =INDEX(Dim_Machine!$E$2:$E$8,MATCH(D28,Dim_Machine!$A$2:$A$8,0))*INDEX(Dim_Machine!$D$2:$D$8,MATCH(D28,Dim_Machine!$A$2:$A$8,0))*I28 -> 16819.2 | K28: =ROUND(J28*0.855,0) -> 14380 | L28: =ROUND(K28*0.0098,0) -> 141 | M28: =K28-L28 -> 14239 | N28: =IFERROR(K28/J28,0) -> 0.85497527 | O28: =IFERROR(I28/G28,0) -> 0.97333333 | P28: =IFERROR((K28/I28)/(INDEX(Dim_Machine!$E$2:$E$8,MATCH(D28,Dim_Machine!$A$2:$A$8,0))*INDEX(Dim_Machine!$D$2:$D$8,MATCH(D28,Dim_Machine!$A$2:$A$8,0))),0) -> 0.85497527 | Q28: =IFERROR(M28/K28,0) -> 0.99019471 | R28: =O28*P28*Q28 -> 0.8240162 | S28: =T28/0.943 -> 3.0199364 | T28: =M28*INDEX(Dim_Product!$C$2:$C$4,MATCH(F28,Dim_Product!$A$2:$A$4,0))/1000000 -> 2.8478 | U28: =IFERROR(T28/S28,0) -> 0.943
A29: 20260701-03-M7 | B29: 20260701 | C29: 3 | D29: M7 | E29: B-PM | F29: A | G29: 60 | H29: 7.4 | I29: =G29-H29 -> 52.6 | J29: =INDEX(Dim_Machine!$E$2:$E$8,MATCH(D29,Dim_Machine!$A$2:$A$8,0))*INDEX(Dim_Machine!$D$2:$D$8,MATCH(D29,Dim_Machine!$A$2:$A$8,0))*I29 -> 34084.8 | K29: =ROUND(J29*0.964,0) -> 32858 | L29: =ROUND(K29*0.023,0) -> 756 | M29: =K29-L29 -> 32102 | N29: =IFERROR(K29/J29,0) -> 0.96400742 | O29: =IFERROR(I29/G29,0) -> 0.87666667 | P29: =IFERROR((K29/I29)/(INDEX(Dim_Machine!$E$2:$E$8,MATCH(D29,Dim_Machine!$A$2:$A$8,0))*INDEX(Dim_Machine!$D$2:$D$8,MATCH(D29,Dim_Machine!$A$2:$A$8,0))),0) -> 0.96400742 | Q29: =IFERROR(M29/K29,0) -> 0.9769919 | R29: =O29*P29*Q29 -> 0.82566872 | S29: =T29/0.873 -> 9.1930126 | T29: =M29*INDEX(Dim_Product!$C$2:$C$4,MATCH(F29,Dim_Product!$A$2:$A$4,0))/1000000 -> 8.0255 | U29: =IFERROR(T29/S29,0) -> 0.873
A30: 20260701-04-M1 | B30: 20260701 | C30: 4 | D30: M1 | E30: B-PM | F30: A | G30: 60 | H30: 0.9 | I30: =G30-H30 -> 59.1 | J30: =INDEX(Dim_Machine!$E$2:$E$8,MATCH(D30,Dim_Machine!$A$2:$A$8,0))*INDEX(Dim_Machine!$D$2:$D$8,MATCH(D30,Dim_Machine!$A$2:$A$8,0))*I30 -> 23640 | K30: =ROUND(J30*0.853,0) -> 20165 | L30: =ROUND(K30*0.0346,0) -> 698 | M30: =K30-L30 -> 19467 | N30: =IFERROR(K30/J30,0) -> 0.85300338 | O30: =IFERROR(I30/G30,0) -> 0.985 | P30: =IFERROR((K30/I30)/(INDEX(Dim_Machine!$E$2:$E$8,MATCH(D30,Dim_Machine!$A$2:$A$8,0))*INDEX(Dim_Machine!$D$2:$D$8,MATCH(D30,Dim_Machine!$A$2:$A$8,0))),0) -> 0.85300338 | Q30: =IFERROR(M30/K30,0) -> 0.96538557 | R30: =O30*P30*Q30 -> 0.811125 | S30: =T30/0.921 -> 5.284202 | T30: =M30*INDEX(Dim_Product!$C$2:$C$4,MATCH(F30,Dim_Product!$A$2:$A$4,0))/1000000 -> 4.86675 | U30: =IFERROR(T30/S30,0) -> 0.921
A31: 20260701-04-M2 | B31: 20260701 | C31: 4 | D31: M2 | E31: B-PM | F31: C | G31: 60 | H31: 1.9 | I31: =G31-H31 -> 58.1 | J31: =INDEX(Dim_Machine!$E$2:$E$8,MATCH(D31,Dim_Machine!$A$2:$A$8,0))*INDEX(Dim_Machine!$D$2:$D$8,MATCH(D31,Dim_Machine!$A$2:$A$8,0))*I31 -> 39043.2 | K31: =ROUND(J31*0.828,0) -> 32328 | L31: =ROUND(K31*0.022,0) -> 711 | M31: =K31-L31 -> 31617 | N31: =IFERROR(K31/J31,0) -> 0.8280059 | O31: =IFERROR(I31/G31,0) -> 0.96833333 | P31: =IFERROR((K31/I31)/(INDEX(Dim_Machine!$E$2:$E$8,MATCH(D31,Dim_Machine!$A$2:$A$8,0))*INDEX(Dim_Machine!$D$2:$D$8,MATCH(D31,Dim_Machine!$A$2:$A$8,0))),0) -> 0.8280059 | Q31: =IFERROR(M31/K31,0) -> 0.97800668 | R31: =O31*P31*Q31 -> 0.78415179 | S31: =T31/0.812 -> 7.7874384 | T31: =M31*INDEX(Dim_Product!$C$2:$C$4,MATCH(F31,Dim_Product!$A$2:$A$4,0))/1000000 -> 6.3234 | U31: =IFERROR(T31/S31,0) -> 0.812
A32: 20260701-04-M3 | B32: 20260701 | C32: 4 | D32: M3 | E32: B-PM | F32: A | G32: 60 | H32: 5.9 | I32: =G32-H32 -> 54.1 | J32: =INDEX(Dim_Machine!$E$2:$E$8,MATCH(D32,Dim_Machine!$A$2:$A$8,0))*INDEX(Dim_Machine!$D$2:$D$8,MATCH(D32,Dim_Machine!$A$2:$A$8,0))*I32 -> 14282.4 | K32: =ROUND(J32*0.943,0) -> 13468 | L32: =ROUND(K32*0.0343,0) -> 462 | M32: =K32-L32 -> 13006 | N32: =IFERROR(K32/J32,0) -> 0.94297877 | O32: =IFERROR(I32/G32,0) -> 0.90166667 | P32: =IFERROR((K32/I32)/(INDEX(Dim_Machine!$E$2:$E$8,MATCH(D32,Dim_Machine!$A$2:$A$8,0))*INDEX(Dim_Machine!$D$2:$D$8,MATCH(D32,Dim_Machine!$A$2:$A$8,0))),0) -> 0.94297877 | Q32: =IFERROR(M32/K32,0) -> 0.96569647 | R32: =O32*P32*Q32 -> 0.82108586 | S32: =T32/0.88 -> 3.6948864 | T32: =M32*INDEX(Dim_Product!$C$2:$C$4,MATCH(F32,Dim_Product!$A$2:$A$4,0))/1000000 -> 3.2515 | U32: =IFERROR(T32/S32,0) -> 0.88
A33: 20260701-04-M4 | B33: 20260701 | C33: 4 | D33: M4 | E33: B-PM | F33: A | G33: 60 | H33: 1 | I33: =G33-H33 -> 59 | J33: =INDEX(Dim_Machine!$E$2:$E$8,MATCH(D33,Dim_Machine!$A$2:$A$8,0))*INDEX(Dim_Machine!$D$2:$D$8,MATCH(D33,Dim_Machine!$A$2:$A$8,0))*I33 -> 42480 | K33: =ROUND(J33*0.912,0) -> 38742 | L33: =ROUND(K33*0.0334,0) -> 1294 | M33: =K33-L33 -> 37448 | N33: =IFERROR(K33/J33,0) -> 0.91200565 | O33: =IFERROR(I33/G33,0) -> 0.98333333 | P33: =IFERROR((K33/I33)/(INDEX(Dim_Machine!$E$2:$E$8,MATCH(D33,Dim_Machine!$A$2:$A$8,0))*INDEX(Dim_Machine!$D$2:$D$8,MATCH(D33,Dim_Machine!$A$2:$A$8,0))),0) -> 0.91200565 | Q33: =IFERROR(M33/K33,0) -> 0.96659956 | R33: =O33*P33*Q33 -> 0.86685185 | S33: =T33/0.825 -> 11.347879 | T33: =M33*INDEX(Dim_Product!$C$2:$C$4,MATCH(F33,Dim_Product!$A$2:$A$4,0))/1000000 -> 9.362 | U33: =IFERROR(T33/S33,0) -> 0.825
A34: 20260701-04-M5 | B34: 20260701 | C34: 4 | D34: M5 | E34: B-PM | F34: A | G34: 60 | H34: 4.2 | I34: =G34-H34 -> 55.8 | J34: =INDEX(Dim_Machine!$E$2:$E$8,MATCH(D34,Dim_Machine!$A$2:$A$8,0))*INDEX(Dim_Machine!$D$2:$D$8,MATCH(D34,Dim_Machine!$A$2:$A$8,0))*I34 -> 23212.8 | K34: =ROUND(J34*0.901,0) -> 20915 | L34: =ROUND(K34*0.0339,0) -> 709 | M34: =K34-L34 -> 20206 | N34: =IFERROR(K34/J34,0) -> 0.90101151 | O34: =IFERROR(I34/G34,0) -> 0.93 | P34: =IFERROR((K34/I34)/(INDEX(Dim_Machine!$E$2:$E$8,MATCH(D34,Dim_Machine!$A$2:$A$8,0))*INDEX(Dim_Machine!$D$2:$D$8,MATCH(D34,Dim_Machine!$A$2:$A$8,0))),0) -> 0.90101151 | Q34: =IFERROR(M34/K34,0) -> 0.96610088 | R34: =O34*P34*Q34 -> 0.80953526 | S34: =T34/0.939 -> 5.3796592 | T34: =M34*INDEX(Dim_Product!$C$2:$C$4,MATCH(F34,Dim_Product!$A$2:$A$4,0))/1000000 -> 5.0515 | U34: =IFERROR(T34/S34,0) -> 0.939
A35: 20260701-04-M6 | B35: 20260701 | C35: 4 | D35: M6 | E35: B-PM | F35: C | G35: 60 | H35: 6 | I35: =G35-H35 -> 54 | J35: =INDEX(Dim_Machine!$E$2:$E$8,MATCH(D35,Dim_Machine!$A$2:$A$8,0))*INDEX(Dim_Machine!$D$2:$D$8,MATCH(D35,Dim_Machine!$A$2:$A$8,0))*I35 -> 15552 | K35: =ROUND(J35*0.918,0) -> 14277 | L35: =ROUND(K35*0.0264,0) -> 377 | M35: =K35-L35 -> 13900 | N35: =IFERROR(K35/J35,0) -> 0.91801698 | O35: =IFERROR(I35/G35,0) -> 0.9 | P35: =IFERROR((K35/I35)/(INDEX(Dim_Machine!$E$2:$E$8,MATCH(D35,Dim_Machine!$A$2:$A$8,0))*INDEX(Dim_Machine!$D$2:$D$8,MATCH(D35,Dim_Machine!$A$2:$A$8,0))),0) -> 0.91801698 | Q35: =IFERROR(M35/K35,0) -> 0.97359389 | R35: =O35*P35*Q35 -> 0.80439815 | S35: =T35/0.86 -> 3.2325581 | T35: =M35*INDEX(Dim_Product!$C$2:$C$4,MATCH(F35,Dim_Product!$A$2:$A$4,0))/1000000 -> 2.78 | U35: =IFERROR(T35/S35,0) -> 0.86
A36: 20260701-04-M7 | B36: 20260701 | C36: 4 | D36: M7 | E36: B-PM | F36: A | G36: 60 | H36: 5.4 | I36: =G36-H36 -> 54.6 | J36: =INDEX(Dim_Machine!$E$2:$E$8,MATCH(D36,Dim_Machine!$A$2:$A$8,0))*INDEX(Dim_Machine!$D$2:$D$8,MATCH(D36,Dim_Machine!$A$2:$A$8,0))*I36 -> 35380.8 | K36: =ROUND(J36*0.855,0) -> 30251 | L36: =ROUND(K36*0.032,0) -> 968 | M36: =K36-L36 -> 29283 | N36: =IFERROR(K36/J36,0) -> 0.85501176 | O36: =IFERROR(I36/G36,0) -> 0.91 | P36: =IFERROR((K36/I36)/(INDEX(Dim_Machine!$E$2:$E$8,MATCH(D36,Dim_Machine!$A$2:$A$8,0))*INDEX(Dim_Machine!$D$2:$D$8,MATCH(D36,Dim_Machine!$A$2:$A$8,0))),0) -> 0.85501176 | Q36: =IFERROR(M36/K36,0) -> 0.96800106 | R36: =O36*P36*Q36 -> 0.75316358 | S36: =T36/0.868 -> 8.4340438 | T36: =M36*INDEX(Dim_Product!$C$2:$C$4,MATCH(F36,Dim_Product!$A$2:$A$4,0))/1000000 -> 7.32075 | U36: =IFERROR(T36/S36,0) -> 0.868
A37: 20260701-05-M1 | B37: 20260701 | C37: 5 | D37: M1 | E37: B-PM | F37: A | G37: 60 | H37: 2 | I37: =G37-H37 -> 58 | J37: =INDEX(Dim_Machine!$E$2:$E$8,MATCH(D37,Dim_Machine!$A$2:$A$8,0))*INDEX(Dim_Machine!$D$2:$D$8,MATCH(D37,Dim_Machine!$A$2:$A$8,0))*I37 -> 23200 | K37: =ROUND(J37*0.793,0) -> 18398 | L37: =ROUND(K37*0.0056,0) -> 103 | M37: =K37-L37 -> 18295 | N37: =IFERROR(K37/J37,0) -> 0.79301724 | O37: =IFERROR(I37/G37,0) -> 0.96666667 | P37: =IFERROR((K37/I37)/(INDEX(Dim_Machine!$E$2:$E$8,MATCH(D37,Dim_Machine!$A$2:$A$8,0))*INDEX(Dim_Machine!$D$2:$D$8,MATCH(D37,Dim_Machine!$A$2:$A$8,0))),0) -> 0.79301724 | Q37: =IFERROR(M37/K37,0) -> 0.99440157 | R37: =O37*P37*Q37 -> 0.76229167 | S37: =T37/0.883 -> 5.1797848 | T37: =M37*INDEX(Dim_Product!$C$2:$C$4,MATCH(F37,Dim_Product!$A$2:$A$4,0))/1000000 -> 4.57375 | U37: =IFERROR(T37/S37,0) -> 0.883
A38: 20260701-05-M2 | B38: 20260701 | C38: 5 | D38: M2 | E38: B-PM | F38: C | G38: 60 | H38: 4.7 | I38: =G38-H38 -> 55.3 | J38: =INDEX(Dim_Machine!$E$2:$E$8,MATCH(D38,Dim_Machine!$A$2:$A$8,0))*INDEX(Dim_Machine!$D$2:$D$8,MATCH(D38,Dim_Machine!$A$2:$A$8,0))*I38 -> 37161.6 | K38: =ROUND(J38*0.781,0) -> 29023 | L38: =ROUND(K38*0.0262,0) -> 760 | M38: =K38-L38 -> 28263 | N38: =IFERROR(K38/J38,0) -> 0.78099436 | O38: =IFERROR(I38/G38,0) -> 0.92166667 | P38: =IFERROR((K38/I38)/(INDEX(Dim_Machine!$E$2:$E$8,MATCH(D38,Dim_Machine!$A$2:$A$8,0))*INDEX(Dim_Machine!$D$2:$D$8,MATCH(D38,Dim_Machine!$A$2:$A$8,0))),0) -> 0.78099436 | Q38: =IFERROR(M38/K38,0) -> 0.97381387 | R38: =O38*P38*Q38 -> 0.70096726 | S38: =T38/0.809 -> 6.9871446 | T38: =M38*INDEX(Dim_Product!$C$2:$C$4,MATCH(F38,Dim_Product!$A$2:$A$4,0))/1000000 -> 5.6526 | U38: =IFERROR(T38/S38,0) -> 0.809
A39: 20260701-05-M3 | B39: 20260701 | C39: 5 | D39: M3 | E39: B-PM | F39: A | G39: 60 | H39: 0.5 | I39: =G39-H39 -> 59.5 | J39: =INDEX(Dim_Machine!$E$2:$E$8,MATCH(D39,Dim_Machine!$A$2:$A$8,0))*INDEX(Dim_Machine!$D$2:$D$8,MATCH(D39,Dim_Machine!$A$2:$A$8,0))*I39 -> 15708 | K39: =ROUND(J39*0.786,0) -> 12346 | L39: =ROUND(K39*0.0149,0) -> 184 | M39: =K39-L39 -> 12162 | N39: =IFERROR(K39/J39,0) -> 0.78596893 | O39: =IFERROR(I39/G39,0) -> 0.99166667 | P39: =IFERROR((K39/I39)/(INDEX(Dim_Machine!$E$2:$E$8,MATCH(D39,Dim_Machine!$A$2:$A$8,0))*INDEX(Dim_Machine!$D$2:$D$8,MATCH(D39,Dim_Machine!$A$2:$A$8,0))),0) -> 0.78596893 | Q39: =IFERROR(M39/K39,0) -> 0.98509639 | R39: =O39*P39*Q39 -> 0.76780303 | S39: =T39/0.877 -> 3.4669327 | T39: =M39*INDEX(Dim_Product!$C$2:$C$4,MATCH(F39,Dim_Product!$A$2:$A$4,0))/1000000 -> 3.0405 | U39: =IFERROR(T39/S39,0) -> 0.877
A40: 20260701-05-M4 | B40: 20260701 | C40: 5 | D40: M4 | E40: B-PM | F40: A | G40: 60 | H40: 2.2 | I40: =G40-H40 -> 57.8 | J40: =INDEX(Dim_Machine!$E$2:$E$8,MATCH(D40,Dim_Machine!$A$2:$A$8,0))*INDEX(Dim_Machine!$D$2:$D$8,MATCH(D40,Dim_Machine!$A$2:$A$8,0))*I40 -> 41616 | K40: =ROUND(J40*0.877,0) -> 36497 | L40: =ROUND(K40*0.0212,0) -> 774 | M40: =K40-L40 -> 35723 | N40: =IFERROR(K40/J40,0) -> 0.87699443 | O40: =IFERROR(I40/G40,0) -> 0.96333333 | P40: =IFERROR((K40/I40)/(INDEX(Dim_Machine!$E$2:$E$8,MATCH(D40,Dim_Machine!$A$2:$A$8,0))*INDEX(Dim_Machine!$D$2:$D$8,MATCH(D40,Dim_Machine!$A$2:$A$8,0))),0) -> 0.87699443 | Q40: =IFERROR(M40/K40,0) -> 0.97879278 | R40: =O40*P40*Q40 -> 0.8269213 | S40: =T40/0.909 -> 9.8248075 | T40: =M40*INDEX(Dim_Product!$C$2:$C$4,MATCH(F40,Dim_Product!$A$2:$A$4,0))/1000000 -> 8.93075 | U40: =IFERROR(T40/S40,0) -> 0.909
...

Sheet Fact_Quality_Sampling
A1: SampleKey (PK) | B1: DateKey (FK) | C1: HourKey (FK) | D1: MachineKey (FK) | E1: ShiftKey (FK) | F1: ProductKey (FK) | G1: SampleSize | H1: DefectiveCount | I1: CriticalCount | J1: MajorCount | K1: MinorCount | L1: TopDefectCode (FK) | M1: AvgWeight_g | N1: WeightOK_Count | O1: WeightNotOK_Count | P1: AvgDiameter_mm | Q1: DiameterOK_Count | R1: DiameterNotOK_Count | S1: AvgHeight_mm | T1: HeightOK_Count | U1: HeightNotOK_Count | V1: DefectRatePct | W1: FPY_Pct
A2: QS-1 | B2: =Fact_Production_Hourly!B2 -> 20260701 | C2: =Fact_Production_Hourly!C2 -> 0 | D2: =Fact_Production_Hourly!D2 -> M1 | E2: =Fact_Production_Hourly!E2 -> B-PM | F2: =Fact_Production_Hourly!F2 -> A | G2: =INDEX(Dim_Machine!$D$2:$D$8,MATCH(D2,Dim_Machine!$A$2:$A$8,0))*2 -> 32 | H2: =ROUND(G2*0.0323,0) -> 1 | I2: =ROUND(H2*0.15,0) -> 0 | J2: =ROUND(H2*0.45,0) -> 0 | K2: =MAX(H2-I2-J2,0) -> 1 | L2: D01 | M2: =INDEX(Dim_Product!$C$2:$C$4,MATCH(F2,Dim_Product!$A$2:$A$4,0))+0.42 -> 250.42 | N2: =IF(AND(M2>=INDEX(Dim_Product!$C$2:$C$4,MATCH(F2,Dim_Product!$A$2:$A$4,0))-INDEX(Dim_Product!$D$2:$D$4,MATCH(F2,Dim_Product!$A$2:$A$4,0)),M2<=INDEX(Dim_Product!$C$2:$C$4,MATCH(F2,Dim_Product!$A$2:$A$4,0))+INDEX(Dim_Product!$D$2:$D$4,MATCH(F2,Dim_Product!$A$2:$A$4,0))),G2-H2,G2-H2-1) -> 31 | O2: =G2-N2 -> 1 | P2: =INDEX(Dim_Product!$G$2:$G$4,MATCH(F2,Dim_Product!$A$2:$A$4,0))+0.01 -> 70.01 | Q2: =IF(AND(P2>=INDEX(Dim_Product!$G$2:$G$4,MATCH(F2,Dim_Product!$A$2:$A$4,0))-INDEX(Dim_Product!$H$2:$H$4,MATCH(F2,Dim_Product!$A$2:$A$4,0)),P2<=INDEX(Dim_Product!$G$2:$G$4,MATCH(F2,Dim_Product!$A$2:$A$4,0))+INDEX(Dim_Product!$H$2:$H$4,MATCH(F2,Dim_Product!$A$2:$A$4,0))),G2-H2,G2-H2-1) -> 31 | R2: =G2-Q2 -> 1 | S2: =INDEX(Dim_Product!$K$2:$K$4,MATCH(F2,Dim_Product!$A$2:$A$4,0))+-0.3 -> 119.7 | T2: =IF(AND(S2>=INDEX(Dim_Product!$K$2:$K$4,MATCH(F2,Dim_Product!$A$2:$A$4,0))-INDEX(Dim_Product!$L$2:$L$4,MATCH(F2,Dim_Product!$A$2:$A$4,0)),S2<=INDEX(Dim_Product!$K$2:$K$4,MATCH(F2,Dim_Product!$A$2:$A$4,0))+INDEX(Dim_Product!$L$2:$L$4,MATCH(F2,Dim_Product!$A$2:$A$4,0))),G2-H2,G2-H2-1) -> 31 | U2: =G2-T2 -> 1 | V2: =IFERROR(H2/G2,0) -> 0.03125 | W2: =1-V2 -> 0.96875
A3: QS-2 | B3: =Fact_Production_Hourly!B3 -> 20260701 | C3: =Fact_Production_Hourly!C3 -> 0 | D3: =Fact_Production_Hourly!D3 -> M2 | E3: =Fact_Production_Hourly!E3 -> B-PM | F3: =Fact_Production_Hourly!F3 -> C | G3: =INDEX(Dim_Machine!$D$2:$D$8,MATCH(D3,Dim_Machine!$A$2:$A$8,0))*2 -> 48 | H3: =ROUND(G3*0.015,0) -> 1 | I3: =ROUND(H3*0.15,0) -> 0 | J3: =ROUND(H3*0.45,0) -> 0 | K3: =MAX(H3-I3-J3,0) -> 1 | L3: D02 | M3: =INDEX(Dim_Product!$C$2:$C$4,MATCH(F3,Dim_Product!$A$2:$A$4,0))+-0.45 -> 199.55 | N3: =IF(AND(M3>=INDEX(Dim_Product!$C$2:$C$4,MATCH(F3,Dim_Product!$A$2:$A$4,0))-INDEX(Dim_Product!$D$2:$D$4,MATCH(F3,Dim_Product!$A$2:$A$4,0)),M3<=INDEX(Dim_Product!$C$2:$C$4,MATCH(F3,Dim_Product!$A$2:$A$4,0))+INDEX(Dim_Product!$D$2:$D$4,MATCH(F3,Dim_Product!$A$2:$A$4,0))),G3-H3,G3-H3-1) -> 47 | O3: =G3-N3 -> 1 | P3: =INDEX(Dim_Product!$G$2:$G$4,MATCH(F3,Dim_Product!$A$2:$A$4,0))+0.24 -> 65.24 | Q3: =IF(AND(P3>=INDEX(Dim_Product!$G$2:$G$4,MATCH(F3,Dim_Product!$A$2:$A$4,0))-INDEX(Dim_Product!$H$2:$H$4,MATCH(F3,Dim_Product!$A$2:$A$4,0)),P3<=INDEX(Dim_Product!$G$2:$G$4,MATCH(F3,Dim_Product!$A$2:$A$4,0))+INDEX(Dim_Product!$H$2:$H$4,MATCH(F3,Dim_Product!$A$2:$A$4,0))),G3-H3,G3-H3-1) -> 47 | R3: =G3-Q3 -> 1 | S3: =INDEX(Dim_Product!$K$2:$K$4,MATCH(F3,Dim_Product!$A$2:$A$4,0))+-0.28 -> 109.72 | T3: =IF(AND(S3>=INDEX(Dim_Product!$K$2:$K$4,MATCH(F3,Dim_Product!$A$2:$A$4,0))-INDEX(Dim_Product!$L$2:$L$4,MATCH(F3,Dim_Product!$A$2:$A$4,0)),S3<=INDEX(Dim_Product!$K$2:$K$4,MATCH(F3,Dim_Product!$A$2:$A$4,0))+INDEX(Dim_Product!$L$2:$L$4,MATCH(F3,Dim_Product!$A$2:$A$4,0))),G3-H3,G3-H3-1) -> 47 | U3: =G3-T3 -> 1 | V3: =IFERROR(H3/G3,0) -> 0.020833333 | W3: =1-V3 -> 0.97916667
A4: QS-3 | B4: =Fact_Production_Hourly!B4 -> 20260701 | C4: =Fact_Production_Hourly!C4 -> 0 | D4: =Fact_Production_Hourly!D4 -> M3 | E4: =Fact_Production_Hourly!E4 -> B-PM | F4: =Fact_Production_Hourly!F4 -> A | G4: =INDEX(Dim_Machine!$D$2:$D$8,MATCH(D4,Dim_Machine!$A$2:$A$8,0))*2 -> 24 | H4: =ROUND(G4*0.0362,0) -> 1 | I4: =ROUND(H4*0.15,0) -> 0 | J4: =ROUND(H4*0.45,0) -> 0 | K4: =MAX(H4-I4-J4,0) -> 1 | L4: D02 | M4: =INDEX(Dim_Product!$C$2:$C$4,MATCH(F4,Dim_Product!$A$2:$A$4,0))+0.63 -> 250.63 | N4: =IF(AND(M4>=INDEX(Dim_Product!$C$2:$C$4,MATCH(F4,Dim_Product!$A$2:$A$4,0))-INDEX(Dim_Product!$D$2:$D$4,MATCH(F4,Dim_Product!$A$2:$A$4,0)),M4<=INDEX(Dim_Product!$C$2:$C$4,MATCH(F4,Dim_Product!$A$2:$A$4,0))+INDEX(Dim_Product!$D$2:$D$4,MATCH(F4,Dim_Product!$A$2:$A$4,0))),G4-H4,G4-H4-1) -> 23 | O4: =G4-N4 -> 1 | P4: =INDEX(Dim_Product!$G$2:$G$4,MATCH(F4,Dim_Product!$A$2:$A$4,0))+0.23 -> 70.23 | Q4: =IF(AND(P4>=INDEX(Dim_Product!$G$2:$G$4,MATCH(F4,Dim_Product!$A$2:$A$4,0))-INDEX(Dim_Product!$H$2:$H$4,MATCH(F4,Dim_Product!$A$2:$A$4,0)),P4<=INDEX(Dim_Product!$G$2:$G$4,MATCH(F4,Dim_Product!$A$2:$A$4,0))+INDEX(Dim_Product!$H$2:$H$4,MATCH(F4,Dim_Product!$A$2:$A$4,0))),G4-H4,G4-H4-1) -> 23 | R4: =G4-Q4 -> 1 | S4: =INDEX(Dim_Product!$K$2:$K$4,MATCH(F4,Dim_Product!$A$2:$A$4,0))+0.34 -> 120.34 | T4: =IF(AND(S4>=INDEX(Dim_Product!$K$2:$K$4,MATCH(F4,Dim_Product!$A$2:$A$4,0))-INDEX(Dim_Product!$L$2:$L$4,MATCH(F4,Dim_Product!$A$2:$A$4,0)),S4<=INDEX(Dim_Product!$K$2:$K$4,MATCH(F4,Dim_Product!$A$2:$A$4,0))+INDEX(Dim_Product!$L$2:$L$4,MATCH(F4,Dim_Product!$A$2:$A$4,0))),G4-H4,G4-H4-1) -> 23 | U4: =G4-T4 -> 1 | V4: =IFERROR(H4/G4,0) -> 0.041666667 | W4: =1-V4 -> 0.95833333
A5: QS-4 | B5: =Fact_Production_Hourly!B5 -> 20260701 | C5: =Fact_Production_Hourly!C5 -> 0 | D5: =Fact_Production_Hourly!D5 -> M4 | E5: =Fact_Production_Hourly!E5 -> B-PM | F5: =Fact_Production_Hourly!F5 -> A | G5: =INDEX(Dim_Machine!$D$2:$D$8,MATCH(D5,Dim_Machine!$A$2:$A$8,0))*2 -> 48 | H5: =ROUND(G5*0.0349,0) -> 2 | I5: =ROUND(H5*0.15,0) -> 0 | J5: =ROUND(H5*0.45,0) -> 1 | K5: =MAX(H5-I5-J5,0) -> 1 | L5: D04 | M5: =INDEX(Dim_Product!$C$2:$C$4,MATCH(F5,Dim_Product!$A$2:$A$4,0))+0 -> 250 | N5: =IF(AND(M5>=INDEX(Dim_Product!$C$2:$C$4,MATCH(F5,Dim_Product!$A$2:$A$4,0))-INDEX(Dim_Product!$D$2:$D$4,MATCH(F5,Dim_Product!$A$2:$A$4,0)),M5<=INDEX(Dim_Product!$C$2:$C$4,MATCH(F5,Dim_Product!$A$2:$A$4,0))+INDEX(Dim_Product!$D$2:$D$4,MATCH(F5,Dim_Product!$A$2:$A$4,0))),G5-H5,G5-H5-1) -> 46 | O5: =G5-N5 -> 2 | P5: =INDEX(Dim_Product!$G$2:$G$4,MATCH(F5,Dim_Product!$A$2:$A$4,0))+-0.16 -> 69.84 | Q5: =IF(AND(P5>=INDEX(Dim_Product!$G$2:$G$4,MATCH(F5,Dim_Product!$A$2:$A$4,0))-INDEX(Dim_Product!$H$2:$H$4,MATCH(F5,Dim_Product!$A$2:$A$4,0)),P5<=INDEX(Dim_Product!$G$2:$G$4,MATCH(F5,Dim_Product!$A$2:$A$4,0))+INDEX(Dim_Product!$H$2:$H$4,MATCH(F5,Dim_Product!$A$2:$A$4,0))),G5-H5,G5-H5-1) -> 46 | R5: =G5-Q5 -> 2 | S5: =INDEX(Dim_Product!$K$2:$K$4,MATCH(F5,Dim_Product!$A$2:$A$4,0))+0.4 -> 120.4 | T5: =IF(AND(S5>=INDEX(Dim_Product!$K$2:$K$4,MATCH(F5,Dim_Product!$A$2:$A$4,0))-INDEX(Dim_Product!$L$2:$L$4,MATCH(F5,Dim_Product!$A$2:$A$4,0)),S5<=INDEX(Dim_Product!$K$2:$K$4,MATCH(F5,Dim_Product!$A$2:$A$4,0))+INDEX(Dim_Product!$L$2:$L$4,MATCH(F5,Dim_Product!$A$2:$A$4,0))),G5-H5,G5-H5-1) -> 46 | U5: =G5-T5 -> 2 | V5: =IFERROR(H5/G5,0) -> 0.041666667 | W5: =1-V5 -> 0.95833333
A6: QS-5 | B6: =Fact_Production_Hourly!B6 -> 20260701 | C6: =Fact_Production_Hourly!C6 -> 0 | D6: =Fact_Production_Hourly!D6 -> M5 | E6: =Fact_Production_Hourly!E6 -> B-PM | F6: =Fact_Production_Hourly!F6 -> A | G6: =INDEX(Dim_Machine!$D$2:$D$8,MATCH(D6,Dim_Machine!$A$2:$A$8,0))*2 -> 32 | H6: =ROUND(G6*0.0325,0) -> 1 | I6: =ROUND(H6*0.15,0) -> 0 | J6: =ROUND(H6*0.45,0) -> 0 | K6: =MAX(H6-I6-J6,0) -> 1 | L6: D01 | M6: =INDEX(Dim_Product!$C$2:$C$4,MATCH(F6,Dim_Product!$A$2:$A$4,0))+-0.36 -> 249.64 | N6: =IF(AND(M6>=INDEX(Dim_Product!$C$2:$C$4,MATCH(F6,Dim_Product!$A$2:$A$4,0))-INDEX(Dim_Product!$D$2:$D$4,MATCH(F6,Dim_Product!$A$2:$A$4,0)),M6<=INDEX(Dim_Product!$C$2:$C$4,MATCH(F6,Dim_Product!$A$2:$A$4,0))+INDEX(Dim_Product!$D$2:$D$4,MATCH(F6,Dim_Product!$A$2:$A$4,0))),G6-H6,G6-H6-1) -> 31 | O6: =G6-N6 -> 1 | P6: =INDEX(Dim_Product!$G$2:$G$4,MATCH(F6,Dim_Product!$A$2:$A$4,0))+-0.24 -> 69.76 | Q6: =IF(AND(P6>=INDEX(Dim_Product!$G$2:$G$4,MATCH(F6,Dim_Product!$A$2:$A$4,0))-INDEX(Dim_Product!$H$2:$H$4,MATCH(F6,Dim_Product!$A$2:$A$4,0)),P6<=INDEX(Dim_Product!$G$2:$G$4,MATCH(F6,Dim_Product!$A$2:$A$4,0))+INDEX(Dim_Product!$H$2:$H$4,MATCH(F6,Dim_Product!$A$2:$A$4,0))),G6-H6,G6-H6-1) -> 31 | R6: =G6-Q6 -> 1 | S6: =INDEX(Dim_Product!$K$2:$K$4,MATCH(F6,Dim_Product!$A$2:$A$4,0))+0.17 -> 120.17 | T6: =IF(AND(S6>=INDEX(Dim_Product!$K$2:$K$4,MATCH(F6,Dim_Product!$A$2:$A$4,0))-INDEX(Dim_Product!$L$2:$L$4,MATCH(F6,Dim_Product!$A$2:$A$4,0)),S6<=INDEX(Dim_Product!$K$2:$K$4,MATCH(F6,Dim_Product!$A$2:$A$4,0))+INDEX(Dim_Product!$L$2:$L$4,MATCH(F6,Dim_Product!$A$2:$A$4,0))),G6-H6,G6-H6-1) -> 31 | U6: =G6-T6 -> 1 | V6: =IFERROR(H6/G6,0) -> 0.03125 | W6: =1-V6 -> 0.96875
A7: QS-6 | B7: =Fact_Production_Hourly!B7 -> 20260701 | C7: =Fact_Production_Hourly!C7 -> 0 | D7: =Fact_Production_Hourly!D7 -> M6 | E7: =Fact_Production_Hourly!E7 -> B-PM | F7: =Fact_Production_Hourly!F7 -> C | G7: =INDEX(Dim_Machine!$D$2:$D$8,MATCH(D7,Dim_Machine!$A$2:$A$8,0))*2 -> 24 | H7: =ROUND(G7*0.0301,0) -> 1 | I7: =ROUND(H7*0.15,0) -> 0 | J7: =ROUND(H7*0.45,0) -> 0 | K7: =MAX(H7-I7-J7,0) -> 1 | L7: D02 | M7: =INDEX(Dim_Product!$C$2:$C$4,MATCH(F7,Dim_Product!$A$2:$A$4,0))+-0.72 -> 199.28 | N7: =IF(AND(M7>=INDEX(Dim_Product!$C$2:$C$4,MATCH(F7,Dim_Product!$A$2:$A$4,0))-INDEX(Dim_Product!$D$2:$D$4,MATCH(F7,Dim_Product!$A$2:$A$4,0)),M7<=INDEX(Dim_Product!$C$2:$C$4,MATCH(F7,Dim_Product!$A$2:$A$4,0))+INDEX(Dim_Product!$D$2:$D$4,MATCH(F7,Dim_Product!$A$2:$A$4,0))),G7-H7,G7-H7-1) -> 23 | O7: =G7-N7 -> 1 | P7: =INDEX(Dim_Product!$G$2:$G$4,MATCH(F7,Dim_Product!$A$2:$A$4,0))+-0.13 -> 64.87 | Q7: =IF(AND(P7>=INDEX(Dim_Product!$G$2:$G$4,MATCH(F7,Dim_Product!$A$2:$A$4,0))-INDEX(Dim_Product!$H$2:$H$4,MATCH(F7,Dim_Product!$A$2:$A$4,0)),P7<=INDEX(Dim_Product!$G$2:$G$4,MATCH(F7,Dim_Product!$A$2:$A$4,0))+INDEX(Dim_Product!$H$2:$H$4,MATCH(F7,Dim_Product!$A$2:$A$4,0))),G7-H7,G7-H7-1) -> 23 | R7: =G7-Q7 -> 1 | S7: =INDEX(Dim_Product!$K$2:$K$4,MATCH(F7,Dim_Product!$A$2:$A$4,0))+0.26 -> 110.26 | T7: =IF(AND(S7>=INDEX(Dim_Product!$K$2:$K$4,MATCH(F7,Dim_Product!$A$2:$A$4,0))-INDEX(Dim_Product!$L$2:$L$4,MATCH(F7,Dim_Product!$A$2:$A$4,0)),S7<=INDEX(Dim_Product!$K$2:$K$4,MATCH(F7,Dim_Product!$A$2:$A$4,0))+INDEX(Dim_Product!$L$2:$L$4,MATCH(F7,Dim_Product!$A$2:$A$4,0))),G7-H7,G7-H7-1) -> 23 | U7: =G7-T7 -> 1 | V7: =IFERROR(H7/G7,0) -> 0.041666667 | W7: =1-V7 -> 0.95833333
A8: QS-7 | B8: =Fact_Production_Hourly!B8 -> 20260701 | C8: =Fact_Production_Hourly!C8 -> 0 | D8: =Fact_Production_Hourly!D8 -> M7 | E8: =Fact_Production_Hourly!E8 -> B-PM | F8: =Fact_Production_Hourly!F8 -> A | G8: =INDEX(Dim_Machine!$D$2:$D$8,MATCH(D8,Dim_Machine!$A$2:$A$8,0))*2 -> 48 | H8: =ROUND(G8*0.0518,0) -> 2 | I8: =ROUND(H8*0.15,0) -> 0 | J8: =ROUND(H8*0.45,0) -> 1 | K8: =MAX(H8-I8-J8,0) -> 1 | L8: D02 | M8: =INDEX(Dim_Product!$C$2:$C$4,MATCH(F8,Dim_Product!$A$2:$A$4,0))+0.52 -> 250.52 | N8: =IF(AND(M8>=INDEX(Dim_Product!$C$2:$C$4,MATCH(F8,Dim_Product!$A$2:$A$4,0))-INDEX(Dim_Product!$D$2:$D$4,MATCH(F8,Dim_Product!$A$2:$A$4,0)),M8<=INDEX(Dim_Product!$C$2:$C$4,MATCH(F8,Dim_Product!$A$2:$A$4,0))+INDEX(Dim_Product!$D$2:$D$4,MATCH(F8,Dim_Product!$A$2:$A$4,0))),G8-H8,G8-H8-1) -> 46 | O8: =G8-N8 -> 2 | P8: =INDEX(Dim_Product!$G$2:$G$4,MATCH(F8,Dim_Product!$A$2:$A$4,0))+-0.02 -> 69.98 | Q8: =IF(AND(P8>=INDEX(Dim_Product!$G$2:$G$4,MATCH(F8,Dim_Product!$A$2:$A$4,0))-INDEX(Dim_Product!$H$2:$H$4,MATCH(F8,Dim_Product!$A$2:$A$4,0)),P8<=INDEX(Dim_Product!$G$2:$G$4,MATCH(F8,Dim_Product!$A$2:$A$4,0))+INDEX(Dim_Product!$H$2:$H$4,MATCH(F8,Dim_Product!$A$2:$A$4,0))),G8-H8,G8-H8-1) -> 46 | R8: =G8-Q8 -> 2 | S8: =INDEX(Dim_Product!$K$2:$K$4,MATCH(F8,Dim_Product!$A$2:$A$4,0))+0.09 -> 120.09 | T8: =IF(AND(S8>=INDEX(Dim_Product!$K$2:$K$4,MATCH(F8,Dim_Product!$A$2:$A$4,0))-INDEX(Dim_Product!$L$2:$L$4,MATCH(F8,Dim_Product!$A$2:$A$4,0)),S8<=INDEX(Dim_Product!$K$2:$K$4,MATCH(F8,Dim_Product!$A$2:$A$4,0))+INDEX(Dim_Product!$L$2:$L$4,MATCH(F8,Dim_Product!$A$2:$A$4,0))),G8-H8,G8-H8-1) -> 46 | U8: =G8-T8 -> 2 | V8: =IFERROR(H8/G8,0) -> 0.041666667 | W8: =1-V8 -> 0.95833333
A9: QS-8 | B9: =Fact_Production_Hourly!B9 -> 20260701 | C9: =Fact_Production_Hourly!C9 -> 1 | D9: =Fact_Production_Hourly!D9 -> M1 | E9: =Fact_Production_Hourly!E9 -> B-PM | F9: =Fact_Production_Hourly!F9 -> A | G9: =INDEX(Dim_Machine!$D$2:$D$8,MATCH(D9,Dim_Machine!$A$2:$A$8,0))*2 -> 32 | H9: =ROUND(G9*0.0644,0) -> 2 | I9: =ROUND(H9*0.15,0) -> 0 | J9: =ROUND(H9*0.45,0) -> 1 | K9: =MAX(H9-I9-J9,0) -> 1 | L9: D01 | M9: =INDEX(Dim_Product!$C$2:$C$4,MATCH(F9,Dim_Product!$A$2:$A$4,0))+-0.49 -> 249.51 | N9: =IF(AND(M9>=INDEX(Dim_Product!$C$2:$C$4,MATCH(F9,Dim_Product!$A$2:$A$4,0))-INDEX(Dim_Product!$D$2:$D$4,MATCH(F9,Dim_Product!$A$2:$A$4,0)),M9<=INDEX(Dim_Product!$C$2:$C$4,MATCH(F9,Dim_Product!$A$2:$A$4,0))+INDEX(Dim_Product!$D$2:$D$4,MATCH(F9,Dim_Product!$A$2:$A$4,0))),G9-H9,G9-H9-1) -> 30 | O9: =G9-N9 -> 2 | P9: =INDEX(Dim_Product!$G$2:$G$4,MATCH(F9,Dim_Product!$A$2:$A$4,0))+0.2 -> 70.2 | Q9: =IF(AND(P9>=INDEX(Dim_Product!$G$2:$G$4,MATCH(F9,Dim_Product!$A$2:$A$4,0))-INDEX(Dim_Product!$H$2:$H$4,MATCH(F9,Dim_Product!$A$2:$A$4,0)),P9<=INDEX(Dim_Product!$G$2:$G$4,MATCH(F9,Dim_Product!$A$2:$A$4,0))+INDEX(Dim_Product!$H$2:$H$4,MATCH(F9,Dim_Product!$A$2:$A$4,0))),G9-H9,G9-H9-1) -> 30 | R9: =G9-Q9 -> 2 | S9: =INDEX(Dim_Product!$K$2:$K$4,MATCH(F9,Dim_Product!$A$2:$A$4,0))+0.04 -> 120.04 | T9: =IF(AND(S9>=INDEX(Dim_Product!$K$2:$K$4,MATCH(F9,Dim_Product!$A$2:$A$4,0))-INDEX(Dim_Product!$L$2:$L$4,MATCH(F9,Dim_Product!$A$2:$A$4,0)),S9<=INDEX(Dim_Product!$K$2:$K$4,MATCH(F9,Dim_Product!$A$2:$A$4,0))+INDEX(Dim_Product!$L$2:$L$4,MATCH(F9,Dim_Product!$A$2:$A$4,0))),G9-H9,G9-H9-1) -> 30 | U9: =G9-T9 -> 2 | V9: =IFERROR(H9/G9,0) -> 0.0625 | W9: =1-V9 -> 0.9375
A10: QS-9 | B10: =Fact_Production_Hourly!B10 -> 20260701 | C10: =Fact_Production_Hourly!C10 -> 1 | D10: =Fact_Production_Hourly!D10 -> M2 | E10: =Fact_Production_Hourly!E10 -> B-PM | F10: =Fact_Production_Hourly!F10 -> C | G10: =INDEX(Dim_Machine!$D$2:$D$8,MATCH(D10,Dim_Machine!$A$2:$A$8,0))*2 -> 48 | H10: =ROUND(G10*0.0536,0) -> 3 | I10: =ROUND(H10*0.15,0) -> 0 | J10: =ROUND(H10*0.45,0) -> 1 | K10: =MAX(H10-I10-J10,0) -> 2 | L10: D05 | M10: =INDEX(Dim_Product!$C$2:$C$4,MATCH(F10,Dim_Product!$A$2:$A$4,0))+-0.15 -> 199.85 | N10: =IF(AND(M10>=INDEX(Dim_Product!$C$2:$C$4,MATCH(F10,Dim_Product!$A$2:$A$4,0))-INDEX(Dim_Product!$D$2:$D$4,MATCH(F10,Dim_Product!$A$2:$A$4,0)),M10<=INDEX(Dim_Product!$C$2:$C$4,MATCH(F10,Dim_Product!$A$2:$A$4,0))+INDEX(Dim_Product!$D$2:$D$4,MATCH(F10,Dim_Product!$A$2:$A$4,0))),G10-H10,G10-H10-1) -> 45 | O10: =G10-N10 -> 3 | P10: =INDEX(Dim_Product!$G$2:$G$4,MATCH(F10,Dim_Product!$A$2:$A$4,0))+0.17 -> 65.17 | Q10: =IF(AND(P10>=INDEX(Dim_Product!$G$2:$G$4,MATCH(F10,Dim_Product!$A$2:$A$4,0))-INDEX(Dim_Product!$H$2:$H$4,MATCH(F10,Dim_Product!$A$2:$A$4,0)),P10<=INDEX(Dim_Product!$G$2:$G$4,MATCH(F10,Dim_Product!$A$2:$A$4,0))+INDEX(Dim_Product!$H$2:$H$4,MATCH(F10,Dim_Product!$A$2:$A$4,0))),G10-H10,G10-H10-1) -> 45 | R10: =G10-Q10 -> 3 | S10: =INDEX(Dim_Product!$K$2:$K$4,MATCH(F10,Dim_Product!$A$2:$A$4,0))+-0.21 -> 109.79 | T10: =IF(AND(S10>=INDEX(Dim_Product!$K$2:$K$4,MATCH(F10,Dim_Product!$A$2:$A$4,0))-INDEX(Dim_Product!$L$2:$L$4,MATCH(F10,Dim_Product!$A$2:$A$4,0)),S10<=INDEX(Dim_Product!$K$2:$K$4,MATCH(F10,Dim_Product!$A$2:$A$4,0))+INDEX(Dim_Product!$L$2:$L$4,MATCH(F10,Dim_Product!$A$2:$A$4,0))),G10-H10,G10-H10-1) -> 45 | U10: =G10-T10 -> 3 | V10: =IFERROR(H10/G10,0) -> 0.0625 | W10: =1-V10 -> 0.9375
